{
	"document": {
		"aggregate_severity": {
			"namespace": "https://www.suse.com/support/security/rating/",
			"text": "moderate"
		},
		"category": "csaf_security_advisory",
		"csaf_version": "2.0",
		"distribution": {
			"text": "Copyright 2024 SUSE LLC. All rights reserved.",
			"tlp": {
				"label": "WHITE",
				"url": "https://www.first.org/tlp/"
			}
		},
		"lang": "en",
		"notes": [
			{
				"category": "summary",
				"text": "Security update for python-Django",
				"title": "Title of the patch"
			},
			{
				"category": "description",
				"text": "This update for python-Django fixes the following issues:\n\n- CVE-2019-12781: Added incorrect HTTP detection with reverse-proxy \n  connecting via HTTPS (bsc#1139945).\n- CVE-2019-3498: Fixed a content spoofing via crafted URL in the default \n  404 page (bsc#1120932).\n",
				"title": "Description of the patch"
			},
			{
				"category": "details",
				"text": "SUSE-2019-3127,SUSE-Storage-5-2019-3127",
				"title": "Patchnames"
			},
			{
				"category": "legal_disclaimer",
				"text": "CSAF 2.0 data is provided by SUSE under the Creative Commons License 4.0 with Attribution (CC-BY-4.0).",
				"title": "Terms of use"
			}
		],
		"publisher": {
			"category": "vendor",
			"contact_details": "https://www.suse.com/support/security/contact/",
			"name": "SUSE Product Security Team",
			"namespace": "https://www.suse.com/"
		},
		"references": [
			{
				"category": "external",
				"summary": "SUSE ratings",
				"url": "https://www.suse.com/support/security/rating/"
			},
			{
				"category": "self",
				"summary": "URL of this CSAF notice",
				"url": "https://ftp.suse.com/pub/projects/security/csaf/suse-su-2019_3127-1.json"
			},
			{
				"category": "self",
				"summary": "URL for SUSE-SU-2019:3127-1",
				"url": "https://www.suse.com/support/update/announcement/2019/suse-su-20193127-1/"
			},
			{
				"category": "self",
				"summary": "E-Mail link for SUSE-SU-2019:3127-1",
				"url": "https://lists.suse.com/pipermail/sle-security-updates/2019-November/006204.html"
			},
			{
				"category": "self",
				"summary": "SUSE Bug 1120932",
				"url": "https://bugzilla.suse.com/1120932"
			},
			{
				"category": "self",
				"summary": "SUSE Bug 1139945",
				"url": "https://bugzilla.suse.com/1139945"
			},
			{
				"category": "self",
				"summary": "SUSE CVE CVE-2019-12781 page",
				"url": "https://www.suse.com/security/cve/CVE-2019-12781/"
			},
			{
				"category": "self",
				"summary": "SUSE CVE CVE-2019-3498 page",
				"url": "https://www.suse.com/security/cve/CVE-2019-3498/"
			}
		],
		"title": "Security update for python-Django",
		"tracking": {
			"current_release_date": "2019-11-29T16:21:37Z",
			"generator": {
				"date": "2019-11-29T16:21:37Z",
				"engine": {
					"name": "cve-database.git:bin/generate-csaf.pl",
					"version": "1"
				}
			},
			"id": "SUSE-SU-2019:3127-1",
			"initial_release_date": "2019-11-29T16:21:37Z",
			"revision_history": [
				{
					"date": "2019-11-29T16:21:37Z",
					"number": "1",
					"summary": "Current version"
				}
			],
			"status": "final",
			"version": "1"
		}
	},
	"product_tree": {
		"branches": [
			{
				"branches": [
					{
						"branches": [
							{
								"category": "product_version",
								"name": "python-Django-1.6.11-6.10.1.noarch",
								"product": {
									"name": "python-Django-1.6.11-6.10.1.noarch",
									"product_id": "python-Django-1.6.11-6.10.1.noarch"
								}
							}
						],
						"category": "architecture",
						"name": "noarch"
					},
					{
						"branches": [
							{
								"category": "product_name",
								"name": "SUSE Enterprise Storage 5",
								"product": {
									"name": "SUSE Enterprise Storage 5",
									"product_id": "SUSE Enterprise Storage 5",
									"product_identification_helper": {
										"cpe": "cpe:/o:suse:ses:5"
									}
								}
							}
						],
						"category": "product_family",
						"name": "SUSE Linux Enterprise"
					}
				],
				"category": "vendor",
				"name": "SUSE"
			}
		],
		"relationships": [
			{
				"category": "default_component_of",
				"full_product_name": {
					"name": "python-Django-1.6.11-6.10.1.noarch as component of SUSE Enterprise Storage 5",
					"product_id": "SUSE Enterprise Storage 5:python-Django-1.6.11-6.10.1.noarch"
				},
				"product_reference": "python-Django-1.6.11-6.10.1.noarch",
				"relates_to_product_reference": "SUSE Enterprise Storage 5"
			}
		]
	},
	"vulnerabilities": [
		{
			"cve": "CVE-2019-12781",
			"ids": [
				{
					"system_name": "SUSE CVE Page",
					"text": "https://www.suse.com/security/cve/CVE-2019-12781"
				}
			],
			"notes": [
				{
					"category": "general",
					"text": "An issue was discovered in Django 1.11 before 1.11.22, 2.1 before 2.1.10, and 2.2 before 2.2.3. An HTTP request is not redirected to HTTPS when the SECURE_PROXY_SSL_HEADER and SECURE_SSL_REDIRECT settings are used, and the proxy connects to Django via HTTPS. In other words, django.http.HttpRequest.scheme has incorrect behavior when a client uses HTTP.",
					"title": "CVE description"
				}
			],
			"product_status": {},
			"references": [
				{
					"category": "external",
					"summary": "CVE-2019-12781",
					"url": "https://www.suse.com/security/cve/CVE-2019-12781"
				},
				{
					"category": "external",
					"summary": "SUSE Bug 1124991 for CVE-2019-12781",
					"url": "https://bugzilla.suse.com/1124991"
				},
				{
					"category": "external",
					"summary": "SUSE Bug 1139945 for CVE-2019-12781",
					"url": "https://bugzilla.suse.com/1139945"
				}
			],
			"remediations": [
				{
					"category": "vendor_fix",
					"details": "To install this SUSE Security Update use the SUSE recommended installation methods like YaST online_update or \"zypper patch\".\n",
					"product_ids": [
						"SUSE Enterprise Storage 5:python-Django-1.6.11-6.10.1.noarch"
					]
				}
			],
			"scores": [
				{
					"cvss_v3": {
						"baseScore": 6.5,
						"baseSeverity": "MEDIUM",
						"vectorString": "CVSS:3.0/AV:N/AC:L/PR:N/UI:N/S:U/C:L/I:L/A:N",
						"version": "3.0"
					},
					"products": [
						"SUSE Enterprise Storage 5:python-Django-1.6.11-6.10.1.noarch"
					]
				}
			],
			"threats": [
				{
					"category": "impact",
					"date": "2019-11-29T16:21:37Z",
					"details": "moderate"
				}
			],
			"title": "CVE-2019-12781"
		},
		{
			"cve": "CVE-2019-3498",
			"ids": [
				{
					"system_name": "SUSE CVE Page",
					"text": "https://www.suse.com/security/cve/CVE-2019-3498"
				}
			],
			"notes": [
				{
					"category": "general",
					"text": "In Django 1.11.x before 1.11.18, 2.0.x before 2.0.10, and 2.1.x before 2.1.5, an Improper Neutralization of Special Elements in Output Used by a Downstream Component issue exists in django.views.defaults.page_not_found(), leading to content spoofing (in a 404 error page) if a user fails to recognize that a crafted URL has malicious content.",
					"title": "CVE description"
				}
			],
			"product_status": {},
			"references": [
				{
					"category": "external",
					"summary": "CVE-2019-3498",
					"url": "https://www.suse.com/security/cve/CVE-2019-3498"
				},
				{
					"category": "external",
					"summary": "SUSE Bug 1120932 for CVE-2019-3498",
					"url": "https://bugzilla.suse.com/1120932"
				},
				{
					"category": "external",
					"summary": "SUSE Bug 1139945 for CVE-2019-3498",
					"url": "https://bugzilla.suse.com/1139945"
				}
			],
			"remediations": [
				{
					"category": "vendor_fix",
					"details": "To install this SUSE Security Update use the SUSE recommended installation methods like YaST online_update or \"zypper patch\".\n",
					"product_ids": [
						"SUSE Enterprise Storage 5:python-Django-1.6.11-6.10.1.noarch"
					]
				}
			],
			"scores": [
				{
					"cvss_v3": {
						"baseScore": 4.3,
						"baseSeverity": "MEDIUM",
						"vectorString": "CVSS:3.0/AV:N/AC:L/PR:N/UI:R/S:U/C:N/I:L/A:N",
						"version": "3.0"
					},
					"products": [
						"SUSE Enterprise Storage 5:python-Django-1.6.11-6.10.1.noarch"
					]
				}
			],
			"threats": [
				{
					"category": "impact",
					"date": "2019-11-29T16:21:37Z",
					"details": "low"
				}
			],
			"title": "CVE-2019-3498"
		}
	]
}
