{
	"document": {
		"aggregate_severity": {
			"namespace": "https://www.suse.com/support/security/rating/",
			"text": "moderate"
		},
		"category": "csaf_security_advisory",
		"csaf_version": "2.0",
		"distribution": {
			"text": "Copyright 2024 SUSE LLC. All rights reserved.",
			"tlp": {
				"label": "WHITE",
				"url": "https://www.first.org/tlp/"
			}
		},
		"lang": "en",
		"notes": [
			{
				"category": "summary",
				"text": "python311-Django-5.1.5-1.1 on GA media",
				"title": "Title of the patch"
			},
			{
				"category": "description",
				"text": "These are all security issues fixed in the python311-Django-5.1.5-1.1 package on the GA media of openSUSE Tumbleweed.",
				"title": "Description of the patch"
			},
			{
				"category": "details",
				"text": "openSUSE-Tumbleweed-2025-14662",
				"title": "Patchnames"
			},
			{
				"category": "legal_disclaimer",
				"text": "CSAF 2.0 data is provided by SUSE under the Creative Commons License 4.0 with Attribution (CC-BY-4.0).",
				"title": "Terms of use"
			}
		],
		"publisher": {
			"category": "vendor",
			"contact_details": "https://www.suse.com/support/security/contact/",
			"name": "SUSE Product Security Team",
			"namespace": "https://www.suse.com/"
		},
		"references": [
			{
				"category": "external",
				"summary": "SUSE ratings",
				"url": "https://www.suse.com/support/security/rating/"
			},
			{
				"category": "self",
				"summary": "URL of this CSAF notice",
				"url": "https://ftp.suse.com/pub/projects/security/csaf/opensuse-su-2025_14662-1.json"
			},
			{
				"category": "self",
				"summary": "SUSE CVE CVE-2021-45115 page",
				"url": "https://www.suse.com/security/cve/CVE-2021-45115/"
			},
			{
				"category": "self",
				"summary": "SUSE CVE CVE-2021-45452 page",
				"url": "https://www.suse.com/security/cve/CVE-2021-45452/"
			},
			{
				"category": "self",
				"summary": "SUSE CVE CVE-2022-22818 page",
				"url": "https://www.suse.com/security/cve/CVE-2022-22818/"
			},
			{
				"category": "self",
				"summary": "SUSE CVE CVE-2022-23833 page",
				"url": "https://www.suse.com/security/cve/CVE-2022-23833/"
			},
			{
				"category": "self",
				"summary": "SUSE CVE CVE-2022-28346 page",
				"url": "https://www.suse.com/security/cve/CVE-2022-28346/"
			},
			{
				"category": "self",
				"summary": "SUSE CVE CVE-2022-28347 page",
				"url": "https://www.suse.com/security/cve/CVE-2022-28347/"
			},
			{
				"category": "self",
				"summary": "SUSE CVE CVE-2022-34265 page",
				"url": "https://www.suse.com/security/cve/CVE-2022-34265/"
			},
			{
				"category": "self",
				"summary": "SUSE CVE CVE-2022-36359 page",
				"url": "https://www.suse.com/security/cve/CVE-2022-36359/"
			},
			{
				"category": "self",
				"summary": "SUSE CVE CVE-2022-41323 page",
				"url": "https://www.suse.com/security/cve/CVE-2022-41323/"
			},
			{
				"category": "self",
				"summary": "SUSE CVE CVE-2023-23969 page",
				"url": "https://www.suse.com/security/cve/CVE-2023-23969/"
			},
			{
				"category": "self",
				"summary": "SUSE CVE CVE-2023-24580 page",
				"url": "https://www.suse.com/security/cve/CVE-2023-24580/"
			},
			{
				"category": "self",
				"summary": "SUSE CVE CVE-2024-56374 page",
				"url": "https://www.suse.com/security/cve/CVE-2024-56374/"
			}
		],
		"title": "python311-Django-5.1.5-1.1 on GA media",
		"tracking": {
			"current_release_date": "2025-01-17T00:00:00Z",
			"generator": {
				"date": "2025-01-17T00:00:00Z",
				"engine": {
					"name": "cve-database.git:bin/generate-csaf.pl",
					"version": "1"
				}
			},
			"id": "openSUSE-SU-2025:14662-1",
			"initial_release_date": "2025-01-17T00:00:00Z",
			"revision_history": [
				{
					"date": "2025-01-17T00:00:00Z",
					"number": "1",
					"summary": "Current version"
				}
			],
			"status": "final",
			"version": "1"
		}
	},
	"product_tree": {
		"branches": [
			{
				"branches": [
					{
						"branches": [
							{
								"category": "product_version",
								"name": "python311-Django-5.1.5-1.1.aarch64",
								"product": {
									"name": "python311-Django-5.1.5-1.1.aarch64",
									"product_id": "python311-Django-5.1.5-1.1.aarch64"
								}
							},
							{
								"category": "product_version",
								"name": "python312-Django-5.1.5-1.1.aarch64",
								"product": {
									"name": "python312-Django-5.1.5-1.1.aarch64",
									"product_id": "python312-Django-5.1.5-1.1.aarch64"
								}
							},
							{
								"category": "product_version",
								"name": "python313-Django-5.1.5-1.1.aarch64",
								"product": {
									"name": "python313-Django-5.1.5-1.1.aarch64",
									"product_id": "python313-Django-5.1.5-1.1.aarch64"
								}
							}
						],
						"category": "architecture",
						"name": "aarch64"
					},
					{
						"branches": [
							{
								"category": "product_version",
								"name": "python311-Django-5.1.5-1.1.ppc64le",
								"product": {
									"name": "python311-Django-5.1.5-1.1.ppc64le",
									"product_id": "python311-Django-5.1.5-1.1.ppc64le"
								}
							},
							{
								"category": "product_version",
								"name": "python312-Django-5.1.5-1.1.ppc64le",
								"product": {
									"name": "python312-Django-5.1.5-1.1.ppc64le",
									"product_id": "python312-Django-5.1.5-1.1.ppc64le"
								}
							},
							{
								"category": "product_version",
								"name": "python313-Django-5.1.5-1.1.ppc64le",
								"product": {
									"name": "python313-Django-5.1.5-1.1.ppc64le",
									"product_id": "python313-Django-5.1.5-1.1.ppc64le"
								}
							}
						],
						"category": "architecture",
						"name": "ppc64le"
					},
					{
						"branches": [
							{
								"category": "product_version",
								"name": "python311-Django-5.1.5-1.1.s390x",
								"product": {
									"name": "python311-Django-5.1.5-1.1.s390x",
									"product_id": "python311-Django-5.1.5-1.1.s390x"
								}
							},
							{
								"category": "product_version",
								"name": "python312-Django-5.1.5-1.1.s390x",
								"product": {
									"name": "python312-Django-5.1.5-1.1.s390x",
									"product_id": "python312-Django-5.1.5-1.1.s390x"
								}
							},
							{
								"category": "product_version",
								"name": "python313-Django-5.1.5-1.1.s390x",
								"product": {
									"name": "python313-Django-5.1.5-1.1.s390x",
									"product_id": "python313-Django-5.1.5-1.1.s390x"
								}
							}
						],
						"category": "architecture",
						"name": "s390x"
					},
					{
						"branches": [
							{
								"category": "product_version",
								"name": "python311-Django-5.1.5-1.1.x86_64",
								"product": {
									"name": "python311-Django-5.1.5-1.1.x86_64",
									"product_id": "python311-Django-5.1.5-1.1.x86_64"
								}
							},
							{
								"category": "product_version",
								"name": "python312-Django-5.1.5-1.1.x86_64",
								"product": {
									"name": "python312-Django-5.1.5-1.1.x86_64",
									"product_id": "python312-Django-5.1.5-1.1.x86_64"
								}
							},
							{
								"category": "product_version",
								"name": "python313-Django-5.1.5-1.1.x86_64",
								"product": {
									"name": "python313-Django-5.1.5-1.1.x86_64",
									"product_id": "python313-Django-5.1.5-1.1.x86_64"
								}
							}
						],
						"category": "architecture",
						"name": "x86_64"
					},
					{
						"branches": [
							{
								"category": "product_name",
								"name": "openSUSE Tumbleweed",
								"product": {
									"name": "openSUSE Tumbleweed",
									"product_id": "openSUSE Tumbleweed",
									"product_identification_helper": {
										"cpe": "cpe:/o:opensuse:tumbleweed"
									}
								}
							}
						],
						"category": "product_family",
						"name": "SUSE Linux Enterprise"
					}
				],
				"category": "vendor",
				"name": "SUSE"
			}
		],
		"relationships": [
			{
				"category": "default_component_of",
				"full_product_name": {
					"name": "python311-Django-5.1.5-1.1.aarch64 as component of openSUSE Tumbleweed",
					"product_id": "openSUSE Tumbleweed:python311-Django-5.1.5-1.1.aarch64"
				},
				"product_reference": "python311-Django-5.1.5-1.1.aarch64",
				"relates_to_product_reference": "openSUSE Tumbleweed"
			},
			{
				"category": "default_component_of",
				"full_product_name": {
					"name": "python311-Django-5.1.5-1.1.ppc64le as component of openSUSE Tumbleweed",
					"product_id": "openSUSE Tumbleweed:python311-Django-5.1.5-1.1.ppc64le"
				},
				"product_reference": "python311-Django-5.1.5-1.1.ppc64le",
				"relates_to_product_reference": "openSUSE Tumbleweed"
			},
			{
				"category": "default_component_of",
				"full_product_name": {
					"name": "python311-Django-5.1.5-1.1.s390x as component of openSUSE Tumbleweed",
					"product_id": "openSUSE Tumbleweed:python311-Django-5.1.5-1.1.s390x"
				},
				"product_reference": "python311-Django-5.1.5-1.1.s390x",
				"relates_to_product_reference": "openSUSE Tumbleweed"
			},
			{
				"category": "default_component_of",
				"full_product_name": {
					"name": "python311-Django-5.1.5-1.1.x86_64 as component of openSUSE Tumbleweed",
					"product_id": "openSUSE Tumbleweed:python311-Django-5.1.5-1.1.x86_64"
				},
				"product_reference": "python311-Django-5.1.5-1.1.x86_64",
				"relates_to_product_reference": "openSUSE Tumbleweed"
			},
			{
				"category": "default_component_of",
				"full_product_name": {
					"name": "python312-Django-5.1.5-1.1.aarch64 as component of openSUSE Tumbleweed",
					"product_id": "openSUSE Tumbleweed:python312-Django-5.1.5-1.1.aarch64"
				},
				"product_reference": "python312-Django-5.1.5-1.1.aarch64",
				"relates_to_product_reference": "openSUSE Tumbleweed"
			},
			{
				"category": "default_component_of",
				"full_product_name": {
					"name": "python312-Django-5.1.5-1.1.ppc64le as component of openSUSE Tumbleweed",
					"product_id": "openSUSE Tumbleweed:python312-Django-5.1.5-1.1.ppc64le"
				},
				"product_reference": "python312-Django-5.1.5-1.1.ppc64le",
				"relates_to_product_reference": "openSUSE Tumbleweed"
			},
			{
				"category": "default_component_of",
				"full_product_name": {
					"name": "python312-Django-5.1.5-1.1.s390x as component of openSUSE Tumbleweed",
					"product_id": "openSUSE Tumbleweed:python312-Django-5.1.5-1.1.s390x"
				},
				"product_reference": "python312-Django-5.1.5-1.1.s390x",
				"relates_to_product_reference": "openSUSE Tumbleweed"
			},
			{
				"category": "default_component_of",
				"full_product_name": {
					"name": "python312-Django-5.1.5-1.1.x86_64 as component of openSUSE Tumbleweed",
					"product_id": "openSUSE Tumbleweed:python312-Django-5.1.5-1.1.x86_64"
				},
				"product_reference": "python312-Django-5.1.5-1.1.x86_64",
				"relates_to_product_reference": "openSUSE Tumbleweed"
			},
			{
				"category": "default_component_of",
				"full_product_name": {
					"name": "python313-Django-5.1.5-1.1.aarch64 as component of openSUSE Tumbleweed",
					"product_id": "openSUSE Tumbleweed:python313-Django-5.1.5-1.1.aarch64"
				},
				"product_reference": "python313-Django-5.1.5-1.1.aarch64",
				"relates_to_product_reference": "openSUSE Tumbleweed"
			},
			{
				"category": "default_component_of",
				"full_product_name": {
					"name": "python313-Django-5.1.5-1.1.ppc64le as component of openSUSE Tumbleweed",
					"product_id": "openSUSE Tumbleweed:python313-Django-5.1.5-1.1.ppc64le"
				},
				"product_reference": "python313-Django-5.1.5-1.1.ppc64le",
				"relates_to_product_reference": "openSUSE Tumbleweed"
			},
			{
				"category": "default_component_of",
				"full_product_name": {
					"name": "python313-Django-5.1.5-1.1.s390x as component of openSUSE Tumbleweed",
					"product_id": "openSUSE Tumbleweed:python313-Django-5.1.5-1.1.s390x"
				},
				"product_reference": "python313-Django-5.1.5-1.1.s390x",
				"relates_to_product_reference": "openSUSE Tumbleweed"
			},
			{
				"category": "default_component_of",
				"full_product_name": {
					"name": "python313-Django-5.1.5-1.1.x86_64 as component of openSUSE Tumbleweed",
					"product_id": "openSUSE Tumbleweed:python313-Django-5.1.5-1.1.x86_64"
				},
				"product_reference": "python313-Django-5.1.5-1.1.x86_64",
				"relates_to_product_reference": "openSUSE Tumbleweed"
			}
		]
	},
	"vulnerabilities": [
		{
			"cve": "CVE-2021-45115",
			"ids": [
				{
					"system_name": "SUSE CVE Page",
					"text": "https://www.suse.com/security/cve/CVE-2021-45115"
				}
			],
			"notes": [
				{
					"category": "general",
					"text": "An issue was discovered in Django 2.2 before 2.2.26, 3.2 before 3.2.11, and 4.0 before 4.0.1. UserAttributeSimilarityValidator incurred significant overhead in evaluating a submitted password that was artificially large in relation to the comparison values. In a situation where access to user registration was unrestricted, this provided a potential vector for a denial-of-service attack.",
					"title": "CVE description"
				}
			],
			"product_status": {
				"recommended": [
					"openSUSE Tumbleweed:python311-Django-5.1.5-1.1.aarch64",
					"openSUSE Tumbleweed:python311-Django-5.1.5-1.1.ppc64le",
					"openSUSE Tumbleweed:python311-Django-5.1.5-1.1.s390x",
					"openSUSE Tumbleweed:python311-Django-5.1.5-1.1.x86_64",
					"openSUSE Tumbleweed:python312-Django-5.1.5-1.1.aarch64",
					"openSUSE Tumbleweed:python312-Django-5.1.5-1.1.ppc64le",
					"openSUSE Tumbleweed:python312-Django-5.1.5-1.1.s390x",
					"openSUSE Tumbleweed:python312-Django-5.1.5-1.1.x86_64",
					"openSUSE Tumbleweed:python313-Django-5.1.5-1.1.aarch64",
					"openSUSE Tumbleweed:python313-Django-5.1.5-1.1.ppc64le",
					"openSUSE Tumbleweed:python313-Django-5.1.5-1.1.s390x",
					"openSUSE Tumbleweed:python313-Django-5.1.5-1.1.x86_64"
				]
			},
			"references": [
				{
					"category": "external",
					"summary": "CVE-2021-45115",
					"url": "https://www.suse.com/security/cve/CVE-2021-45115"
				},
				{
					"category": "external",
					"summary": "SUSE Bug 1194115 for CVE-2021-45115",
					"url": "https://bugzilla.suse.com/1194115"
				},
				{
					"category": "external",
					"summary": "SUSE Bug 1194117 for CVE-2021-45115",
					"url": "https://bugzilla.suse.com/1194117"
				}
			],
			"remediations": [
				{
					"category": "vendor_fix",
					"details": "To install this SUSE Security Update use the SUSE recommended installation methods like YaST online_update or \"zypper patch\".\n",
					"product_ids": [
						"openSUSE Tumbleweed:python311-Django-5.1.5-1.1.aarch64",
						"openSUSE Tumbleweed:python311-Django-5.1.5-1.1.ppc64le",
						"openSUSE Tumbleweed:python311-Django-5.1.5-1.1.s390x",
						"openSUSE Tumbleweed:python311-Django-5.1.5-1.1.x86_64",
						"openSUSE Tumbleweed:python312-Django-5.1.5-1.1.aarch64",
						"openSUSE Tumbleweed:python312-Django-5.1.5-1.1.ppc64le",
						"openSUSE Tumbleweed:python312-Django-5.1.5-1.1.s390x",
						"openSUSE Tumbleweed:python312-Django-5.1.5-1.1.x86_64",
						"openSUSE Tumbleweed:python313-Django-5.1.5-1.1.aarch64",
						"openSUSE Tumbleweed:python313-Django-5.1.5-1.1.ppc64le",
						"openSUSE Tumbleweed:python313-Django-5.1.5-1.1.s390x",
						"openSUSE Tumbleweed:python313-Django-5.1.5-1.1.x86_64"
					]
				}
			],
			"scores": [
				{
					"cvss_v3": {
						"baseScore": 7.5,
						"baseSeverity": "HIGH",
						"vectorString": "CVSS:3.1/AV:N/AC:L/PR:N/UI:N/S:U/C:N/I:N/A:H",
						"version": "3.1"
					},
					"products": [
						"openSUSE Tumbleweed:python311-Django-5.1.5-1.1.aarch64",
						"openSUSE Tumbleweed:python311-Django-5.1.5-1.1.ppc64le",
						"openSUSE Tumbleweed:python311-Django-5.1.5-1.1.s390x",
						"openSUSE Tumbleweed:python311-Django-5.1.5-1.1.x86_64",
						"openSUSE Tumbleweed:python312-Django-5.1.5-1.1.aarch64",
						"openSUSE Tumbleweed:python312-Django-5.1.5-1.1.ppc64le",
						"openSUSE Tumbleweed:python312-Django-5.1.5-1.1.s390x",
						"openSUSE Tumbleweed:python312-Django-5.1.5-1.1.x86_64",
						"openSUSE Tumbleweed:python313-Django-5.1.5-1.1.aarch64",
						"openSUSE Tumbleweed:python313-Django-5.1.5-1.1.ppc64le",
						"openSUSE Tumbleweed:python313-Django-5.1.5-1.1.s390x",
						"openSUSE Tumbleweed:python313-Django-5.1.5-1.1.x86_64"
					]
				}
			],
			"threats": [
				{
					"category": "impact",
					"date": "2025-01-17T00:00:00Z",
					"details": "important"
				}
			],
			"title": "CVE-2021-45115"
		},
		{
			"cve": "CVE-2021-45452",
			"ids": [
				{
					"system_name": "SUSE CVE Page",
					"text": "https://www.suse.com/security/cve/CVE-2021-45452"
				}
			],
			"notes": [
				{
					"category": "general",
					"text": "Storage.save in Django 2.2 before 2.2.26, 3.2 before 3.2.11, and 4.0 before 4.0.1 allows directory traversal if crafted filenames are directly passed to it.",
					"title": "CVE description"
				}
			],
			"product_status": {
				"recommended": [
					"openSUSE Tumbleweed:python311-Django-5.1.5-1.1.aarch64",
					"openSUSE Tumbleweed:python311-Django-5.1.5-1.1.ppc64le",
					"openSUSE Tumbleweed:python311-Django-5.1.5-1.1.s390x",
					"openSUSE Tumbleweed:python311-Django-5.1.5-1.1.x86_64",
					"openSUSE Tumbleweed:python312-Django-5.1.5-1.1.aarch64",
					"openSUSE Tumbleweed:python312-Django-5.1.5-1.1.ppc64le",
					"openSUSE Tumbleweed:python312-Django-5.1.5-1.1.s390x",
					"openSUSE Tumbleweed:python312-Django-5.1.5-1.1.x86_64",
					"openSUSE Tumbleweed:python313-Django-5.1.5-1.1.aarch64",
					"openSUSE Tumbleweed:python313-Django-5.1.5-1.1.ppc64le",
					"openSUSE Tumbleweed:python313-Django-5.1.5-1.1.s390x",
					"openSUSE Tumbleweed:python313-Django-5.1.5-1.1.x86_64"
				]
			},
			"references": [
				{
					"category": "external",
					"summary": "CVE-2021-45452",
					"url": "https://www.suse.com/security/cve/CVE-2021-45452"
				},
				{
					"category": "external",
					"summary": "SUSE Bug 1194116 for CVE-2021-45452",
					"url": "https://bugzilla.suse.com/1194116"
				}
			],
			"remediations": [
				{
					"category": "vendor_fix",
					"details": "To install this SUSE Security Update use the SUSE recommended installation methods like YaST online_update or \"zypper patch\".\n",
					"product_ids": [
						"openSUSE Tumbleweed:python311-Django-5.1.5-1.1.aarch64",
						"openSUSE Tumbleweed:python311-Django-5.1.5-1.1.ppc64le",
						"openSUSE Tumbleweed:python311-Django-5.1.5-1.1.s390x",
						"openSUSE Tumbleweed:python311-Django-5.1.5-1.1.x86_64",
						"openSUSE Tumbleweed:python312-Django-5.1.5-1.1.aarch64",
						"openSUSE Tumbleweed:python312-Django-5.1.5-1.1.ppc64le",
						"openSUSE Tumbleweed:python312-Django-5.1.5-1.1.s390x",
						"openSUSE Tumbleweed:python312-Django-5.1.5-1.1.x86_64",
						"openSUSE Tumbleweed:python313-Django-5.1.5-1.1.aarch64",
						"openSUSE Tumbleweed:python313-Django-5.1.5-1.1.ppc64le",
						"openSUSE Tumbleweed:python313-Django-5.1.5-1.1.s390x",
						"openSUSE Tumbleweed:python313-Django-5.1.5-1.1.x86_64"
					]
				}
			],
			"scores": [
				{
					"cvss_v3": {
						"baseScore": 5.3,
						"baseSeverity": "MEDIUM",
						"vectorString": "CVSS:3.1/AV:N/AC:L/PR:N/UI:N/S:U/C:N/I:L/A:N",
						"version": "3.1"
					},
					"products": [
						"openSUSE Tumbleweed:python311-Django-5.1.5-1.1.aarch64",
						"openSUSE Tumbleweed:python311-Django-5.1.5-1.1.ppc64le",
						"openSUSE Tumbleweed:python311-Django-5.1.5-1.1.s390x",
						"openSUSE Tumbleweed:python311-Django-5.1.5-1.1.x86_64",
						"openSUSE Tumbleweed:python312-Django-5.1.5-1.1.aarch64",
						"openSUSE Tumbleweed:python312-Django-5.1.5-1.1.ppc64le",
						"openSUSE Tumbleweed:python312-Django-5.1.5-1.1.s390x",
						"openSUSE Tumbleweed:python312-Django-5.1.5-1.1.x86_64",
						"openSUSE Tumbleweed:python313-Django-5.1.5-1.1.aarch64",
						"openSUSE Tumbleweed:python313-Django-5.1.5-1.1.ppc64le",
						"openSUSE Tumbleweed:python313-Django-5.1.5-1.1.s390x",
						"openSUSE Tumbleweed:python313-Django-5.1.5-1.1.x86_64"
					]
				}
			],
			"threats": [
				{
					"category": "impact",
					"date": "2025-01-17T00:00:00Z",
					"details": "moderate"
				}
			],
			"title": "CVE-2021-45452"
		},
		{
			"cve": "CVE-2022-22818",
			"ids": [
				{
					"system_name": "SUSE CVE Page",
					"text": "https://www.suse.com/security/cve/CVE-2022-22818"
				}
			],
			"notes": [
				{
					"category": "general",
					"text": "The {% debug %} template tag in Django 2.2 before 2.2.27, 3.2 before 3.2.12, and 4.0 before 4.0.2 does not properly encode the current context. This may lead to XSS.",
					"title": "CVE description"
				}
			],
			"product_status": {
				"recommended": [
					"openSUSE Tumbleweed:python311-Django-5.1.5-1.1.aarch64",
					"openSUSE Tumbleweed:python311-Django-5.1.5-1.1.ppc64le",
					"openSUSE Tumbleweed:python311-Django-5.1.5-1.1.s390x",
					"openSUSE Tumbleweed:python311-Django-5.1.5-1.1.x86_64",
					"openSUSE Tumbleweed:python312-Django-5.1.5-1.1.aarch64",
					"openSUSE Tumbleweed:python312-Django-5.1.5-1.1.ppc64le",
					"openSUSE Tumbleweed:python312-Django-5.1.5-1.1.s390x",
					"openSUSE Tumbleweed:python312-Django-5.1.5-1.1.x86_64",
					"openSUSE Tumbleweed:python313-Django-5.1.5-1.1.aarch64",
					"openSUSE Tumbleweed:python313-Django-5.1.5-1.1.ppc64le",
					"openSUSE Tumbleweed:python313-Django-5.1.5-1.1.s390x",
					"openSUSE Tumbleweed:python313-Django-5.1.5-1.1.x86_64"
				]
			},
			"references": [
				{
					"category": "external",
					"summary": "CVE-2022-22818",
					"url": "https://www.suse.com/security/cve/CVE-2022-22818"
				},
				{
					"category": "external",
					"summary": "SUSE Bug 1195086 for CVE-2022-22818",
					"url": "https://bugzilla.suse.com/1195086"
				}
			],
			"remediations": [
				{
					"category": "vendor_fix",
					"details": "To install this SUSE Security Update use the SUSE recommended installation methods like YaST online_update or \"zypper patch\".\n",
					"product_ids": [
						"openSUSE Tumbleweed:python311-Django-5.1.5-1.1.aarch64",
						"openSUSE Tumbleweed:python311-Django-5.1.5-1.1.ppc64le",
						"openSUSE Tumbleweed:python311-Django-5.1.5-1.1.s390x",
						"openSUSE Tumbleweed:python311-Django-5.1.5-1.1.x86_64",
						"openSUSE Tumbleweed:python312-Django-5.1.5-1.1.aarch64",
						"openSUSE Tumbleweed:python312-Django-5.1.5-1.1.ppc64le",
						"openSUSE Tumbleweed:python312-Django-5.1.5-1.1.s390x",
						"openSUSE Tumbleweed:python312-Django-5.1.5-1.1.x86_64",
						"openSUSE Tumbleweed:python313-Django-5.1.5-1.1.aarch64",
						"openSUSE Tumbleweed:python313-Django-5.1.5-1.1.ppc64le",
						"openSUSE Tumbleweed:python313-Django-5.1.5-1.1.s390x",
						"openSUSE Tumbleweed:python313-Django-5.1.5-1.1.x86_64"
					]
				}
			],
			"scores": [
				{
					"cvss_v3": {
						"baseScore": 5,
						"baseSeverity": "MEDIUM",
						"vectorString": "CVSS:3.1/AV:N/AC:H/PR:N/UI:R/S:U/C:L/I:L/A:L",
						"version": "3.1"
					},
					"products": [
						"openSUSE Tumbleweed:python311-Django-5.1.5-1.1.aarch64",
						"openSUSE Tumbleweed:python311-Django-5.1.5-1.1.ppc64le",
						"openSUSE Tumbleweed:python311-Django-5.1.5-1.1.s390x",
						"openSUSE Tumbleweed:python311-Django-5.1.5-1.1.x86_64",
						"openSUSE Tumbleweed:python312-Django-5.1.5-1.1.aarch64",
						"openSUSE Tumbleweed:python312-Django-5.1.5-1.1.ppc64le",
						"openSUSE Tumbleweed:python312-Django-5.1.5-1.1.s390x",
						"openSUSE Tumbleweed:python312-Django-5.1.5-1.1.x86_64",
						"openSUSE Tumbleweed:python313-Django-5.1.5-1.1.aarch64",
						"openSUSE Tumbleweed:python313-Django-5.1.5-1.1.ppc64le",
						"openSUSE Tumbleweed:python313-Django-5.1.5-1.1.s390x",
						"openSUSE Tumbleweed:python313-Django-5.1.5-1.1.x86_64"
					]
				}
			],
			"threats": [
				{
					"category": "impact",
					"date": "2025-01-17T00:00:00Z",
					"details": "moderate"
				}
			],
			"title": "CVE-2022-22818"
		},
		{
			"cve": "CVE-2022-23833",
			"ids": [
				{
					"system_name": "SUSE CVE Page",
					"text": "https://www.suse.com/security/cve/CVE-2022-23833"
				}
			],
			"notes": [
				{
					"category": "general",
					"text": "An issue was discovered in MultiPartParser in Django 2.2 before 2.2.27, 3.2 before 3.2.12, and 4.0 before 4.0.2. Passing certain inputs to multipart forms could result in an infinite loop when parsing files.",
					"title": "CVE description"
				}
			],
			"product_status": {
				"recommended": [
					"openSUSE Tumbleweed:python311-Django-5.1.5-1.1.aarch64",
					"openSUSE Tumbleweed:python311-Django-5.1.5-1.1.ppc64le",
					"openSUSE Tumbleweed:python311-Django-5.1.5-1.1.s390x",
					"openSUSE Tumbleweed:python311-Django-5.1.5-1.1.x86_64",
					"openSUSE Tumbleweed:python312-Django-5.1.5-1.1.aarch64",
					"openSUSE Tumbleweed:python312-Django-5.1.5-1.1.ppc64le",
					"openSUSE Tumbleweed:python312-Django-5.1.5-1.1.s390x",
					"openSUSE Tumbleweed:python312-Django-5.1.5-1.1.x86_64",
					"openSUSE Tumbleweed:python313-Django-5.1.5-1.1.aarch64",
					"openSUSE Tumbleweed:python313-Django-5.1.5-1.1.ppc64le",
					"openSUSE Tumbleweed:python313-Django-5.1.5-1.1.s390x",
					"openSUSE Tumbleweed:python313-Django-5.1.5-1.1.x86_64"
				]
			},
			"references": [
				{
					"category": "external",
					"summary": "CVE-2022-23833",
					"url": "https://www.suse.com/security/cve/CVE-2022-23833"
				},
				{
					"category": "external",
					"summary": "SUSE Bug 1195088 for CVE-2022-23833",
					"url": "https://bugzilla.suse.com/1195088"
				}
			],
			"remediations": [
				{
					"category": "vendor_fix",
					"details": "To install this SUSE Security Update use the SUSE recommended installation methods like YaST online_update or \"zypper patch\".\n",
					"product_ids": [
						"openSUSE Tumbleweed:python311-Django-5.1.5-1.1.aarch64",
						"openSUSE Tumbleweed:python311-Django-5.1.5-1.1.ppc64le",
						"openSUSE Tumbleweed:python311-Django-5.1.5-1.1.s390x",
						"openSUSE Tumbleweed:python311-Django-5.1.5-1.1.x86_64",
						"openSUSE Tumbleweed:python312-Django-5.1.5-1.1.aarch64",
						"openSUSE Tumbleweed:python312-Django-5.1.5-1.1.ppc64le",
						"openSUSE Tumbleweed:python312-Django-5.1.5-1.1.s390x",
						"openSUSE Tumbleweed:python312-Django-5.1.5-1.1.x86_64",
						"openSUSE Tumbleweed:python313-Django-5.1.5-1.1.aarch64",
						"openSUSE Tumbleweed:python313-Django-5.1.5-1.1.ppc64le",
						"openSUSE Tumbleweed:python313-Django-5.1.5-1.1.s390x",
						"openSUSE Tumbleweed:python313-Django-5.1.5-1.1.x86_64"
					]
				}
			],
			"scores": [
				{
					"cvss_v3": {
						"baseScore": 7.5,
						"baseSeverity": "HIGH",
						"vectorString": "CVSS:3.1/AV:N/AC:L/PR:N/UI:N/S:U/C:N/I:N/A:H",
						"version": "3.1"
					},
					"products": [
						"openSUSE Tumbleweed:python311-Django-5.1.5-1.1.aarch64",
						"openSUSE Tumbleweed:python311-Django-5.1.5-1.1.ppc64le",
						"openSUSE Tumbleweed:python311-Django-5.1.5-1.1.s390x",
						"openSUSE Tumbleweed:python311-Django-5.1.5-1.1.x86_64",
						"openSUSE Tumbleweed:python312-Django-5.1.5-1.1.aarch64",
						"openSUSE Tumbleweed:python312-Django-5.1.5-1.1.ppc64le",
						"openSUSE Tumbleweed:python312-Django-5.1.5-1.1.s390x",
						"openSUSE Tumbleweed:python312-Django-5.1.5-1.1.x86_64",
						"openSUSE Tumbleweed:python313-Django-5.1.5-1.1.aarch64",
						"openSUSE Tumbleweed:python313-Django-5.1.5-1.1.ppc64le",
						"openSUSE Tumbleweed:python313-Django-5.1.5-1.1.s390x",
						"openSUSE Tumbleweed:python313-Django-5.1.5-1.1.x86_64"
					]
				}
			],
			"threats": [
				{
					"category": "impact",
					"date": "2025-01-17T00:00:00Z",
					"details": "important"
				}
			],
			"title": "CVE-2022-23833"
		},
		{
			"cve": "CVE-2022-28346",
			"ids": [
				{
					"system_name": "SUSE CVE Page",
					"text": "https://www.suse.com/security/cve/CVE-2022-28346"
				}
			],
			"notes": [
				{
					"category": "general",
					"text": "An issue was discovered in Django 2.2 before 2.2.28, 3.2 before 3.2.13, and 4.0 before 4.0.4. QuerySet.annotate(), aggregate(), and extra() methods are subject to SQL injection in column aliases via a crafted dictionary (with dictionary expansion) as the passed **kwargs.",
					"title": "CVE description"
				}
			],
			"product_status": {
				"recommended": [
					"openSUSE Tumbleweed:python311-Django-5.1.5-1.1.aarch64",
					"openSUSE Tumbleweed:python311-Django-5.1.5-1.1.ppc64le",
					"openSUSE Tumbleweed:python311-Django-5.1.5-1.1.s390x",
					"openSUSE Tumbleweed:python311-Django-5.1.5-1.1.x86_64",
					"openSUSE Tumbleweed:python312-Django-5.1.5-1.1.aarch64",
					"openSUSE Tumbleweed:python312-Django-5.1.5-1.1.ppc64le",
					"openSUSE Tumbleweed:python312-Django-5.1.5-1.1.s390x",
					"openSUSE Tumbleweed:python312-Django-5.1.5-1.1.x86_64",
					"openSUSE Tumbleweed:python313-Django-5.1.5-1.1.aarch64",
					"openSUSE Tumbleweed:python313-Django-5.1.5-1.1.ppc64le",
					"openSUSE Tumbleweed:python313-Django-5.1.5-1.1.s390x",
					"openSUSE Tumbleweed:python313-Django-5.1.5-1.1.x86_64"
				]
			},
			"references": [
				{
					"category": "external",
					"summary": "CVE-2022-28346",
					"url": "https://www.suse.com/security/cve/CVE-2022-28346"
				},
				{
					"category": "external",
					"summary": "SUSE Bug 1198398 for CVE-2022-28346",
					"url": "https://bugzilla.suse.com/1198398"
				}
			],
			"remediations": [
				{
					"category": "vendor_fix",
					"details": "To install this SUSE Security Update use the SUSE recommended installation methods like YaST online_update or \"zypper patch\".\n",
					"product_ids": [
						"openSUSE Tumbleweed:python311-Django-5.1.5-1.1.aarch64",
						"openSUSE Tumbleweed:python311-Django-5.1.5-1.1.ppc64le",
						"openSUSE Tumbleweed:python311-Django-5.1.5-1.1.s390x",
						"openSUSE Tumbleweed:python311-Django-5.1.5-1.1.x86_64",
						"openSUSE Tumbleweed:python312-Django-5.1.5-1.1.aarch64",
						"openSUSE Tumbleweed:python312-Django-5.1.5-1.1.ppc64le",
						"openSUSE Tumbleweed:python312-Django-5.1.5-1.1.s390x",
						"openSUSE Tumbleweed:python312-Django-5.1.5-1.1.x86_64",
						"openSUSE Tumbleweed:python313-Django-5.1.5-1.1.aarch64",
						"openSUSE Tumbleweed:python313-Django-5.1.5-1.1.ppc64le",
						"openSUSE Tumbleweed:python313-Django-5.1.5-1.1.s390x",
						"openSUSE Tumbleweed:python313-Django-5.1.5-1.1.x86_64"
					]
				}
			],
			"scores": [
				{
					"cvss_v3": {
						"baseScore": 7.3,
						"baseSeverity": "HIGH",
						"vectorString": "CVSS:3.1/AV:N/AC:L/PR:N/UI:N/S:U/C:L/I:L/A:L",
						"version": "3.1"
					},
					"products": [
						"openSUSE Tumbleweed:python311-Django-5.1.5-1.1.aarch64",
						"openSUSE Tumbleweed:python311-Django-5.1.5-1.1.ppc64le",
						"openSUSE Tumbleweed:python311-Django-5.1.5-1.1.s390x",
						"openSUSE Tumbleweed:python311-Django-5.1.5-1.1.x86_64",
						"openSUSE Tumbleweed:python312-Django-5.1.5-1.1.aarch64",
						"openSUSE Tumbleweed:python312-Django-5.1.5-1.1.ppc64le",
						"openSUSE Tumbleweed:python312-Django-5.1.5-1.1.s390x",
						"openSUSE Tumbleweed:python312-Django-5.1.5-1.1.x86_64",
						"openSUSE Tumbleweed:python313-Django-5.1.5-1.1.aarch64",
						"openSUSE Tumbleweed:python313-Django-5.1.5-1.1.ppc64le",
						"openSUSE Tumbleweed:python313-Django-5.1.5-1.1.s390x",
						"openSUSE Tumbleweed:python313-Django-5.1.5-1.1.x86_64"
					]
				}
			],
			"threats": [
				{
					"category": "impact",
					"date": "2025-01-17T00:00:00Z",
					"details": "important"
				}
			],
			"title": "CVE-2022-28346"
		},
		{
			"cve": "CVE-2022-28347",
			"ids": [
				{
					"system_name": "SUSE CVE Page",
					"text": "https://www.suse.com/security/cve/CVE-2022-28347"
				}
			],
			"notes": [
				{
					"category": "general",
					"text": "A SQL injection issue was discovered in QuerySet.explain() in Django 2.2 before 2.2.28, 3.2 before 3.2.13, and 4.0 before 4.0.4. This occurs by passing a crafted dictionary (with dictionary expansion) as the **options argument, and placing the injection payload in an option name.",
					"title": "CVE description"
				}
			],
			"product_status": {
				"recommended": [
					"openSUSE Tumbleweed:python311-Django-5.1.5-1.1.aarch64",
					"openSUSE Tumbleweed:python311-Django-5.1.5-1.1.ppc64le",
					"openSUSE Tumbleweed:python311-Django-5.1.5-1.1.s390x",
					"openSUSE Tumbleweed:python311-Django-5.1.5-1.1.x86_64",
					"openSUSE Tumbleweed:python312-Django-5.1.5-1.1.aarch64",
					"openSUSE Tumbleweed:python312-Django-5.1.5-1.1.ppc64le",
					"openSUSE Tumbleweed:python312-Django-5.1.5-1.1.s390x",
					"openSUSE Tumbleweed:python312-Django-5.1.5-1.1.x86_64",
					"openSUSE Tumbleweed:python313-Django-5.1.5-1.1.aarch64",
					"openSUSE Tumbleweed:python313-Django-5.1.5-1.1.ppc64le",
					"openSUSE Tumbleweed:python313-Django-5.1.5-1.1.s390x",
					"openSUSE Tumbleweed:python313-Django-5.1.5-1.1.x86_64"
				]
			},
			"references": [
				{
					"category": "external",
					"summary": "CVE-2022-28347",
					"url": "https://www.suse.com/security/cve/CVE-2022-28347"
				},
				{
					"category": "external",
					"summary": "SUSE Bug 1198399 for CVE-2022-28347",
					"url": "https://bugzilla.suse.com/1198399"
				}
			],
			"remediations": [
				{
					"category": "vendor_fix",
					"details": "To install this SUSE Security Update use the SUSE recommended installation methods like YaST online_update or \"zypper patch\".\n",
					"product_ids": [
						"openSUSE Tumbleweed:python311-Django-5.1.5-1.1.aarch64",
						"openSUSE Tumbleweed:python311-Django-5.1.5-1.1.ppc64le",
						"openSUSE Tumbleweed:python311-Django-5.1.5-1.1.s390x",
						"openSUSE Tumbleweed:python311-Django-5.1.5-1.1.x86_64",
						"openSUSE Tumbleweed:python312-Django-5.1.5-1.1.aarch64",
						"openSUSE Tumbleweed:python312-Django-5.1.5-1.1.ppc64le",
						"openSUSE Tumbleweed:python312-Django-5.1.5-1.1.s390x",
						"openSUSE Tumbleweed:python312-Django-5.1.5-1.1.x86_64",
						"openSUSE Tumbleweed:python313-Django-5.1.5-1.1.aarch64",
						"openSUSE Tumbleweed:python313-Django-5.1.5-1.1.ppc64le",
						"openSUSE Tumbleweed:python313-Django-5.1.5-1.1.s390x",
						"openSUSE Tumbleweed:python313-Django-5.1.5-1.1.x86_64"
					]
				}
			],
			"scores": [
				{
					"cvss_v3": {
						"baseScore": 7.3,
						"baseSeverity": "HIGH",
						"vectorString": "CVSS:3.1/AV:N/AC:L/PR:N/UI:N/S:U/C:L/I:L/A:L",
						"version": "3.1"
					},
					"products": [
						"openSUSE Tumbleweed:python311-Django-5.1.5-1.1.aarch64",
						"openSUSE Tumbleweed:python311-Django-5.1.5-1.1.ppc64le",
						"openSUSE Tumbleweed:python311-Django-5.1.5-1.1.s390x",
						"openSUSE Tumbleweed:python311-Django-5.1.5-1.1.x86_64",
						"openSUSE Tumbleweed:python312-Django-5.1.5-1.1.aarch64",
						"openSUSE Tumbleweed:python312-Django-5.1.5-1.1.ppc64le",
						"openSUSE Tumbleweed:python312-Django-5.1.5-1.1.s390x",
						"openSUSE Tumbleweed:python312-Django-5.1.5-1.1.x86_64",
						"openSUSE Tumbleweed:python313-Django-5.1.5-1.1.aarch64",
						"openSUSE Tumbleweed:python313-Django-5.1.5-1.1.ppc64le",
						"openSUSE Tumbleweed:python313-Django-5.1.5-1.1.s390x",
						"openSUSE Tumbleweed:python313-Django-5.1.5-1.1.x86_64"
					]
				}
			],
			"threats": [
				{
					"category": "impact",
					"date": "2025-01-17T00:00:00Z",
					"details": "important"
				}
			],
			"title": "CVE-2022-28347"
		},
		{
			"cve": "CVE-2022-34265",
			"ids": [
				{
					"system_name": "SUSE CVE Page",
					"text": "https://www.suse.com/security/cve/CVE-2022-34265"
				}
			],
			"notes": [
				{
					"category": "general",
					"text": "An issue was discovered in Django 3.2 before 3.2.14 and 4.0 before 4.0.6. The Trunc() and Extract() database functions are subject to SQL injection if untrusted data is used as a kind/lookup_name value. Applications that constrain the lookup name and kind choice to a known safe list are unaffected.",
					"title": "CVE description"
				}
			],
			"product_status": {
				"recommended": [
					"openSUSE Tumbleweed:python311-Django-5.1.5-1.1.aarch64",
					"openSUSE Tumbleweed:python311-Django-5.1.5-1.1.ppc64le",
					"openSUSE Tumbleweed:python311-Django-5.1.5-1.1.s390x",
					"openSUSE Tumbleweed:python311-Django-5.1.5-1.1.x86_64",
					"openSUSE Tumbleweed:python312-Django-5.1.5-1.1.aarch64",
					"openSUSE Tumbleweed:python312-Django-5.1.5-1.1.ppc64le",
					"openSUSE Tumbleweed:python312-Django-5.1.5-1.1.s390x",
					"openSUSE Tumbleweed:python312-Django-5.1.5-1.1.x86_64",
					"openSUSE Tumbleweed:python313-Django-5.1.5-1.1.aarch64",
					"openSUSE Tumbleweed:python313-Django-5.1.5-1.1.ppc64le",
					"openSUSE Tumbleweed:python313-Django-5.1.5-1.1.s390x",
					"openSUSE Tumbleweed:python313-Django-5.1.5-1.1.x86_64"
				]
			},
			"references": [
				{
					"category": "external",
					"summary": "CVE-2022-34265",
					"url": "https://www.suse.com/security/cve/CVE-2022-34265"
				},
				{
					"category": "external",
					"summary": "SUSE Bug 1201186 for CVE-2022-34265",
					"url": "https://bugzilla.suse.com/1201186"
				}
			],
			"remediations": [
				{
					"category": "vendor_fix",
					"details": "To install this SUSE Security Update use the SUSE recommended installation methods like YaST online_update or \"zypper patch\".\n",
					"product_ids": [
						"openSUSE Tumbleweed:python311-Django-5.1.5-1.1.aarch64",
						"openSUSE Tumbleweed:python311-Django-5.1.5-1.1.ppc64le",
						"openSUSE Tumbleweed:python311-Django-5.1.5-1.1.s390x",
						"openSUSE Tumbleweed:python311-Django-5.1.5-1.1.x86_64",
						"openSUSE Tumbleweed:python312-Django-5.1.5-1.1.aarch64",
						"openSUSE Tumbleweed:python312-Django-5.1.5-1.1.ppc64le",
						"openSUSE Tumbleweed:python312-Django-5.1.5-1.1.s390x",
						"openSUSE Tumbleweed:python312-Django-5.1.5-1.1.x86_64",
						"openSUSE Tumbleweed:python313-Django-5.1.5-1.1.aarch64",
						"openSUSE Tumbleweed:python313-Django-5.1.5-1.1.ppc64le",
						"openSUSE Tumbleweed:python313-Django-5.1.5-1.1.s390x",
						"openSUSE Tumbleweed:python313-Django-5.1.5-1.1.x86_64"
					]
				}
			],
			"scores": [
				{
					"cvss_v3": {
						"baseScore": 8.1,
						"baseSeverity": "HIGH",
						"vectorString": "CVSS:3.1/AV:N/AC:H/PR:N/UI:N/S:U/C:H/I:H/A:H",
						"version": "3.1"
					},
					"products": [
						"openSUSE Tumbleweed:python311-Django-5.1.5-1.1.aarch64",
						"openSUSE Tumbleweed:python311-Django-5.1.5-1.1.ppc64le",
						"openSUSE Tumbleweed:python311-Django-5.1.5-1.1.s390x",
						"openSUSE Tumbleweed:python311-Django-5.1.5-1.1.x86_64",
						"openSUSE Tumbleweed:python312-Django-5.1.5-1.1.aarch64",
						"openSUSE Tumbleweed:python312-Django-5.1.5-1.1.ppc64le",
						"openSUSE Tumbleweed:python312-Django-5.1.5-1.1.s390x",
						"openSUSE Tumbleweed:python312-Django-5.1.5-1.1.x86_64",
						"openSUSE Tumbleweed:python313-Django-5.1.5-1.1.aarch64",
						"openSUSE Tumbleweed:python313-Django-5.1.5-1.1.ppc64le",
						"openSUSE Tumbleweed:python313-Django-5.1.5-1.1.s390x",
						"openSUSE Tumbleweed:python313-Django-5.1.5-1.1.x86_64"
					]
				}
			],
			"threats": [
				{
					"category": "impact",
					"date": "2025-01-17T00:00:00Z",
					"details": "important"
				}
			],
			"title": "CVE-2022-34265"
		},
		{
			"cve": "CVE-2022-36359",
			"ids": [
				{
					"system_name": "SUSE CVE Page",
					"text": "https://www.suse.com/security/cve/CVE-2022-36359"
				}
			],
			"notes": [
				{
					"category": "general",
					"text": "An issue was discovered in the HTTP FileResponse class in Django 3.2 before 3.2.15 and 4.0 before 4.0.7. An application is vulnerable to a reflected file download (RFD) attack that sets the Content-Disposition header of a FileResponse when the filename is derived from user-supplied input.",
					"title": "CVE description"
				}
			],
			"product_status": {
				"recommended": [
					"openSUSE Tumbleweed:python311-Django-5.1.5-1.1.aarch64",
					"openSUSE Tumbleweed:python311-Django-5.1.5-1.1.ppc64le",
					"openSUSE Tumbleweed:python311-Django-5.1.5-1.1.s390x",
					"openSUSE Tumbleweed:python311-Django-5.1.5-1.1.x86_64",
					"openSUSE Tumbleweed:python312-Django-5.1.5-1.1.aarch64",
					"openSUSE Tumbleweed:python312-Django-5.1.5-1.1.ppc64le",
					"openSUSE Tumbleweed:python312-Django-5.1.5-1.1.s390x",
					"openSUSE Tumbleweed:python312-Django-5.1.5-1.1.x86_64",
					"openSUSE Tumbleweed:python313-Django-5.1.5-1.1.aarch64",
					"openSUSE Tumbleweed:python313-Django-5.1.5-1.1.ppc64le",
					"openSUSE Tumbleweed:python313-Django-5.1.5-1.1.s390x",
					"openSUSE Tumbleweed:python313-Django-5.1.5-1.1.x86_64"
				]
			},
			"references": [
				{
					"category": "external",
					"summary": "CVE-2022-36359",
					"url": "https://www.suse.com/security/cve/CVE-2022-36359"
				},
				{
					"category": "external",
					"summary": "SUSE Bug 1201923 for CVE-2022-36359",
					"url": "https://bugzilla.suse.com/1201923"
				}
			],
			"remediations": [
				{
					"category": "vendor_fix",
					"details": "To install this SUSE Security Update use the SUSE recommended installation methods like YaST online_update or \"zypper patch\".\n",
					"product_ids": [
						"openSUSE Tumbleweed:python311-Django-5.1.5-1.1.aarch64",
						"openSUSE Tumbleweed:python311-Django-5.1.5-1.1.ppc64le",
						"openSUSE Tumbleweed:python311-Django-5.1.5-1.1.s390x",
						"openSUSE Tumbleweed:python311-Django-5.1.5-1.1.x86_64",
						"openSUSE Tumbleweed:python312-Django-5.1.5-1.1.aarch64",
						"openSUSE Tumbleweed:python312-Django-5.1.5-1.1.ppc64le",
						"openSUSE Tumbleweed:python312-Django-5.1.5-1.1.s390x",
						"openSUSE Tumbleweed:python312-Django-5.1.5-1.1.x86_64",
						"openSUSE Tumbleweed:python313-Django-5.1.5-1.1.aarch64",
						"openSUSE Tumbleweed:python313-Django-5.1.5-1.1.ppc64le",
						"openSUSE Tumbleweed:python313-Django-5.1.5-1.1.s390x",
						"openSUSE Tumbleweed:python313-Django-5.1.5-1.1.x86_64"
					]
				}
			],
			"scores": [
				{
					"cvss_v3": {
						"baseScore": 7.3,
						"baseSeverity": "HIGH",
						"vectorString": "CVSS:3.1/AV:N/AC:L/PR:L/UI:R/S:U/C:H/I:H/A:N",
						"version": "3.1"
					},
					"products": [
						"openSUSE Tumbleweed:python311-Django-5.1.5-1.1.aarch64",
						"openSUSE Tumbleweed:python311-Django-5.1.5-1.1.ppc64le",
						"openSUSE Tumbleweed:python311-Django-5.1.5-1.1.s390x",
						"openSUSE Tumbleweed:python311-Django-5.1.5-1.1.x86_64",
						"openSUSE Tumbleweed:python312-Django-5.1.5-1.1.aarch64",
						"openSUSE Tumbleweed:python312-Django-5.1.5-1.1.ppc64le",
						"openSUSE Tumbleweed:python312-Django-5.1.5-1.1.s390x",
						"openSUSE Tumbleweed:python312-Django-5.1.5-1.1.x86_64",
						"openSUSE Tumbleweed:python313-Django-5.1.5-1.1.aarch64",
						"openSUSE Tumbleweed:python313-Django-5.1.5-1.1.ppc64le",
						"openSUSE Tumbleweed:python313-Django-5.1.5-1.1.s390x",
						"openSUSE Tumbleweed:python313-Django-5.1.5-1.1.x86_64"
					]
				}
			],
			"threats": [
				{
					"category": "impact",
					"date": "2025-01-17T00:00:00Z",
					"details": "important"
				}
			],
			"title": "CVE-2022-36359"
		},
		{
			"cve": "CVE-2022-41323",
			"ids": [
				{
					"system_name": "SUSE CVE Page",
					"text": "https://www.suse.com/security/cve/CVE-2022-41323"
				}
			],
			"notes": [
				{
					"category": "general",
					"text": "In Django 3.2 before 3.2.16, 4.0 before 4.0.8, and 4.1 before 4.1.2, internationalized URLs were subject to a potential denial of service attack via the locale parameter, which is treated as a regular expression.",
					"title": "CVE description"
				}
			],
			"product_status": {
				"recommended": [
					"openSUSE Tumbleweed:python311-Django-5.1.5-1.1.aarch64",
					"openSUSE Tumbleweed:python311-Django-5.1.5-1.1.ppc64le",
					"openSUSE Tumbleweed:python311-Django-5.1.5-1.1.s390x",
					"openSUSE Tumbleweed:python311-Django-5.1.5-1.1.x86_64",
					"openSUSE Tumbleweed:python312-Django-5.1.5-1.1.aarch64",
					"openSUSE Tumbleweed:python312-Django-5.1.5-1.1.ppc64le",
					"openSUSE Tumbleweed:python312-Django-5.1.5-1.1.s390x",
					"openSUSE Tumbleweed:python312-Django-5.1.5-1.1.x86_64",
					"openSUSE Tumbleweed:python313-Django-5.1.5-1.1.aarch64",
					"openSUSE Tumbleweed:python313-Django-5.1.5-1.1.ppc64le",
					"openSUSE Tumbleweed:python313-Django-5.1.5-1.1.s390x",
					"openSUSE Tumbleweed:python313-Django-5.1.5-1.1.x86_64"
				]
			},
			"references": [
				{
					"category": "external",
					"summary": "CVE-2022-41323",
					"url": "https://www.suse.com/security/cve/CVE-2022-41323"
				},
				{
					"category": "external",
					"summary": "SUSE Bug 1203793 for CVE-2022-41323",
					"url": "https://bugzilla.suse.com/1203793"
				}
			],
			"remediations": [
				{
					"category": "vendor_fix",
					"details": "To install this SUSE Security Update use the SUSE recommended installation methods like YaST online_update or \"zypper patch\".\n",
					"product_ids": [
						"openSUSE Tumbleweed:python311-Django-5.1.5-1.1.aarch64",
						"openSUSE Tumbleweed:python311-Django-5.1.5-1.1.ppc64le",
						"openSUSE Tumbleweed:python311-Django-5.1.5-1.1.s390x",
						"openSUSE Tumbleweed:python311-Django-5.1.5-1.1.x86_64",
						"openSUSE Tumbleweed:python312-Django-5.1.5-1.1.aarch64",
						"openSUSE Tumbleweed:python312-Django-5.1.5-1.1.ppc64le",
						"openSUSE Tumbleweed:python312-Django-5.1.5-1.1.s390x",
						"openSUSE Tumbleweed:python312-Django-5.1.5-1.1.x86_64",
						"openSUSE Tumbleweed:python313-Django-5.1.5-1.1.aarch64",
						"openSUSE Tumbleweed:python313-Django-5.1.5-1.1.ppc64le",
						"openSUSE Tumbleweed:python313-Django-5.1.5-1.1.s390x",
						"openSUSE Tumbleweed:python313-Django-5.1.5-1.1.x86_64"
					]
				}
			],
			"scores": [
				{
					"cvss_v3": {
						"baseScore": 7.5,
						"baseSeverity": "HIGH",
						"vectorString": "CVSS:3.1/AV:N/AC:L/PR:N/UI:N/S:U/C:N/I:N/A:H",
						"version": "3.1"
					},
					"products": [
						"openSUSE Tumbleweed:python311-Django-5.1.5-1.1.aarch64",
						"openSUSE Tumbleweed:python311-Django-5.1.5-1.1.ppc64le",
						"openSUSE Tumbleweed:python311-Django-5.1.5-1.1.s390x",
						"openSUSE Tumbleweed:python311-Django-5.1.5-1.1.x86_64",
						"openSUSE Tumbleweed:python312-Django-5.1.5-1.1.aarch64",
						"openSUSE Tumbleweed:python312-Django-5.1.5-1.1.ppc64le",
						"openSUSE Tumbleweed:python312-Django-5.1.5-1.1.s390x",
						"openSUSE Tumbleweed:python312-Django-5.1.5-1.1.x86_64",
						"openSUSE Tumbleweed:python313-Django-5.1.5-1.1.aarch64",
						"openSUSE Tumbleweed:python313-Django-5.1.5-1.1.ppc64le",
						"openSUSE Tumbleweed:python313-Django-5.1.5-1.1.s390x",
						"openSUSE Tumbleweed:python313-Django-5.1.5-1.1.x86_64"
					]
				}
			],
			"threats": [
				{
					"category": "impact",
					"date": "2025-01-17T00:00:00Z",
					"details": "important"
				}
			],
			"title": "CVE-2022-41323"
		},
		{
			"cve": "CVE-2023-23969",
			"ids": [
				{
					"system_name": "SUSE CVE Page",
					"text": "https://www.suse.com/security/cve/CVE-2023-23969"
				}
			],
			"notes": [
				{
					"category": "general",
					"text": "In Django 3.2 before 3.2.17, 4.0 before 4.0.9, and 4.1 before 4.1.6, the parsed values of Accept-Language headers are cached in order to avoid repetitive parsing. This leads to a potential denial-of-service vector via excessive memory usage if the raw value of Accept-Language headers is very large.",
					"title": "CVE description"
				}
			],
			"product_status": {
				"recommended": [
					"openSUSE Tumbleweed:python311-Django-5.1.5-1.1.aarch64",
					"openSUSE Tumbleweed:python311-Django-5.1.5-1.1.ppc64le",
					"openSUSE Tumbleweed:python311-Django-5.1.5-1.1.s390x",
					"openSUSE Tumbleweed:python311-Django-5.1.5-1.1.x86_64",
					"openSUSE Tumbleweed:python312-Django-5.1.5-1.1.aarch64",
					"openSUSE Tumbleweed:python312-Django-5.1.5-1.1.ppc64le",
					"openSUSE Tumbleweed:python312-Django-5.1.5-1.1.s390x",
					"openSUSE Tumbleweed:python312-Django-5.1.5-1.1.x86_64",
					"openSUSE Tumbleweed:python313-Django-5.1.5-1.1.aarch64",
					"openSUSE Tumbleweed:python313-Django-5.1.5-1.1.ppc64le",
					"openSUSE Tumbleweed:python313-Django-5.1.5-1.1.s390x",
					"openSUSE Tumbleweed:python313-Django-5.1.5-1.1.x86_64"
				]
			},
			"references": [
				{
					"category": "external",
					"summary": "CVE-2023-23969",
					"url": "https://www.suse.com/security/cve/CVE-2023-23969"
				},
				{
					"category": "external",
					"summary": "SUSE Bug 1207565 for CVE-2023-23969",
					"url": "https://bugzilla.suse.com/1207565"
				}
			],
			"remediations": [
				{
					"category": "vendor_fix",
					"details": "To install this SUSE Security Update use the SUSE recommended installation methods like YaST online_update or \"zypper patch\".\n",
					"product_ids": [
						"openSUSE Tumbleweed:python311-Django-5.1.5-1.1.aarch64",
						"openSUSE Tumbleweed:python311-Django-5.1.5-1.1.ppc64le",
						"openSUSE Tumbleweed:python311-Django-5.1.5-1.1.s390x",
						"openSUSE Tumbleweed:python311-Django-5.1.5-1.1.x86_64",
						"openSUSE Tumbleweed:python312-Django-5.1.5-1.1.aarch64",
						"openSUSE Tumbleweed:python312-Django-5.1.5-1.1.ppc64le",
						"openSUSE Tumbleweed:python312-Django-5.1.5-1.1.s390x",
						"openSUSE Tumbleweed:python312-Django-5.1.5-1.1.x86_64",
						"openSUSE Tumbleweed:python313-Django-5.1.5-1.1.aarch64",
						"openSUSE Tumbleweed:python313-Django-5.1.5-1.1.ppc64le",
						"openSUSE Tumbleweed:python313-Django-5.1.5-1.1.s390x",
						"openSUSE Tumbleweed:python313-Django-5.1.5-1.1.x86_64"
					]
				}
			],
			"scores": [
				{
					"cvss_v3": {
						"baseScore": 7.5,
						"baseSeverity": "HIGH",
						"vectorString": "CVSS:3.1/AV:N/AC:L/PR:N/UI:N/S:U/C:N/I:N/A:H",
						"version": "3.1"
					},
					"products": [
						"openSUSE Tumbleweed:python311-Django-5.1.5-1.1.aarch64",
						"openSUSE Tumbleweed:python311-Django-5.1.5-1.1.ppc64le",
						"openSUSE Tumbleweed:python311-Django-5.1.5-1.1.s390x",
						"openSUSE Tumbleweed:python311-Django-5.1.5-1.1.x86_64",
						"openSUSE Tumbleweed:python312-Django-5.1.5-1.1.aarch64",
						"openSUSE Tumbleweed:python312-Django-5.1.5-1.1.ppc64le",
						"openSUSE Tumbleweed:python312-Django-5.1.5-1.1.s390x",
						"openSUSE Tumbleweed:python312-Django-5.1.5-1.1.x86_64",
						"openSUSE Tumbleweed:python313-Django-5.1.5-1.1.aarch64",
						"openSUSE Tumbleweed:python313-Django-5.1.5-1.1.ppc64le",
						"openSUSE Tumbleweed:python313-Django-5.1.5-1.1.s390x",
						"openSUSE Tumbleweed:python313-Django-5.1.5-1.1.x86_64"
					]
				}
			],
			"threats": [
				{
					"category": "impact",
					"date": "2025-01-17T00:00:00Z",
					"details": "important"
				}
			],
			"title": "CVE-2023-23969"
		},
		{
			"cve": "CVE-2023-24580",
			"ids": [
				{
					"system_name": "SUSE CVE Page",
					"text": "https://www.suse.com/security/cve/CVE-2023-24580"
				}
			],
			"notes": [
				{
					"category": "general",
					"text": "An issue was discovered in the Multipart Request Parser in Django 3.2 before 3.2.18, 4.0 before 4.0.10, and 4.1 before 4.1.7. Passing certain inputs (e.g., an excessive number of parts) to multipart forms could result in too many open files or memory exhaustion, and provided a potential vector for a denial-of-service attack.",
					"title": "CVE description"
				}
			],
			"product_status": {
				"recommended": [
					"openSUSE Tumbleweed:python311-Django-5.1.5-1.1.aarch64",
					"openSUSE Tumbleweed:python311-Django-5.1.5-1.1.ppc64le",
					"openSUSE Tumbleweed:python311-Django-5.1.5-1.1.s390x",
					"openSUSE Tumbleweed:python311-Django-5.1.5-1.1.x86_64",
					"openSUSE Tumbleweed:python312-Django-5.1.5-1.1.aarch64",
					"openSUSE Tumbleweed:python312-Django-5.1.5-1.1.ppc64le",
					"openSUSE Tumbleweed:python312-Django-5.1.5-1.1.s390x",
					"openSUSE Tumbleweed:python312-Django-5.1.5-1.1.x86_64",
					"openSUSE Tumbleweed:python313-Django-5.1.5-1.1.aarch64",
					"openSUSE Tumbleweed:python313-Django-5.1.5-1.1.ppc64le",
					"openSUSE Tumbleweed:python313-Django-5.1.5-1.1.s390x",
					"openSUSE Tumbleweed:python313-Django-5.1.5-1.1.x86_64"
				]
			},
			"references": [
				{
					"category": "external",
					"summary": "CVE-2023-24580",
					"url": "https://www.suse.com/security/cve/CVE-2023-24580"
				},
				{
					"category": "external",
					"summary": "SUSE Bug 1208082 for CVE-2023-24580",
					"url": "https://bugzilla.suse.com/1208082"
				}
			],
			"remediations": [
				{
					"category": "vendor_fix",
					"details": "To install this SUSE Security Update use the SUSE recommended installation methods like YaST online_update or \"zypper patch\".\n",
					"product_ids": [
						"openSUSE Tumbleweed:python311-Django-5.1.5-1.1.aarch64",
						"openSUSE Tumbleweed:python311-Django-5.1.5-1.1.ppc64le",
						"openSUSE Tumbleweed:python311-Django-5.1.5-1.1.s390x",
						"openSUSE Tumbleweed:python311-Django-5.1.5-1.1.x86_64",
						"openSUSE Tumbleweed:python312-Django-5.1.5-1.1.aarch64",
						"openSUSE Tumbleweed:python312-Django-5.1.5-1.1.ppc64le",
						"openSUSE Tumbleweed:python312-Django-5.1.5-1.1.s390x",
						"openSUSE Tumbleweed:python312-Django-5.1.5-1.1.x86_64",
						"openSUSE Tumbleweed:python313-Django-5.1.5-1.1.aarch64",
						"openSUSE Tumbleweed:python313-Django-5.1.5-1.1.ppc64le",
						"openSUSE Tumbleweed:python313-Django-5.1.5-1.1.s390x",
						"openSUSE Tumbleweed:python313-Django-5.1.5-1.1.x86_64"
					]
				}
			],
			"scores": [
				{
					"cvss_v3": {
						"baseScore": 7.5,
						"baseSeverity": "HIGH",
						"vectorString": "CVSS:3.1/AV:N/AC:L/PR:N/UI:N/S:U/C:N/I:N/A:H",
						"version": "3.1"
					},
					"products": [
						"openSUSE Tumbleweed:python311-Django-5.1.5-1.1.aarch64",
						"openSUSE Tumbleweed:python311-Django-5.1.5-1.1.ppc64le",
						"openSUSE Tumbleweed:python311-Django-5.1.5-1.1.s390x",
						"openSUSE Tumbleweed:python311-Django-5.1.5-1.1.x86_64",
						"openSUSE Tumbleweed:python312-Django-5.1.5-1.1.aarch64",
						"openSUSE Tumbleweed:python312-Django-5.1.5-1.1.ppc64le",
						"openSUSE Tumbleweed:python312-Django-5.1.5-1.1.s390x",
						"openSUSE Tumbleweed:python312-Django-5.1.5-1.1.x86_64",
						"openSUSE Tumbleweed:python313-Django-5.1.5-1.1.aarch64",
						"openSUSE Tumbleweed:python313-Django-5.1.5-1.1.ppc64le",
						"openSUSE Tumbleweed:python313-Django-5.1.5-1.1.s390x",
						"openSUSE Tumbleweed:python313-Django-5.1.5-1.1.x86_64"
					]
				}
			],
			"threats": [
				{
					"category": "impact",
					"date": "2025-01-17T00:00:00Z",
					"details": "important"
				}
			],
			"title": "CVE-2023-24580"
		},
		{
			"cve": "CVE-2024-56374",
			"ids": [
				{
					"system_name": "SUSE CVE Page",
					"text": "https://www.suse.com/security/cve/CVE-2024-56374"
				}
			],
			"notes": [
				{
					"category": "general",
					"text": "An issue was discovered in Django 5.1 before 5.1.5, 5.0 before 5.0.11, and 4.2 before 4.2.18. Lack of upper-bound limit enforcement in strings passed when performing IPv6 validation could lead to a potential denial-of-service attack. The undocumented and private functions clean_ipv6_address and is_valid_ipv6_address are vulnerable, as is the django.forms.GenericIPAddressField form field. (The django.db.models.GenericIPAddressField model field is not affected.)",
					"title": "CVE description"
				}
			],
			"product_status": {
				"recommended": [
					"openSUSE Tumbleweed:python311-Django-5.1.5-1.1.aarch64",
					"openSUSE Tumbleweed:python311-Django-5.1.5-1.1.ppc64le",
					"openSUSE Tumbleweed:python311-Django-5.1.5-1.1.s390x",
					"openSUSE Tumbleweed:python311-Django-5.1.5-1.1.x86_64",
					"openSUSE Tumbleweed:python312-Django-5.1.5-1.1.aarch64",
					"openSUSE Tumbleweed:python312-Django-5.1.5-1.1.ppc64le",
					"openSUSE Tumbleweed:python312-Django-5.1.5-1.1.s390x",
					"openSUSE Tumbleweed:python312-Django-5.1.5-1.1.x86_64",
					"openSUSE Tumbleweed:python313-Django-5.1.5-1.1.aarch64",
					"openSUSE Tumbleweed:python313-Django-5.1.5-1.1.ppc64le",
					"openSUSE Tumbleweed:python313-Django-5.1.5-1.1.s390x",
					"openSUSE Tumbleweed:python313-Django-5.1.5-1.1.x86_64"
				]
			},
			"references": [
				{
					"category": "external",
					"summary": "CVE-2024-56374",
					"url": "https://www.suse.com/security/cve/CVE-2024-56374"
				},
				{
					"category": "external",
					"summary": "SUSE Bug 1235856 for CVE-2024-56374",
					"url": "https://bugzilla.suse.com/1235856"
				}
			],
			"remediations": [
				{
					"category": "vendor_fix",
					"details": "To install this SUSE Security Update use the SUSE recommended installation methods like YaST online_update or \"zypper patch\".\n",
					"product_ids": [
						"openSUSE Tumbleweed:python311-Django-5.1.5-1.1.aarch64",
						"openSUSE Tumbleweed:python311-Django-5.1.5-1.1.ppc64le",
						"openSUSE Tumbleweed:python311-Django-5.1.5-1.1.s390x",
						"openSUSE Tumbleweed:python311-Django-5.1.5-1.1.x86_64",
						"openSUSE Tumbleweed:python312-Django-5.1.5-1.1.aarch64",
						"openSUSE Tumbleweed:python312-Django-5.1.5-1.1.ppc64le",
						"openSUSE Tumbleweed:python312-Django-5.1.5-1.1.s390x",
						"openSUSE Tumbleweed:python312-Django-5.1.5-1.1.x86_64",
						"openSUSE Tumbleweed:python313-Django-5.1.5-1.1.aarch64",
						"openSUSE Tumbleweed:python313-Django-5.1.5-1.1.ppc64le",
						"openSUSE Tumbleweed:python313-Django-5.1.5-1.1.s390x",
						"openSUSE Tumbleweed:python313-Django-5.1.5-1.1.x86_64"
					]
				}
			],
			"scores": [
				{
					"cvss_v3": {
						"baseScore": 7.5,
						"baseSeverity": "HIGH",
						"vectorString": "CVSS:3.1/AV:N/AC:L/PR:N/UI:N/S:U/C:N/I:N/A:H",
						"version": "3.1"
					},
					"products": [
						"openSUSE Tumbleweed:python311-Django-5.1.5-1.1.aarch64",
						"openSUSE Tumbleweed:python311-Django-5.1.5-1.1.ppc64le",
						"openSUSE Tumbleweed:python311-Django-5.1.5-1.1.s390x",
						"openSUSE Tumbleweed:python311-Django-5.1.5-1.1.x86_64",
						"openSUSE Tumbleweed:python312-Django-5.1.5-1.1.aarch64",
						"openSUSE Tumbleweed:python312-Django-5.1.5-1.1.ppc64le",
						"openSUSE Tumbleweed:python312-Django-5.1.5-1.1.s390x",
						"openSUSE Tumbleweed:python312-Django-5.1.5-1.1.x86_64",
						"openSUSE Tumbleweed:python313-Django-5.1.5-1.1.aarch64",
						"openSUSE Tumbleweed:python313-Django-5.1.5-1.1.ppc64le",
						"openSUSE Tumbleweed:python313-Django-5.1.5-1.1.s390x",
						"openSUSE Tumbleweed:python313-Django-5.1.5-1.1.x86_64"
					]
				}
			],
			"threats": [
				{
					"category": "impact",
					"date": "2025-01-17T00:00:00Z",
					"details": "important"
				}
			],
			"title": "CVE-2024-56374"
		}
	]
}
