{
	"document": {
		"aggregate_severity": {
			"namespace": "https://www.suse.com/support/security/rating/",
			"text": "moderate"
		},
		"category": "csaf_security_advisory",
		"csaf_version": "2.0",
		"distribution": {
			"text": "Copyright 2024 SUSE LLC. All rights reserved.",
			"tlp": {
				"label": "WHITE",
				"url": "https://www.first.org/tlp/"
			}
		},
		"lang": "en",
		"notes": [
			{
				"category": "summary",
				"text": "python36-Django-3.2.7-2.3 on GA media",
				"title": "Title of the patch"
			},
			{
				"category": "description",
				"text": "These are all security issues fixed in the python36-Django-3.2.7-2.3 package on the GA media of openSUSE Tumbleweed.",
				"title": "Description of the patch"
			},
			{
				"category": "details",
				"text": "openSUSE-Tumbleweed-2024-11205",
				"title": "Patchnames"
			},
			{
				"category": "legal_disclaimer",
				"text": "CSAF 2.0 data is provided by SUSE under the Creative Commons License 4.0 with Attribution (CC-BY-4.0).",
				"title": "Terms of use"
			}
		],
		"publisher": {
			"category": "vendor",
			"contact_details": "https://www.suse.com/support/security/contact/",
			"name": "SUSE Product Security Team",
			"namespace": "https://www.suse.com/"
		},
		"references": [
			{
				"category": "external",
				"summary": "SUSE ratings",
				"url": "https://www.suse.com/support/security/rating/"
			},
			{
				"category": "self",
				"summary": "URL of this CSAF notice",
				"url": "https://ftp.suse.com/pub/projects/security/csaf/opensuse-su-2024_11205-1.json"
			},
			{
				"category": "self",
				"summary": "SUSE CVE CVE-2015-3982 page",
				"url": "https://www.suse.com/security/cve/CVE-2015-3982/"
			},
			{
				"category": "self",
				"summary": "SUSE CVE CVE-2015-5145 page",
				"url": "https://www.suse.com/security/cve/CVE-2015-5145/"
			},
			{
				"category": "self",
				"summary": "SUSE CVE CVE-2015-5963 page",
				"url": "https://www.suse.com/security/cve/CVE-2015-5963/"
			},
			{
				"category": "self",
				"summary": "SUSE CVE CVE-2016-7401 page",
				"url": "https://www.suse.com/security/cve/CVE-2016-7401/"
			},
			{
				"category": "self",
				"summary": "SUSE CVE CVE-2017-12794 page",
				"url": "https://www.suse.com/security/cve/CVE-2017-12794/"
			},
			{
				"category": "self",
				"summary": "SUSE CVE CVE-2017-7233 page",
				"url": "https://www.suse.com/security/cve/CVE-2017-7233/"
			},
			{
				"category": "self",
				"summary": "SUSE CVE CVE-2017-7234 page",
				"url": "https://www.suse.com/security/cve/CVE-2017-7234/"
			},
			{
				"category": "self",
				"summary": "SUSE CVE CVE-2018-16984 page",
				"url": "https://www.suse.com/security/cve/CVE-2018-16984/"
			},
			{
				"category": "self",
				"summary": "SUSE CVE CVE-2018-6188 page",
				"url": "https://www.suse.com/security/cve/CVE-2018-6188/"
			},
			{
				"category": "self",
				"summary": "SUSE CVE CVE-2018-7536 page",
				"url": "https://www.suse.com/security/cve/CVE-2018-7536/"
			},
			{
				"category": "self",
				"summary": "SUSE CVE CVE-2018-7537 page",
				"url": "https://www.suse.com/security/cve/CVE-2018-7537/"
			},
			{
				"category": "self",
				"summary": "SUSE CVE CVE-2019-11358 page",
				"url": "https://www.suse.com/security/cve/CVE-2019-11358/"
			},
			{
				"category": "self",
				"summary": "SUSE CVE CVE-2019-12308 page",
				"url": "https://www.suse.com/security/cve/CVE-2019-12308/"
			},
			{
				"category": "self",
				"summary": "SUSE CVE CVE-2019-12781 page",
				"url": "https://www.suse.com/security/cve/CVE-2019-12781/"
			},
			{
				"category": "self",
				"summary": "SUSE CVE CVE-2019-14232 page",
				"url": "https://www.suse.com/security/cve/CVE-2019-14232/"
			},
			{
				"category": "self",
				"summary": "SUSE CVE CVE-2019-19118 page",
				"url": "https://www.suse.com/security/cve/CVE-2019-19118/"
			},
			{
				"category": "self",
				"summary": "SUSE CVE CVE-2019-19844 page",
				"url": "https://www.suse.com/security/cve/CVE-2019-19844/"
			},
			{
				"category": "self",
				"summary": "SUSE CVE CVE-2019-3498 page",
				"url": "https://www.suse.com/security/cve/CVE-2019-3498/"
			},
			{
				"category": "self",
				"summary": "SUSE CVE CVE-2019-6975 page",
				"url": "https://www.suse.com/security/cve/CVE-2019-6975/"
			},
			{
				"category": "self",
				"summary": "SUSE CVE CVE-2020-13254 page",
				"url": "https://www.suse.com/security/cve/CVE-2020-13254/"
			},
			{
				"category": "self",
				"summary": "SUSE CVE CVE-2020-13596 page",
				"url": "https://www.suse.com/security/cve/CVE-2020-13596/"
			},
			{
				"category": "self",
				"summary": "SUSE CVE CVE-2020-24583 page",
				"url": "https://www.suse.com/security/cve/CVE-2020-24583/"
			},
			{
				"category": "self",
				"summary": "SUSE CVE CVE-2020-24584 page",
				"url": "https://www.suse.com/security/cve/CVE-2020-24584/"
			},
			{
				"category": "self",
				"summary": "SUSE CVE CVE-2020-7471 page",
				"url": "https://www.suse.com/security/cve/CVE-2020-7471/"
			},
			{
				"category": "self",
				"summary": "SUSE CVE CVE-2020-9402 page",
				"url": "https://www.suse.com/security/cve/CVE-2020-9402/"
			},
			{
				"category": "self",
				"summary": "SUSE CVE CVE-2021-31542 page",
				"url": "https://www.suse.com/security/cve/CVE-2021-31542/"
			},
			{
				"category": "self",
				"summary": "SUSE CVE CVE-2021-32052 page",
				"url": "https://www.suse.com/security/cve/CVE-2021-32052/"
			},
			{
				"category": "self",
				"summary": "SUSE CVE CVE-2021-33203 page",
				"url": "https://www.suse.com/security/cve/CVE-2021-33203/"
			},
			{
				"category": "self",
				"summary": "SUSE CVE CVE-2021-33571 page",
				"url": "https://www.suse.com/security/cve/CVE-2021-33571/"
			},
			{
				"category": "self",
				"summary": "SUSE CVE CVE-2021-35042 page",
				"url": "https://www.suse.com/security/cve/CVE-2021-35042/"
			}
		],
		"title": "python36-Django-3.2.7-2.3 on GA media",
		"tracking": {
			"current_release_date": "2024-06-15T00:00:00Z",
			"generator": {
				"date": "2024-06-15T00:00:00Z",
				"engine": {
					"name": "cve-database.git:bin/generate-csaf.pl",
					"version": "1"
				}
			},
			"id": "openSUSE-SU-2024:11205-1",
			"initial_release_date": "2024-06-15T00:00:00Z",
			"revision_history": [
				{
					"date": "2024-06-15T00:00:00Z",
					"number": "1",
					"summary": "Current version"
				}
			],
			"status": "final",
			"version": "1"
		}
	},
	"product_tree": {
		"branches": [
			{
				"branches": [
					{
						"branches": [
							{
								"category": "product_version",
								"name": "python36-Django-3.2.7-2.3.aarch64",
								"product": {
									"name": "python36-Django-3.2.7-2.3.aarch64",
									"product_id": "python36-Django-3.2.7-2.3.aarch64"
								}
							},
							{
								"category": "product_version",
								"name": "python38-Django-3.2.7-2.3.aarch64",
								"product": {
									"name": "python38-Django-3.2.7-2.3.aarch64",
									"product_id": "python38-Django-3.2.7-2.3.aarch64"
								}
							},
							{
								"category": "product_version",
								"name": "python39-Django-3.2.7-2.3.aarch64",
								"product": {
									"name": "python39-Django-3.2.7-2.3.aarch64",
									"product_id": "python39-Django-3.2.7-2.3.aarch64"
								}
							}
						],
						"category": "architecture",
						"name": "aarch64"
					},
					{
						"branches": [
							{
								"category": "product_version",
								"name": "python36-Django-3.2.7-2.3.ppc64le",
								"product": {
									"name": "python36-Django-3.2.7-2.3.ppc64le",
									"product_id": "python36-Django-3.2.7-2.3.ppc64le"
								}
							},
							{
								"category": "product_version",
								"name": "python38-Django-3.2.7-2.3.ppc64le",
								"product": {
									"name": "python38-Django-3.2.7-2.3.ppc64le",
									"product_id": "python38-Django-3.2.7-2.3.ppc64le"
								}
							},
							{
								"category": "product_version",
								"name": "python39-Django-3.2.7-2.3.ppc64le",
								"product": {
									"name": "python39-Django-3.2.7-2.3.ppc64le",
									"product_id": "python39-Django-3.2.7-2.3.ppc64le"
								}
							}
						],
						"category": "architecture",
						"name": "ppc64le"
					},
					{
						"branches": [
							{
								"category": "product_version",
								"name": "python36-Django-3.2.7-2.3.s390x",
								"product": {
									"name": "python36-Django-3.2.7-2.3.s390x",
									"product_id": "python36-Django-3.2.7-2.3.s390x"
								}
							},
							{
								"category": "product_version",
								"name": "python38-Django-3.2.7-2.3.s390x",
								"product": {
									"name": "python38-Django-3.2.7-2.3.s390x",
									"product_id": "python38-Django-3.2.7-2.3.s390x"
								}
							},
							{
								"category": "product_version",
								"name": "python39-Django-3.2.7-2.3.s390x",
								"product": {
									"name": "python39-Django-3.2.7-2.3.s390x",
									"product_id": "python39-Django-3.2.7-2.3.s390x"
								}
							}
						],
						"category": "architecture",
						"name": "s390x"
					},
					{
						"branches": [
							{
								"category": "product_version",
								"name": "python36-Django-3.2.7-2.3.x86_64",
								"product": {
									"name": "python36-Django-3.2.7-2.3.x86_64",
									"product_id": "python36-Django-3.2.7-2.3.x86_64"
								}
							},
							{
								"category": "product_version",
								"name": "python38-Django-3.2.7-2.3.x86_64",
								"product": {
									"name": "python38-Django-3.2.7-2.3.x86_64",
									"product_id": "python38-Django-3.2.7-2.3.x86_64"
								}
							},
							{
								"category": "product_version",
								"name": "python39-Django-3.2.7-2.3.x86_64",
								"product": {
									"name": "python39-Django-3.2.7-2.3.x86_64",
									"product_id": "python39-Django-3.2.7-2.3.x86_64"
								}
							}
						],
						"category": "architecture",
						"name": "x86_64"
					},
					{
						"branches": [
							{
								"category": "product_name",
								"name": "openSUSE Tumbleweed",
								"product": {
									"name": "openSUSE Tumbleweed",
									"product_id": "openSUSE Tumbleweed",
									"product_identification_helper": {
										"cpe": "cpe:/o:opensuse:tumbleweed"
									}
								}
							}
						],
						"category": "product_family",
						"name": "SUSE Linux Enterprise"
					}
				],
				"category": "vendor",
				"name": "SUSE"
			}
		],
		"relationships": [
			{
				"category": "default_component_of",
				"full_product_name": {
					"name": "python36-Django-3.2.7-2.3.aarch64 as component of openSUSE Tumbleweed",
					"product_id": "openSUSE Tumbleweed:python36-Django-3.2.7-2.3.aarch64"
				},
				"product_reference": "python36-Django-3.2.7-2.3.aarch64",
				"relates_to_product_reference": "openSUSE Tumbleweed"
			},
			{
				"category": "default_component_of",
				"full_product_name": {
					"name": "python36-Django-3.2.7-2.3.ppc64le as component of openSUSE Tumbleweed",
					"product_id": "openSUSE Tumbleweed:python36-Django-3.2.7-2.3.ppc64le"
				},
				"product_reference": "python36-Django-3.2.7-2.3.ppc64le",
				"relates_to_product_reference": "openSUSE Tumbleweed"
			},
			{
				"category": "default_component_of",
				"full_product_name": {
					"name": "python36-Django-3.2.7-2.3.s390x as component of openSUSE Tumbleweed",
					"product_id": "openSUSE Tumbleweed:python36-Django-3.2.7-2.3.s390x"
				},
				"product_reference": "python36-Django-3.2.7-2.3.s390x",
				"relates_to_product_reference": "openSUSE Tumbleweed"
			},
			{
				"category": "default_component_of",
				"full_product_name": {
					"name": "python36-Django-3.2.7-2.3.x86_64 as component of openSUSE Tumbleweed",
					"product_id": "openSUSE Tumbleweed:python36-Django-3.2.7-2.3.x86_64"
				},
				"product_reference": "python36-Django-3.2.7-2.3.x86_64",
				"relates_to_product_reference": "openSUSE Tumbleweed"
			},
			{
				"category": "default_component_of",
				"full_product_name": {
					"name": "python38-Django-3.2.7-2.3.aarch64 as component of openSUSE Tumbleweed",
					"product_id": "openSUSE Tumbleweed:python38-Django-3.2.7-2.3.aarch64"
				},
				"product_reference": "python38-Django-3.2.7-2.3.aarch64",
				"relates_to_product_reference": "openSUSE Tumbleweed"
			},
			{
				"category": "default_component_of",
				"full_product_name": {
					"name": "python38-Django-3.2.7-2.3.ppc64le as component of openSUSE Tumbleweed",
					"product_id": "openSUSE Tumbleweed:python38-Django-3.2.7-2.3.ppc64le"
				},
				"product_reference": "python38-Django-3.2.7-2.3.ppc64le",
				"relates_to_product_reference": "openSUSE Tumbleweed"
			},
			{
				"category": "default_component_of",
				"full_product_name": {
					"name": "python38-Django-3.2.7-2.3.s390x as component of openSUSE Tumbleweed",
					"product_id": "openSUSE Tumbleweed:python38-Django-3.2.7-2.3.s390x"
				},
				"product_reference": "python38-Django-3.2.7-2.3.s390x",
				"relates_to_product_reference": "openSUSE Tumbleweed"
			},
			{
				"category": "default_component_of",
				"full_product_name": {
					"name": "python38-Django-3.2.7-2.3.x86_64 as component of openSUSE Tumbleweed",
					"product_id": "openSUSE Tumbleweed:python38-Django-3.2.7-2.3.x86_64"
				},
				"product_reference": "python38-Django-3.2.7-2.3.x86_64",
				"relates_to_product_reference": "openSUSE Tumbleweed"
			},
			{
				"category": "default_component_of",
				"full_product_name": {
					"name": "python39-Django-3.2.7-2.3.aarch64 as component of openSUSE Tumbleweed",
					"product_id": "openSUSE Tumbleweed:python39-Django-3.2.7-2.3.aarch64"
				},
				"product_reference": "python39-Django-3.2.7-2.3.aarch64",
				"relates_to_product_reference": "openSUSE Tumbleweed"
			},
			{
				"category": "default_component_of",
				"full_product_name": {
					"name": "python39-Django-3.2.7-2.3.ppc64le as component of openSUSE Tumbleweed",
					"product_id": "openSUSE Tumbleweed:python39-Django-3.2.7-2.3.ppc64le"
				},
				"product_reference": "python39-Django-3.2.7-2.3.ppc64le",
				"relates_to_product_reference": "openSUSE Tumbleweed"
			},
			{
				"category": "default_component_of",
				"full_product_name": {
					"name": "python39-Django-3.2.7-2.3.s390x as component of openSUSE Tumbleweed",
					"product_id": "openSUSE Tumbleweed:python39-Django-3.2.7-2.3.s390x"
				},
				"product_reference": "python39-Django-3.2.7-2.3.s390x",
				"relates_to_product_reference": "openSUSE Tumbleweed"
			},
			{
				"category": "default_component_of",
				"full_product_name": {
					"name": "python39-Django-3.2.7-2.3.x86_64 as component of openSUSE Tumbleweed",
					"product_id": "openSUSE Tumbleweed:python39-Django-3.2.7-2.3.x86_64"
				},
				"product_reference": "python39-Django-3.2.7-2.3.x86_64",
				"relates_to_product_reference": "openSUSE Tumbleweed"
			}
		]
	},
	"vulnerabilities": [
		{
			"cve": "CVE-2015-3982",
			"ids": [
				{
					"system_name": "SUSE CVE Page",
					"text": "https://www.suse.com/security/cve/CVE-2015-3982"
				}
			],
			"notes": [
				{
					"category": "general",
					"text": "The session.flush function in the cached_db backend in Django 1.8.x before 1.8.2 does not properly flush the session, which allows remote attackers to hijack user sessions via an empty string in the session key.",
					"title": "CVE description"
				}
			],
			"product_status": {
				"recommended": [
					"openSUSE Tumbleweed:python36-Django-3.2.7-2.3.aarch64",
					"openSUSE Tumbleweed:python36-Django-3.2.7-2.3.ppc64le",
					"openSUSE Tumbleweed:python36-Django-3.2.7-2.3.s390x",
					"openSUSE Tumbleweed:python36-Django-3.2.7-2.3.x86_64",
					"openSUSE Tumbleweed:python38-Django-3.2.7-2.3.aarch64",
					"openSUSE Tumbleweed:python38-Django-3.2.7-2.3.ppc64le",
					"openSUSE Tumbleweed:python38-Django-3.2.7-2.3.s390x",
					"openSUSE Tumbleweed:python38-Django-3.2.7-2.3.x86_64",
					"openSUSE Tumbleweed:python39-Django-3.2.7-2.3.aarch64",
					"openSUSE Tumbleweed:python39-Django-3.2.7-2.3.ppc64le",
					"openSUSE Tumbleweed:python39-Django-3.2.7-2.3.s390x",
					"openSUSE Tumbleweed:python39-Django-3.2.7-2.3.x86_64"
				]
			},
			"references": [
				{
					"category": "external",
					"summary": "CVE-2015-3982",
					"url": "https://www.suse.com/security/cve/CVE-2015-3982"
				},
				{
					"category": "external",
					"summary": "SUSE Bug 932265 for CVE-2015-3982",
					"url": "https://bugzilla.suse.com/932265"
				}
			],
			"remediations": [
				{
					"category": "vendor_fix",
					"details": "To install this SUSE Security Update use the SUSE recommended installation methods like YaST online_update or \"zypper patch\".\n",
					"product_ids": [
						"openSUSE Tumbleweed:python36-Django-3.2.7-2.3.aarch64",
						"openSUSE Tumbleweed:python36-Django-3.2.7-2.3.ppc64le",
						"openSUSE Tumbleweed:python36-Django-3.2.7-2.3.s390x",
						"openSUSE Tumbleweed:python36-Django-3.2.7-2.3.x86_64",
						"openSUSE Tumbleweed:python38-Django-3.2.7-2.3.aarch64",
						"openSUSE Tumbleweed:python38-Django-3.2.7-2.3.ppc64le",
						"openSUSE Tumbleweed:python38-Django-3.2.7-2.3.s390x",
						"openSUSE Tumbleweed:python38-Django-3.2.7-2.3.x86_64",
						"openSUSE Tumbleweed:python39-Django-3.2.7-2.3.aarch64",
						"openSUSE Tumbleweed:python39-Django-3.2.7-2.3.ppc64le",
						"openSUSE Tumbleweed:python39-Django-3.2.7-2.3.s390x",
						"openSUSE Tumbleweed:python39-Django-3.2.7-2.3.x86_64"
					]
				}
			],
			"threats": [
				{
					"category": "impact",
					"date": "2024-06-15T00:00:00Z",
					"details": "moderate"
				}
			],
			"title": "CVE-2015-3982"
		},
		{
			"cve": "CVE-2015-5145",
			"ids": [
				{
					"system_name": "SUSE CVE Page",
					"text": "https://www.suse.com/security/cve/CVE-2015-5145"
				}
			],
			"notes": [
				{
					"category": "general",
					"text": "validators.URLValidator in Django 1.8.x before 1.8.3 allows remote attackers to cause a denial of service (CPU consumption) via unspecified vectors.",
					"title": "CVE description"
				}
			],
			"product_status": {
				"recommended": [
					"openSUSE Tumbleweed:python36-Django-3.2.7-2.3.aarch64",
					"openSUSE Tumbleweed:python36-Django-3.2.7-2.3.ppc64le",
					"openSUSE Tumbleweed:python36-Django-3.2.7-2.3.s390x",
					"openSUSE Tumbleweed:python36-Django-3.2.7-2.3.x86_64",
					"openSUSE Tumbleweed:python38-Django-3.2.7-2.3.aarch64",
					"openSUSE Tumbleweed:python38-Django-3.2.7-2.3.ppc64le",
					"openSUSE Tumbleweed:python38-Django-3.2.7-2.3.s390x",
					"openSUSE Tumbleweed:python38-Django-3.2.7-2.3.x86_64",
					"openSUSE Tumbleweed:python39-Django-3.2.7-2.3.aarch64",
					"openSUSE Tumbleweed:python39-Django-3.2.7-2.3.ppc64le",
					"openSUSE Tumbleweed:python39-Django-3.2.7-2.3.s390x",
					"openSUSE Tumbleweed:python39-Django-3.2.7-2.3.x86_64"
				]
			},
			"references": [
				{
					"category": "external",
					"summary": "CVE-2015-5145",
					"url": "https://www.suse.com/security/cve/CVE-2015-5145"
				},
				{
					"category": "external",
					"summary": "SUSE Bug 937524 for CVE-2015-5145",
					"url": "https://bugzilla.suse.com/937524"
				}
			],
			"remediations": [
				{
					"category": "vendor_fix",
					"details": "To install this SUSE Security Update use the SUSE recommended installation methods like YaST online_update or \"zypper patch\".\n",
					"product_ids": [
						"openSUSE Tumbleweed:python36-Django-3.2.7-2.3.aarch64",
						"openSUSE Tumbleweed:python36-Django-3.2.7-2.3.ppc64le",
						"openSUSE Tumbleweed:python36-Django-3.2.7-2.3.s390x",
						"openSUSE Tumbleweed:python36-Django-3.2.7-2.3.x86_64",
						"openSUSE Tumbleweed:python38-Django-3.2.7-2.3.aarch64",
						"openSUSE Tumbleweed:python38-Django-3.2.7-2.3.ppc64le",
						"openSUSE Tumbleweed:python38-Django-3.2.7-2.3.s390x",
						"openSUSE Tumbleweed:python38-Django-3.2.7-2.3.x86_64",
						"openSUSE Tumbleweed:python39-Django-3.2.7-2.3.aarch64",
						"openSUSE Tumbleweed:python39-Django-3.2.7-2.3.ppc64le",
						"openSUSE Tumbleweed:python39-Django-3.2.7-2.3.s390x",
						"openSUSE Tumbleweed:python39-Django-3.2.7-2.3.x86_64"
					]
				}
			],
			"threats": [
				{
					"category": "impact",
					"date": "2024-06-15T00:00:00Z",
					"details": "important"
				}
			],
			"title": "CVE-2015-5145"
		},
		{
			"cve": "CVE-2015-5963",
			"ids": [
				{
					"system_name": "SUSE CVE Page",
					"text": "https://www.suse.com/security/cve/CVE-2015-5963"
				}
			],
			"notes": [
				{
					"category": "general",
					"text": "contrib.sessions.middleware.SessionMiddleware in Django 1.8.x before 1.8.4, 1.7.x before 1.7.10, 1.4.x before 1.4.22, and possibly other versions allows remote attackers to cause a denial of service (session store consumption or session record removal) via a large number of requests to contrib.auth.views.logout, which triggers the creation of an empty session record.",
					"title": "CVE description"
				}
			],
			"product_status": {
				"recommended": [
					"openSUSE Tumbleweed:python36-Django-3.2.7-2.3.aarch64",
					"openSUSE Tumbleweed:python36-Django-3.2.7-2.3.ppc64le",
					"openSUSE Tumbleweed:python36-Django-3.2.7-2.3.s390x",
					"openSUSE Tumbleweed:python36-Django-3.2.7-2.3.x86_64",
					"openSUSE Tumbleweed:python38-Django-3.2.7-2.3.aarch64",
					"openSUSE Tumbleweed:python38-Django-3.2.7-2.3.ppc64le",
					"openSUSE Tumbleweed:python38-Django-3.2.7-2.3.s390x",
					"openSUSE Tumbleweed:python38-Django-3.2.7-2.3.x86_64",
					"openSUSE Tumbleweed:python39-Django-3.2.7-2.3.aarch64",
					"openSUSE Tumbleweed:python39-Django-3.2.7-2.3.ppc64le",
					"openSUSE Tumbleweed:python39-Django-3.2.7-2.3.s390x",
					"openSUSE Tumbleweed:python39-Django-3.2.7-2.3.x86_64"
				]
			},
			"references": [
				{
					"category": "external",
					"summary": "CVE-2015-5963",
					"url": "https://www.suse.com/security/cve/CVE-2015-5963"
				},
				{
					"category": "external",
					"summary": "SUSE Bug 941587 for CVE-2015-5963",
					"url": "https://bugzilla.suse.com/941587"
				}
			],
			"remediations": [
				{
					"category": "vendor_fix",
					"details": "To install this SUSE Security Update use the SUSE recommended installation methods like YaST online_update or \"zypper patch\".\n",
					"product_ids": [
						"openSUSE Tumbleweed:python36-Django-3.2.7-2.3.aarch64",
						"openSUSE Tumbleweed:python36-Django-3.2.7-2.3.ppc64le",
						"openSUSE Tumbleweed:python36-Django-3.2.7-2.3.s390x",
						"openSUSE Tumbleweed:python36-Django-3.2.7-2.3.x86_64",
						"openSUSE Tumbleweed:python38-Django-3.2.7-2.3.aarch64",
						"openSUSE Tumbleweed:python38-Django-3.2.7-2.3.ppc64le",
						"openSUSE Tumbleweed:python38-Django-3.2.7-2.3.s390x",
						"openSUSE Tumbleweed:python38-Django-3.2.7-2.3.x86_64",
						"openSUSE Tumbleweed:python39-Django-3.2.7-2.3.aarch64",
						"openSUSE Tumbleweed:python39-Django-3.2.7-2.3.ppc64le",
						"openSUSE Tumbleweed:python39-Django-3.2.7-2.3.s390x",
						"openSUSE Tumbleweed:python39-Django-3.2.7-2.3.x86_64"
					]
				}
			],
			"threats": [
				{
					"category": "impact",
					"date": "2024-06-15T00:00:00Z",
					"details": "moderate"
				}
			],
			"title": "CVE-2015-5963"
		},
		{
			"cve": "CVE-2016-7401",
			"ids": [
				{
					"system_name": "SUSE CVE Page",
					"text": "https://www.suse.com/security/cve/CVE-2016-7401"
				}
			],
			"notes": [
				{
					"category": "general",
					"text": "The cookie parsing code in Django before 1.8.15 and 1.9.x before 1.9.10, when used on a site with Google Analytics, allows remote attackers to bypass an intended CSRF protection mechanism by setting arbitrary cookies.",
					"title": "CVE description"
				}
			],
			"product_status": {
				"recommended": [
					"openSUSE Tumbleweed:python36-Django-3.2.7-2.3.aarch64",
					"openSUSE Tumbleweed:python36-Django-3.2.7-2.3.ppc64le",
					"openSUSE Tumbleweed:python36-Django-3.2.7-2.3.s390x",
					"openSUSE Tumbleweed:python36-Django-3.2.7-2.3.x86_64",
					"openSUSE Tumbleweed:python38-Django-3.2.7-2.3.aarch64",
					"openSUSE Tumbleweed:python38-Django-3.2.7-2.3.ppc64le",
					"openSUSE Tumbleweed:python38-Django-3.2.7-2.3.s390x",
					"openSUSE Tumbleweed:python38-Django-3.2.7-2.3.x86_64",
					"openSUSE Tumbleweed:python39-Django-3.2.7-2.3.aarch64",
					"openSUSE Tumbleweed:python39-Django-3.2.7-2.3.ppc64le",
					"openSUSE Tumbleweed:python39-Django-3.2.7-2.3.s390x",
					"openSUSE Tumbleweed:python39-Django-3.2.7-2.3.x86_64"
				]
			},
			"references": [
				{
					"category": "external",
					"summary": "CVE-2016-7401",
					"url": "https://www.suse.com/security/cve/CVE-2016-7401"
				},
				{
					"category": "external",
					"summary": "SUSE Bug 1001374 for CVE-2016-7401",
					"url": "https://bugzilla.suse.com/1001374"
				}
			],
			"remediations": [
				{
					"category": "vendor_fix",
					"details": "To install this SUSE Security Update use the SUSE recommended installation methods like YaST online_update or \"zypper patch\".\n",
					"product_ids": [
						"openSUSE Tumbleweed:python36-Django-3.2.7-2.3.aarch64",
						"openSUSE Tumbleweed:python36-Django-3.2.7-2.3.ppc64le",
						"openSUSE Tumbleweed:python36-Django-3.2.7-2.3.s390x",
						"openSUSE Tumbleweed:python36-Django-3.2.7-2.3.x86_64",
						"openSUSE Tumbleweed:python38-Django-3.2.7-2.3.aarch64",
						"openSUSE Tumbleweed:python38-Django-3.2.7-2.3.ppc64le",
						"openSUSE Tumbleweed:python38-Django-3.2.7-2.3.s390x",
						"openSUSE Tumbleweed:python38-Django-3.2.7-2.3.x86_64",
						"openSUSE Tumbleweed:python39-Django-3.2.7-2.3.aarch64",
						"openSUSE Tumbleweed:python39-Django-3.2.7-2.3.ppc64le",
						"openSUSE Tumbleweed:python39-Django-3.2.7-2.3.s390x",
						"openSUSE Tumbleweed:python39-Django-3.2.7-2.3.x86_64"
					]
				}
			],
			"scores": [
				{
					"cvss_v3": {
						"baseScore": 6.1,
						"baseSeverity": "MEDIUM",
						"vectorString": "CVSS:3.1/AV:N/AC:L/PR:N/UI:R/S:C/C:L/I:L/A:N",
						"version": "3.1"
					},
					"products": [
						"openSUSE Tumbleweed:python36-Django-3.2.7-2.3.aarch64",
						"openSUSE Tumbleweed:python36-Django-3.2.7-2.3.ppc64le",
						"openSUSE Tumbleweed:python36-Django-3.2.7-2.3.s390x",
						"openSUSE Tumbleweed:python36-Django-3.2.7-2.3.x86_64",
						"openSUSE Tumbleweed:python38-Django-3.2.7-2.3.aarch64",
						"openSUSE Tumbleweed:python38-Django-3.2.7-2.3.ppc64le",
						"openSUSE Tumbleweed:python38-Django-3.2.7-2.3.s390x",
						"openSUSE Tumbleweed:python38-Django-3.2.7-2.3.x86_64",
						"openSUSE Tumbleweed:python39-Django-3.2.7-2.3.aarch64",
						"openSUSE Tumbleweed:python39-Django-3.2.7-2.3.ppc64le",
						"openSUSE Tumbleweed:python39-Django-3.2.7-2.3.s390x",
						"openSUSE Tumbleweed:python39-Django-3.2.7-2.3.x86_64"
					]
				}
			],
			"threats": [
				{
					"category": "impact",
					"date": "2024-06-15T00:00:00Z",
					"details": "moderate"
				}
			],
			"title": "CVE-2016-7401"
		},
		{
			"cve": "CVE-2017-12794",
			"ids": [
				{
					"system_name": "SUSE CVE Page",
					"text": "https://www.suse.com/security/cve/CVE-2017-12794"
				}
			],
			"notes": [
				{
					"category": "general",
					"text": "In Django 1.10.x before 1.10.8 and 1.11.x before 1.11.5, HTML autoescaping was disabled in a portion of the template for the technical 500 debug page. Given the right circumstances, this allowed a cross-site scripting attack. This vulnerability shouldn't affect most production sites since you shouldn't run with \"DEBUG = True\" (which makes this page accessible) in your production settings.",
					"title": "CVE description"
				}
			],
			"product_status": {
				"recommended": [
					"openSUSE Tumbleweed:python36-Django-3.2.7-2.3.aarch64",
					"openSUSE Tumbleweed:python36-Django-3.2.7-2.3.ppc64le",
					"openSUSE Tumbleweed:python36-Django-3.2.7-2.3.s390x",
					"openSUSE Tumbleweed:python36-Django-3.2.7-2.3.x86_64",
					"openSUSE Tumbleweed:python38-Django-3.2.7-2.3.aarch64",
					"openSUSE Tumbleweed:python38-Django-3.2.7-2.3.ppc64le",
					"openSUSE Tumbleweed:python38-Django-3.2.7-2.3.s390x",
					"openSUSE Tumbleweed:python38-Django-3.2.7-2.3.x86_64",
					"openSUSE Tumbleweed:python39-Django-3.2.7-2.3.aarch64",
					"openSUSE Tumbleweed:python39-Django-3.2.7-2.3.ppc64le",
					"openSUSE Tumbleweed:python39-Django-3.2.7-2.3.s390x",
					"openSUSE Tumbleweed:python39-Django-3.2.7-2.3.x86_64"
				]
			},
			"references": [
				{
					"category": "external",
					"summary": "CVE-2017-12794",
					"url": "https://www.suse.com/security/cve/CVE-2017-12794"
				},
				{
					"category": "external",
					"summary": "SUSE Bug 1056284 for CVE-2017-12794",
					"url": "https://bugzilla.suse.com/1056284"
				}
			],
			"remediations": [
				{
					"category": "vendor_fix",
					"details": "To install this SUSE Security Update use the SUSE recommended installation methods like YaST online_update or \"zypper patch\".\n",
					"product_ids": [
						"openSUSE Tumbleweed:python36-Django-3.2.7-2.3.aarch64",
						"openSUSE Tumbleweed:python36-Django-3.2.7-2.3.ppc64le",
						"openSUSE Tumbleweed:python36-Django-3.2.7-2.3.s390x",
						"openSUSE Tumbleweed:python36-Django-3.2.7-2.3.x86_64",
						"openSUSE Tumbleweed:python38-Django-3.2.7-2.3.aarch64",
						"openSUSE Tumbleweed:python38-Django-3.2.7-2.3.ppc64le",
						"openSUSE Tumbleweed:python38-Django-3.2.7-2.3.s390x",
						"openSUSE Tumbleweed:python38-Django-3.2.7-2.3.x86_64",
						"openSUSE Tumbleweed:python39-Django-3.2.7-2.3.aarch64",
						"openSUSE Tumbleweed:python39-Django-3.2.7-2.3.ppc64le",
						"openSUSE Tumbleweed:python39-Django-3.2.7-2.3.s390x",
						"openSUSE Tumbleweed:python39-Django-3.2.7-2.3.x86_64"
					]
				}
			],
			"scores": [
				{
					"cvss_v3": {
						"baseScore": 6.1,
						"baseSeverity": "MEDIUM",
						"vectorString": "CVSS:3.0/AV:N/AC:L/PR:N/UI:R/S:C/C:L/I:L/A:N",
						"version": "3.0"
					},
					"products": [
						"openSUSE Tumbleweed:python36-Django-3.2.7-2.3.aarch64",
						"openSUSE Tumbleweed:python36-Django-3.2.7-2.3.ppc64le",
						"openSUSE Tumbleweed:python36-Django-3.2.7-2.3.s390x",
						"openSUSE Tumbleweed:python36-Django-3.2.7-2.3.x86_64",
						"openSUSE Tumbleweed:python38-Django-3.2.7-2.3.aarch64",
						"openSUSE Tumbleweed:python38-Django-3.2.7-2.3.ppc64le",
						"openSUSE Tumbleweed:python38-Django-3.2.7-2.3.s390x",
						"openSUSE Tumbleweed:python38-Django-3.2.7-2.3.x86_64",
						"openSUSE Tumbleweed:python39-Django-3.2.7-2.3.aarch64",
						"openSUSE Tumbleweed:python39-Django-3.2.7-2.3.ppc64le",
						"openSUSE Tumbleweed:python39-Django-3.2.7-2.3.s390x",
						"openSUSE Tumbleweed:python39-Django-3.2.7-2.3.x86_64"
					]
				}
			],
			"threats": [
				{
					"category": "impact",
					"date": "2024-06-15T00:00:00Z",
					"details": "moderate"
				}
			],
			"title": "CVE-2017-12794"
		},
		{
			"cve": "CVE-2017-7233",
			"ids": [
				{
					"system_name": "SUSE CVE Page",
					"text": "https://www.suse.com/security/cve/CVE-2017-7233"
				}
			],
			"notes": [
				{
					"category": "general",
					"text": "Django 1.10 before 1.10.7, 1.9 before 1.9.13, and 1.8 before 1.8.18 relies on user input in some cases to redirect the user to an \"on success\" URL. The security check for these redirects (namely ``django.utils.http.is_safe_url()``) considered some numeric URLs \"safe\" when they shouldn't be, aka an open redirect vulnerability. Also, if a developer relies on ``is_safe_url()`` to provide safe redirect targets and puts such a URL into a link, they could suffer from an XSS attack.",
					"title": "CVE description"
				}
			],
			"product_status": {
				"recommended": [
					"openSUSE Tumbleweed:python36-Django-3.2.7-2.3.aarch64",
					"openSUSE Tumbleweed:python36-Django-3.2.7-2.3.ppc64le",
					"openSUSE Tumbleweed:python36-Django-3.2.7-2.3.s390x",
					"openSUSE Tumbleweed:python36-Django-3.2.7-2.3.x86_64",
					"openSUSE Tumbleweed:python38-Django-3.2.7-2.3.aarch64",
					"openSUSE Tumbleweed:python38-Django-3.2.7-2.3.ppc64le",
					"openSUSE Tumbleweed:python38-Django-3.2.7-2.3.s390x",
					"openSUSE Tumbleweed:python38-Django-3.2.7-2.3.x86_64",
					"openSUSE Tumbleweed:python39-Django-3.2.7-2.3.aarch64",
					"openSUSE Tumbleweed:python39-Django-3.2.7-2.3.ppc64le",
					"openSUSE Tumbleweed:python39-Django-3.2.7-2.3.s390x",
					"openSUSE Tumbleweed:python39-Django-3.2.7-2.3.x86_64"
				]
			},
			"references": [
				{
					"category": "external",
					"summary": "CVE-2017-7233",
					"url": "https://www.suse.com/security/cve/CVE-2017-7233"
				},
				{
					"category": "external",
					"summary": "SUSE Bug 1031450 for CVE-2017-7233",
					"url": "https://bugzilla.suse.com/1031450"
				}
			],
			"remediations": [
				{
					"category": "vendor_fix",
					"details": "To install this SUSE Security Update use the SUSE recommended installation methods like YaST online_update or \"zypper patch\".\n",
					"product_ids": [
						"openSUSE Tumbleweed:python36-Django-3.2.7-2.3.aarch64",
						"openSUSE Tumbleweed:python36-Django-3.2.7-2.3.ppc64le",
						"openSUSE Tumbleweed:python36-Django-3.2.7-2.3.s390x",
						"openSUSE Tumbleweed:python36-Django-3.2.7-2.3.x86_64",
						"openSUSE Tumbleweed:python38-Django-3.2.7-2.3.aarch64",
						"openSUSE Tumbleweed:python38-Django-3.2.7-2.3.ppc64le",
						"openSUSE Tumbleweed:python38-Django-3.2.7-2.3.s390x",
						"openSUSE Tumbleweed:python38-Django-3.2.7-2.3.x86_64",
						"openSUSE Tumbleweed:python39-Django-3.2.7-2.3.aarch64",
						"openSUSE Tumbleweed:python39-Django-3.2.7-2.3.ppc64le",
						"openSUSE Tumbleweed:python39-Django-3.2.7-2.3.s390x",
						"openSUSE Tumbleweed:python39-Django-3.2.7-2.3.x86_64"
					]
				}
			],
			"scores": [
				{
					"cvss_v3": {
						"baseScore": 6.1,
						"baseSeverity": "MEDIUM",
						"vectorString": "CVSS:3.0/AV:N/AC:L/PR:N/UI:R/S:C/C:L/I:L/A:N",
						"version": "3.0"
					},
					"products": [
						"openSUSE Tumbleweed:python36-Django-3.2.7-2.3.aarch64",
						"openSUSE Tumbleweed:python36-Django-3.2.7-2.3.ppc64le",
						"openSUSE Tumbleweed:python36-Django-3.2.7-2.3.s390x",
						"openSUSE Tumbleweed:python36-Django-3.2.7-2.3.x86_64",
						"openSUSE Tumbleweed:python38-Django-3.2.7-2.3.aarch64",
						"openSUSE Tumbleweed:python38-Django-3.2.7-2.3.ppc64le",
						"openSUSE Tumbleweed:python38-Django-3.2.7-2.3.s390x",
						"openSUSE Tumbleweed:python38-Django-3.2.7-2.3.x86_64",
						"openSUSE Tumbleweed:python39-Django-3.2.7-2.3.aarch64",
						"openSUSE Tumbleweed:python39-Django-3.2.7-2.3.ppc64le",
						"openSUSE Tumbleweed:python39-Django-3.2.7-2.3.s390x",
						"openSUSE Tumbleweed:python39-Django-3.2.7-2.3.x86_64"
					]
				}
			],
			"threats": [
				{
					"category": "impact",
					"date": "2024-06-15T00:00:00Z",
					"details": "low"
				}
			],
			"title": "CVE-2017-7233"
		},
		{
			"cve": "CVE-2017-7234",
			"ids": [
				{
					"system_name": "SUSE CVE Page",
					"text": "https://www.suse.com/security/cve/CVE-2017-7234"
				}
			],
			"notes": [
				{
					"category": "general",
					"text": "A maliciously crafted URL to a Django (1.10 before 1.10.7, 1.9 before 1.9.13, and 1.8 before 1.8.18) site using the ``django.views.static.serve()`` view could redirect to any other domain, aka an open redirect vulnerability.",
					"title": "CVE description"
				}
			],
			"product_status": {
				"recommended": [
					"openSUSE Tumbleweed:python36-Django-3.2.7-2.3.aarch64",
					"openSUSE Tumbleweed:python36-Django-3.2.7-2.3.ppc64le",
					"openSUSE Tumbleweed:python36-Django-3.2.7-2.3.s390x",
					"openSUSE Tumbleweed:python36-Django-3.2.7-2.3.x86_64",
					"openSUSE Tumbleweed:python38-Django-3.2.7-2.3.aarch64",
					"openSUSE Tumbleweed:python38-Django-3.2.7-2.3.ppc64le",
					"openSUSE Tumbleweed:python38-Django-3.2.7-2.3.s390x",
					"openSUSE Tumbleweed:python38-Django-3.2.7-2.3.x86_64",
					"openSUSE Tumbleweed:python39-Django-3.2.7-2.3.aarch64",
					"openSUSE Tumbleweed:python39-Django-3.2.7-2.3.ppc64le",
					"openSUSE Tumbleweed:python39-Django-3.2.7-2.3.s390x",
					"openSUSE Tumbleweed:python39-Django-3.2.7-2.3.x86_64"
				]
			},
			"references": [
				{
					"category": "external",
					"summary": "CVE-2017-7234",
					"url": "https://www.suse.com/security/cve/CVE-2017-7234"
				},
				{
					"category": "external",
					"summary": "SUSE Bug 1031451 for CVE-2017-7234",
					"url": "https://bugzilla.suse.com/1031451"
				}
			],
			"remediations": [
				{
					"category": "vendor_fix",
					"details": "To install this SUSE Security Update use the SUSE recommended installation methods like YaST online_update or \"zypper patch\".\n",
					"product_ids": [
						"openSUSE Tumbleweed:python36-Django-3.2.7-2.3.aarch64",
						"openSUSE Tumbleweed:python36-Django-3.2.7-2.3.ppc64le",
						"openSUSE Tumbleweed:python36-Django-3.2.7-2.3.s390x",
						"openSUSE Tumbleweed:python36-Django-3.2.7-2.3.x86_64",
						"openSUSE Tumbleweed:python38-Django-3.2.7-2.3.aarch64",
						"openSUSE Tumbleweed:python38-Django-3.2.7-2.3.ppc64le",
						"openSUSE Tumbleweed:python38-Django-3.2.7-2.3.s390x",
						"openSUSE Tumbleweed:python38-Django-3.2.7-2.3.x86_64",
						"openSUSE Tumbleweed:python39-Django-3.2.7-2.3.aarch64",
						"openSUSE Tumbleweed:python39-Django-3.2.7-2.3.ppc64le",
						"openSUSE Tumbleweed:python39-Django-3.2.7-2.3.s390x",
						"openSUSE Tumbleweed:python39-Django-3.2.7-2.3.x86_64"
					]
				}
			],
			"scores": [
				{
					"cvss_v3": {
						"baseScore": 6.1,
						"baseSeverity": "MEDIUM",
						"vectorString": "CVSS:3.0/AV:N/AC:L/PR:N/UI:R/S:C/C:L/I:L/A:N",
						"version": "3.0"
					},
					"products": [
						"openSUSE Tumbleweed:python36-Django-3.2.7-2.3.aarch64",
						"openSUSE Tumbleweed:python36-Django-3.2.7-2.3.ppc64le",
						"openSUSE Tumbleweed:python36-Django-3.2.7-2.3.s390x",
						"openSUSE Tumbleweed:python36-Django-3.2.7-2.3.x86_64",
						"openSUSE Tumbleweed:python38-Django-3.2.7-2.3.aarch64",
						"openSUSE Tumbleweed:python38-Django-3.2.7-2.3.ppc64le",
						"openSUSE Tumbleweed:python38-Django-3.2.7-2.3.s390x",
						"openSUSE Tumbleweed:python38-Django-3.2.7-2.3.x86_64",
						"openSUSE Tumbleweed:python39-Django-3.2.7-2.3.aarch64",
						"openSUSE Tumbleweed:python39-Django-3.2.7-2.3.ppc64le",
						"openSUSE Tumbleweed:python39-Django-3.2.7-2.3.s390x",
						"openSUSE Tumbleweed:python39-Django-3.2.7-2.3.x86_64"
					]
				}
			],
			"threats": [
				{
					"category": "impact",
					"date": "2024-06-15T00:00:00Z",
					"details": "low"
				}
			],
			"title": "CVE-2017-7234"
		},
		{
			"cve": "CVE-2018-16984",
			"ids": [
				{
					"system_name": "SUSE CVE Page",
					"text": "https://www.suse.com/security/cve/CVE-2018-16984"
				}
			],
			"notes": [
				{
					"category": "general",
					"text": "An issue was discovered in Django 2.1 before 2.1.2, in which unprivileged users can read the password hashes of arbitrary accounts. The read-only password widget used by the Django Admin to display an obfuscated password hash was bypassed if a user has only the \"view\" permission (new in Django 2.1), resulting in display of the entire password hash to those users. This may result in a vulnerability for sites with legacy user accounts using insecure hashes.",
					"title": "CVE description"
				}
			],
			"product_status": {
				"recommended": [
					"openSUSE Tumbleweed:python36-Django-3.2.7-2.3.aarch64",
					"openSUSE Tumbleweed:python36-Django-3.2.7-2.3.ppc64le",
					"openSUSE Tumbleweed:python36-Django-3.2.7-2.3.s390x",
					"openSUSE Tumbleweed:python36-Django-3.2.7-2.3.x86_64",
					"openSUSE Tumbleweed:python38-Django-3.2.7-2.3.aarch64",
					"openSUSE Tumbleweed:python38-Django-3.2.7-2.3.ppc64le",
					"openSUSE Tumbleweed:python38-Django-3.2.7-2.3.s390x",
					"openSUSE Tumbleweed:python38-Django-3.2.7-2.3.x86_64",
					"openSUSE Tumbleweed:python39-Django-3.2.7-2.3.aarch64",
					"openSUSE Tumbleweed:python39-Django-3.2.7-2.3.ppc64le",
					"openSUSE Tumbleweed:python39-Django-3.2.7-2.3.s390x",
					"openSUSE Tumbleweed:python39-Django-3.2.7-2.3.x86_64"
				]
			},
			"references": [
				{
					"category": "external",
					"summary": "CVE-2018-16984",
					"url": "https://www.suse.com/security/cve/CVE-2018-16984"
				},
				{
					"category": "external",
					"summary": "SUSE Bug 1109621 for CVE-2018-16984",
					"url": "https://bugzilla.suse.com/1109621"
				}
			],
			"remediations": [
				{
					"category": "vendor_fix",
					"details": "To install this SUSE Security Update use the SUSE recommended installation methods like YaST online_update or \"zypper patch\".\n",
					"product_ids": [
						"openSUSE Tumbleweed:python36-Django-3.2.7-2.3.aarch64",
						"openSUSE Tumbleweed:python36-Django-3.2.7-2.3.ppc64le",
						"openSUSE Tumbleweed:python36-Django-3.2.7-2.3.s390x",
						"openSUSE Tumbleweed:python36-Django-3.2.7-2.3.x86_64",
						"openSUSE Tumbleweed:python38-Django-3.2.7-2.3.aarch64",
						"openSUSE Tumbleweed:python38-Django-3.2.7-2.3.ppc64le",
						"openSUSE Tumbleweed:python38-Django-3.2.7-2.3.s390x",
						"openSUSE Tumbleweed:python38-Django-3.2.7-2.3.x86_64",
						"openSUSE Tumbleweed:python39-Django-3.2.7-2.3.aarch64",
						"openSUSE Tumbleweed:python39-Django-3.2.7-2.3.ppc64le",
						"openSUSE Tumbleweed:python39-Django-3.2.7-2.3.s390x",
						"openSUSE Tumbleweed:python39-Django-3.2.7-2.3.x86_64"
					]
				}
			],
			"scores": [
				{
					"cvss_v3": {
						"baseScore": 5.3,
						"baseSeverity": "MEDIUM",
						"vectorString": "CVSS:3.0/AV:N/AC:L/PR:N/UI:N/S:U/C:L/I:N/A:N",
						"version": "3.0"
					},
					"products": [
						"openSUSE Tumbleweed:python36-Django-3.2.7-2.3.aarch64",
						"openSUSE Tumbleweed:python36-Django-3.2.7-2.3.ppc64le",
						"openSUSE Tumbleweed:python36-Django-3.2.7-2.3.s390x",
						"openSUSE Tumbleweed:python36-Django-3.2.7-2.3.x86_64",
						"openSUSE Tumbleweed:python38-Django-3.2.7-2.3.aarch64",
						"openSUSE Tumbleweed:python38-Django-3.2.7-2.3.ppc64le",
						"openSUSE Tumbleweed:python38-Django-3.2.7-2.3.s390x",
						"openSUSE Tumbleweed:python38-Django-3.2.7-2.3.x86_64",
						"openSUSE Tumbleweed:python39-Django-3.2.7-2.3.aarch64",
						"openSUSE Tumbleweed:python39-Django-3.2.7-2.3.ppc64le",
						"openSUSE Tumbleweed:python39-Django-3.2.7-2.3.s390x",
						"openSUSE Tumbleweed:python39-Django-3.2.7-2.3.x86_64"
					]
				}
			],
			"threats": [
				{
					"category": "impact",
					"date": "2024-06-15T00:00:00Z",
					"details": "moderate"
				}
			],
			"title": "CVE-2018-16984"
		},
		{
			"cve": "CVE-2018-6188",
			"ids": [
				{
					"system_name": "SUSE CVE Page",
					"text": "https://www.suse.com/security/cve/CVE-2018-6188"
				}
			],
			"notes": [
				{
					"category": "general",
					"text": "django.contrib.auth.forms.AuthenticationForm in Django 2.0 before 2.0.2, and 1.11.8 and 1.11.9, allows remote attackers to obtain potentially sensitive information by leveraging data exposure from the confirm_login_allowed() method, as demonstrated by discovering whether a user account is inactive.",
					"title": "CVE description"
				}
			],
			"product_status": {
				"recommended": [
					"openSUSE Tumbleweed:python36-Django-3.2.7-2.3.aarch64",
					"openSUSE Tumbleweed:python36-Django-3.2.7-2.3.ppc64le",
					"openSUSE Tumbleweed:python36-Django-3.2.7-2.3.s390x",
					"openSUSE Tumbleweed:python36-Django-3.2.7-2.3.x86_64",
					"openSUSE Tumbleweed:python38-Django-3.2.7-2.3.aarch64",
					"openSUSE Tumbleweed:python38-Django-3.2.7-2.3.ppc64le",
					"openSUSE Tumbleweed:python38-Django-3.2.7-2.3.s390x",
					"openSUSE Tumbleweed:python38-Django-3.2.7-2.3.x86_64",
					"openSUSE Tumbleweed:python39-Django-3.2.7-2.3.aarch64",
					"openSUSE Tumbleweed:python39-Django-3.2.7-2.3.ppc64le",
					"openSUSE Tumbleweed:python39-Django-3.2.7-2.3.s390x",
					"openSUSE Tumbleweed:python39-Django-3.2.7-2.3.x86_64"
				]
			},
			"references": [
				{
					"category": "external",
					"summary": "CVE-2018-6188",
					"url": "https://www.suse.com/security/cve/CVE-2018-6188"
				},
				{
					"category": "external",
					"summary": "SUSE Bug 1077714 for CVE-2018-6188",
					"url": "https://bugzilla.suse.com/1077714"
				}
			],
			"remediations": [
				{
					"category": "vendor_fix",
					"details": "To install this SUSE Security Update use the SUSE recommended installation methods like YaST online_update or \"zypper patch\".\n",
					"product_ids": [
						"openSUSE Tumbleweed:python36-Django-3.2.7-2.3.aarch64",
						"openSUSE Tumbleweed:python36-Django-3.2.7-2.3.ppc64le",
						"openSUSE Tumbleweed:python36-Django-3.2.7-2.3.s390x",
						"openSUSE Tumbleweed:python36-Django-3.2.7-2.3.x86_64",
						"openSUSE Tumbleweed:python38-Django-3.2.7-2.3.aarch64",
						"openSUSE Tumbleweed:python38-Django-3.2.7-2.3.ppc64le",
						"openSUSE Tumbleweed:python38-Django-3.2.7-2.3.s390x",
						"openSUSE Tumbleweed:python38-Django-3.2.7-2.3.x86_64",
						"openSUSE Tumbleweed:python39-Django-3.2.7-2.3.aarch64",
						"openSUSE Tumbleweed:python39-Django-3.2.7-2.3.ppc64le",
						"openSUSE Tumbleweed:python39-Django-3.2.7-2.3.s390x",
						"openSUSE Tumbleweed:python39-Django-3.2.7-2.3.x86_64"
					]
				}
			],
			"scores": [
				{
					"cvss_v3": {
						"baseScore": 7.5,
						"baseSeverity": "HIGH",
						"vectorString": "CVSS:3.0/AV:N/AC:L/PR:N/UI:N/S:U/C:H/I:N/A:N",
						"version": "3.0"
					},
					"products": [
						"openSUSE Tumbleweed:python36-Django-3.2.7-2.3.aarch64",
						"openSUSE Tumbleweed:python36-Django-3.2.7-2.3.ppc64le",
						"openSUSE Tumbleweed:python36-Django-3.2.7-2.3.s390x",
						"openSUSE Tumbleweed:python36-Django-3.2.7-2.3.x86_64",
						"openSUSE Tumbleweed:python38-Django-3.2.7-2.3.aarch64",
						"openSUSE Tumbleweed:python38-Django-3.2.7-2.3.ppc64le",
						"openSUSE Tumbleweed:python38-Django-3.2.7-2.3.s390x",
						"openSUSE Tumbleweed:python38-Django-3.2.7-2.3.x86_64",
						"openSUSE Tumbleweed:python39-Django-3.2.7-2.3.aarch64",
						"openSUSE Tumbleweed:python39-Django-3.2.7-2.3.ppc64le",
						"openSUSE Tumbleweed:python39-Django-3.2.7-2.3.s390x",
						"openSUSE Tumbleweed:python39-Django-3.2.7-2.3.x86_64"
					]
				}
			],
			"threats": [
				{
					"category": "impact",
					"date": "2024-06-15T00:00:00Z",
					"details": "important"
				}
			],
			"title": "CVE-2018-6188"
		},
		{
			"cve": "CVE-2018-7536",
			"ids": [
				{
					"system_name": "SUSE CVE Page",
					"text": "https://www.suse.com/security/cve/CVE-2018-7536"
				}
			],
			"notes": [
				{
					"category": "general",
					"text": "An issue was discovered in Django 2.0 before 2.0.3, 1.11 before 1.11.11, and 1.8 before 1.8.19. The django.utils.html.urlize() function was extremely slow to evaluate certain inputs due to catastrophic backtracking vulnerabilities in two regular expressions (only one regular expression for Django 1.8.x). The urlize() function is used to implement the urlize and urlizetrunc template filters, which were thus vulnerable.",
					"title": "CVE description"
				}
			],
			"product_status": {
				"recommended": [
					"openSUSE Tumbleweed:python36-Django-3.2.7-2.3.aarch64",
					"openSUSE Tumbleweed:python36-Django-3.2.7-2.3.ppc64le",
					"openSUSE Tumbleweed:python36-Django-3.2.7-2.3.s390x",
					"openSUSE Tumbleweed:python36-Django-3.2.7-2.3.x86_64",
					"openSUSE Tumbleweed:python38-Django-3.2.7-2.3.aarch64",
					"openSUSE Tumbleweed:python38-Django-3.2.7-2.3.ppc64le",
					"openSUSE Tumbleweed:python38-Django-3.2.7-2.3.s390x",
					"openSUSE Tumbleweed:python38-Django-3.2.7-2.3.x86_64",
					"openSUSE Tumbleweed:python39-Django-3.2.7-2.3.aarch64",
					"openSUSE Tumbleweed:python39-Django-3.2.7-2.3.ppc64le",
					"openSUSE Tumbleweed:python39-Django-3.2.7-2.3.s390x",
					"openSUSE Tumbleweed:python39-Django-3.2.7-2.3.x86_64"
				]
			},
			"references": [
				{
					"category": "external",
					"summary": "CVE-2018-7536",
					"url": "https://www.suse.com/security/cve/CVE-2018-7536"
				},
				{
					"category": "external",
					"summary": "SUSE Bug 1083304 for CVE-2018-7536",
					"url": "https://bugzilla.suse.com/1083304"
				}
			],
			"remediations": [
				{
					"category": "vendor_fix",
					"details": "To install this SUSE Security Update use the SUSE recommended installation methods like YaST online_update or \"zypper patch\".\n",
					"product_ids": [
						"openSUSE Tumbleweed:python36-Django-3.2.7-2.3.aarch64",
						"openSUSE Tumbleweed:python36-Django-3.2.7-2.3.ppc64le",
						"openSUSE Tumbleweed:python36-Django-3.2.7-2.3.s390x",
						"openSUSE Tumbleweed:python36-Django-3.2.7-2.3.x86_64",
						"openSUSE Tumbleweed:python38-Django-3.2.7-2.3.aarch64",
						"openSUSE Tumbleweed:python38-Django-3.2.7-2.3.ppc64le",
						"openSUSE Tumbleweed:python38-Django-3.2.7-2.3.s390x",
						"openSUSE Tumbleweed:python38-Django-3.2.7-2.3.x86_64",
						"openSUSE Tumbleweed:python39-Django-3.2.7-2.3.aarch64",
						"openSUSE Tumbleweed:python39-Django-3.2.7-2.3.ppc64le",
						"openSUSE Tumbleweed:python39-Django-3.2.7-2.3.s390x",
						"openSUSE Tumbleweed:python39-Django-3.2.7-2.3.x86_64"
					]
				}
			],
			"scores": [
				{
					"cvss_v3": {
						"baseScore": 5.3,
						"baseSeverity": "MEDIUM",
						"vectorString": "CVSS:3.0/AV:N/AC:L/PR:N/UI:N/S:U/C:N/I:N/A:L",
						"version": "3.0"
					},
					"products": [
						"openSUSE Tumbleweed:python36-Django-3.2.7-2.3.aarch64",
						"openSUSE Tumbleweed:python36-Django-3.2.7-2.3.ppc64le",
						"openSUSE Tumbleweed:python36-Django-3.2.7-2.3.s390x",
						"openSUSE Tumbleweed:python36-Django-3.2.7-2.3.x86_64",
						"openSUSE Tumbleweed:python38-Django-3.2.7-2.3.aarch64",
						"openSUSE Tumbleweed:python38-Django-3.2.7-2.3.ppc64le",
						"openSUSE Tumbleweed:python38-Django-3.2.7-2.3.s390x",
						"openSUSE Tumbleweed:python38-Django-3.2.7-2.3.x86_64",
						"openSUSE Tumbleweed:python39-Django-3.2.7-2.3.aarch64",
						"openSUSE Tumbleweed:python39-Django-3.2.7-2.3.ppc64le",
						"openSUSE Tumbleweed:python39-Django-3.2.7-2.3.s390x",
						"openSUSE Tumbleweed:python39-Django-3.2.7-2.3.x86_64"
					]
				}
			],
			"threats": [
				{
					"category": "impact",
					"date": "2024-06-15T00:00:00Z",
					"details": "moderate"
				}
			],
			"title": "CVE-2018-7536"
		},
		{
			"cve": "CVE-2018-7537",
			"ids": [
				{
					"system_name": "SUSE CVE Page",
					"text": "https://www.suse.com/security/cve/CVE-2018-7537"
				}
			],
			"notes": [
				{
					"category": "general",
					"text": "An issue was discovered in Django 2.0 before 2.0.3, 1.11 before 1.11.11, and 1.8 before 1.8.19. If django.utils.text.Truncator's chars() and words() methods were passed the html=True argument, they were extremely slow to evaluate certain inputs due to a catastrophic backtracking vulnerability in a regular expression. The chars() and words() methods are used to implement the truncatechars_html and truncatewords_html template filters, which were thus vulnerable.",
					"title": "CVE description"
				}
			],
			"product_status": {
				"recommended": [
					"openSUSE Tumbleweed:python36-Django-3.2.7-2.3.aarch64",
					"openSUSE Tumbleweed:python36-Django-3.2.7-2.3.ppc64le",
					"openSUSE Tumbleweed:python36-Django-3.2.7-2.3.s390x",
					"openSUSE Tumbleweed:python36-Django-3.2.7-2.3.x86_64",
					"openSUSE Tumbleweed:python38-Django-3.2.7-2.3.aarch64",
					"openSUSE Tumbleweed:python38-Django-3.2.7-2.3.ppc64le",
					"openSUSE Tumbleweed:python38-Django-3.2.7-2.3.s390x",
					"openSUSE Tumbleweed:python38-Django-3.2.7-2.3.x86_64",
					"openSUSE Tumbleweed:python39-Django-3.2.7-2.3.aarch64",
					"openSUSE Tumbleweed:python39-Django-3.2.7-2.3.ppc64le",
					"openSUSE Tumbleweed:python39-Django-3.2.7-2.3.s390x",
					"openSUSE Tumbleweed:python39-Django-3.2.7-2.3.x86_64"
				]
			},
			"references": [
				{
					"category": "external",
					"summary": "CVE-2018-7537",
					"url": "https://www.suse.com/security/cve/CVE-2018-7537"
				},
				{
					"category": "external",
					"summary": "SUSE Bug 1083305 for CVE-2018-7537",
					"url": "https://bugzilla.suse.com/1083305"
				}
			],
			"remediations": [
				{
					"category": "vendor_fix",
					"details": "To install this SUSE Security Update use the SUSE recommended installation methods like YaST online_update or \"zypper patch\".\n",
					"product_ids": [
						"openSUSE Tumbleweed:python36-Django-3.2.7-2.3.aarch64",
						"openSUSE Tumbleweed:python36-Django-3.2.7-2.3.ppc64le",
						"openSUSE Tumbleweed:python36-Django-3.2.7-2.3.s390x",
						"openSUSE Tumbleweed:python36-Django-3.2.7-2.3.x86_64",
						"openSUSE Tumbleweed:python38-Django-3.2.7-2.3.aarch64",
						"openSUSE Tumbleweed:python38-Django-3.2.7-2.3.ppc64le",
						"openSUSE Tumbleweed:python38-Django-3.2.7-2.3.s390x",
						"openSUSE Tumbleweed:python38-Django-3.2.7-2.3.x86_64",
						"openSUSE Tumbleweed:python39-Django-3.2.7-2.3.aarch64",
						"openSUSE Tumbleweed:python39-Django-3.2.7-2.3.ppc64le",
						"openSUSE Tumbleweed:python39-Django-3.2.7-2.3.s390x",
						"openSUSE Tumbleweed:python39-Django-3.2.7-2.3.x86_64"
					]
				}
			],
			"scores": [
				{
					"cvss_v3": {
						"baseScore": 5.3,
						"baseSeverity": "MEDIUM",
						"vectorString": "CVSS:3.1/AV:N/AC:L/PR:N/UI:N/S:U/C:N/I:N/A:L",
						"version": "3.1"
					},
					"products": [
						"openSUSE Tumbleweed:python36-Django-3.2.7-2.3.aarch64",
						"openSUSE Tumbleweed:python36-Django-3.2.7-2.3.ppc64le",
						"openSUSE Tumbleweed:python36-Django-3.2.7-2.3.s390x",
						"openSUSE Tumbleweed:python36-Django-3.2.7-2.3.x86_64",
						"openSUSE Tumbleweed:python38-Django-3.2.7-2.3.aarch64",
						"openSUSE Tumbleweed:python38-Django-3.2.7-2.3.ppc64le",
						"openSUSE Tumbleweed:python38-Django-3.2.7-2.3.s390x",
						"openSUSE Tumbleweed:python38-Django-3.2.7-2.3.x86_64",
						"openSUSE Tumbleweed:python39-Django-3.2.7-2.3.aarch64",
						"openSUSE Tumbleweed:python39-Django-3.2.7-2.3.ppc64le",
						"openSUSE Tumbleweed:python39-Django-3.2.7-2.3.s390x",
						"openSUSE Tumbleweed:python39-Django-3.2.7-2.3.x86_64"
					]
				}
			],
			"threats": [
				{
					"category": "impact",
					"date": "2024-06-15T00:00:00Z",
					"details": "moderate"
				}
			],
			"title": "CVE-2018-7537"
		},
		{
			"cve": "CVE-2019-11358",
			"ids": [
				{
					"system_name": "SUSE CVE Page",
					"text": "https://www.suse.com/security/cve/CVE-2019-11358"
				}
			],
			"notes": [
				{
					"category": "general",
					"text": "jQuery before 3.4.0, as used in Drupal, Backdrop CMS, and other products, mishandles jQuery.extend(true, {}, ...) because of Object.prototype pollution. If an unsanitized source object contained an enumerable __proto__ property, it could extend the native Object.prototype.",
					"title": "CVE description"
				}
			],
			"product_status": {
				"recommended": [
					"openSUSE Tumbleweed:python36-Django-3.2.7-2.3.aarch64",
					"openSUSE Tumbleweed:python36-Django-3.2.7-2.3.ppc64le",
					"openSUSE Tumbleweed:python36-Django-3.2.7-2.3.s390x",
					"openSUSE Tumbleweed:python36-Django-3.2.7-2.3.x86_64",
					"openSUSE Tumbleweed:python38-Django-3.2.7-2.3.aarch64",
					"openSUSE Tumbleweed:python38-Django-3.2.7-2.3.ppc64le",
					"openSUSE Tumbleweed:python38-Django-3.2.7-2.3.s390x",
					"openSUSE Tumbleweed:python38-Django-3.2.7-2.3.x86_64",
					"openSUSE Tumbleweed:python39-Django-3.2.7-2.3.aarch64",
					"openSUSE Tumbleweed:python39-Django-3.2.7-2.3.ppc64le",
					"openSUSE Tumbleweed:python39-Django-3.2.7-2.3.s390x",
					"openSUSE Tumbleweed:python39-Django-3.2.7-2.3.x86_64"
				]
			},
			"references": [
				{
					"category": "external",
					"summary": "CVE-2019-11358",
					"url": "https://www.suse.com/security/cve/CVE-2019-11358"
				}
			],
			"remediations": [
				{
					"category": "vendor_fix",
					"details": "To install this SUSE Security Update use the SUSE recommended installation methods like YaST online_update or \"zypper patch\".\n",
					"product_ids": [
						"openSUSE Tumbleweed:python36-Django-3.2.7-2.3.aarch64",
						"openSUSE Tumbleweed:python36-Django-3.2.7-2.3.ppc64le",
						"openSUSE Tumbleweed:python36-Django-3.2.7-2.3.s390x",
						"openSUSE Tumbleweed:python36-Django-3.2.7-2.3.x86_64",
						"openSUSE Tumbleweed:python38-Django-3.2.7-2.3.aarch64",
						"openSUSE Tumbleweed:python38-Django-3.2.7-2.3.ppc64le",
						"openSUSE Tumbleweed:python38-Django-3.2.7-2.3.s390x",
						"openSUSE Tumbleweed:python38-Django-3.2.7-2.3.x86_64",
						"openSUSE Tumbleweed:python39-Django-3.2.7-2.3.aarch64",
						"openSUSE Tumbleweed:python39-Django-3.2.7-2.3.ppc64le",
						"openSUSE Tumbleweed:python39-Django-3.2.7-2.3.s390x",
						"openSUSE Tumbleweed:python39-Django-3.2.7-2.3.x86_64"
					]
				}
			],
			"scores": [
				{
					"cvss_v3": {
						"baseScore": 6.1,
						"baseSeverity": "MEDIUM",
						"vectorString": "CVSS:3.1/AV:N/AC:L/PR:N/UI:R/S:C/C:L/I:L/A:N",
						"version": "3.1"
					},
					"products": [
						"openSUSE Tumbleweed:python36-Django-3.2.7-2.3.aarch64",
						"openSUSE Tumbleweed:python36-Django-3.2.7-2.3.ppc64le",
						"openSUSE Tumbleweed:python36-Django-3.2.7-2.3.s390x",
						"openSUSE Tumbleweed:python36-Django-3.2.7-2.3.x86_64",
						"openSUSE Tumbleweed:python38-Django-3.2.7-2.3.aarch64",
						"openSUSE Tumbleweed:python38-Django-3.2.7-2.3.ppc64le",
						"openSUSE Tumbleweed:python38-Django-3.2.7-2.3.s390x",
						"openSUSE Tumbleweed:python38-Django-3.2.7-2.3.x86_64",
						"openSUSE Tumbleweed:python39-Django-3.2.7-2.3.aarch64",
						"openSUSE Tumbleweed:python39-Django-3.2.7-2.3.ppc64le",
						"openSUSE Tumbleweed:python39-Django-3.2.7-2.3.s390x",
						"openSUSE Tumbleweed:python39-Django-3.2.7-2.3.x86_64"
					]
				}
			],
			"threats": [
				{
					"category": "impact",
					"date": "2024-06-15T00:00:00Z",
					"details": "moderate"
				}
			],
			"title": "CVE-2019-11358"
		},
		{
			"cve": "CVE-2019-12308",
			"ids": [
				{
					"system_name": "SUSE CVE Page",
					"text": "https://www.suse.com/security/cve/CVE-2019-12308"
				}
			],
			"notes": [
				{
					"category": "general",
					"text": "An issue was discovered in Django 1.11 before 1.11.21, 2.1 before 2.1.9, and 2.2 before 2.2.2. The clickable Current URL value displayed by the AdminURLFieldWidget displays the provided value without validating it as a safe URL. Thus, an unvalidated value stored in the database, or a value provided as a URL query parameter payload, could result in an clickable JavaScript link.",
					"title": "CVE description"
				}
			],
			"product_status": {
				"recommended": [
					"openSUSE Tumbleweed:python36-Django-3.2.7-2.3.aarch64",
					"openSUSE Tumbleweed:python36-Django-3.2.7-2.3.ppc64le",
					"openSUSE Tumbleweed:python36-Django-3.2.7-2.3.s390x",
					"openSUSE Tumbleweed:python36-Django-3.2.7-2.3.x86_64",
					"openSUSE Tumbleweed:python38-Django-3.2.7-2.3.aarch64",
					"openSUSE Tumbleweed:python38-Django-3.2.7-2.3.ppc64le",
					"openSUSE Tumbleweed:python38-Django-3.2.7-2.3.s390x",
					"openSUSE Tumbleweed:python38-Django-3.2.7-2.3.x86_64",
					"openSUSE Tumbleweed:python39-Django-3.2.7-2.3.aarch64",
					"openSUSE Tumbleweed:python39-Django-3.2.7-2.3.ppc64le",
					"openSUSE Tumbleweed:python39-Django-3.2.7-2.3.s390x",
					"openSUSE Tumbleweed:python39-Django-3.2.7-2.3.x86_64"
				]
			},
			"references": [
				{
					"category": "external",
					"summary": "CVE-2019-12308",
					"url": "https://www.suse.com/security/cve/CVE-2019-12308"
				},
				{
					"category": "external",
					"summary": "SUSE Bug 1136468 for CVE-2019-12308",
					"url": "https://bugzilla.suse.com/1136468"
				}
			],
			"remediations": [
				{
					"category": "vendor_fix",
					"details": "To install this SUSE Security Update use the SUSE recommended installation methods like YaST online_update or \"zypper patch\".\n",
					"product_ids": [
						"openSUSE Tumbleweed:python36-Django-3.2.7-2.3.aarch64",
						"openSUSE Tumbleweed:python36-Django-3.2.7-2.3.ppc64le",
						"openSUSE Tumbleweed:python36-Django-3.2.7-2.3.s390x",
						"openSUSE Tumbleweed:python36-Django-3.2.7-2.3.x86_64",
						"openSUSE Tumbleweed:python38-Django-3.2.7-2.3.aarch64",
						"openSUSE Tumbleweed:python38-Django-3.2.7-2.3.ppc64le",
						"openSUSE Tumbleweed:python38-Django-3.2.7-2.3.s390x",
						"openSUSE Tumbleweed:python38-Django-3.2.7-2.3.x86_64",
						"openSUSE Tumbleweed:python39-Django-3.2.7-2.3.aarch64",
						"openSUSE Tumbleweed:python39-Django-3.2.7-2.3.ppc64le",
						"openSUSE Tumbleweed:python39-Django-3.2.7-2.3.s390x",
						"openSUSE Tumbleweed:python39-Django-3.2.7-2.3.x86_64"
					]
				}
			],
			"scores": [
				{
					"cvss_v3": {
						"baseScore": 6.1,
						"baseSeverity": "MEDIUM",
						"vectorString": "CVSS:3.0/AV:N/AC:L/PR:N/UI:R/S:C/C:L/I:L/A:N",
						"version": "3.0"
					},
					"products": [
						"openSUSE Tumbleweed:python36-Django-3.2.7-2.3.aarch64",
						"openSUSE Tumbleweed:python36-Django-3.2.7-2.3.ppc64le",
						"openSUSE Tumbleweed:python36-Django-3.2.7-2.3.s390x",
						"openSUSE Tumbleweed:python36-Django-3.2.7-2.3.x86_64",
						"openSUSE Tumbleweed:python38-Django-3.2.7-2.3.aarch64",
						"openSUSE Tumbleweed:python38-Django-3.2.7-2.3.ppc64le",
						"openSUSE Tumbleweed:python38-Django-3.2.7-2.3.s390x",
						"openSUSE Tumbleweed:python38-Django-3.2.7-2.3.x86_64",
						"openSUSE Tumbleweed:python39-Django-3.2.7-2.3.aarch64",
						"openSUSE Tumbleweed:python39-Django-3.2.7-2.3.ppc64le",
						"openSUSE Tumbleweed:python39-Django-3.2.7-2.3.s390x",
						"openSUSE Tumbleweed:python39-Django-3.2.7-2.3.x86_64"
					]
				}
			],
			"threats": [
				{
					"category": "impact",
					"date": "2024-06-15T00:00:00Z",
					"details": "moderate"
				}
			],
			"title": "CVE-2019-12308"
		},
		{
			"cve": "CVE-2019-12781",
			"ids": [
				{
					"system_name": "SUSE CVE Page",
					"text": "https://www.suse.com/security/cve/CVE-2019-12781"
				}
			],
			"notes": [
				{
					"category": "general",
					"text": "An issue was discovered in Django 1.11 before 1.11.22, 2.1 before 2.1.10, and 2.2 before 2.2.3. An HTTP request is not redirected to HTTPS when the SECURE_PROXY_SSL_HEADER and SECURE_SSL_REDIRECT settings are used, and the proxy connects to Django via HTTPS. In other words, django.http.HttpRequest.scheme has incorrect behavior when a client uses HTTP.",
					"title": "CVE description"
				}
			],
			"product_status": {
				"recommended": [
					"openSUSE Tumbleweed:python36-Django-3.2.7-2.3.aarch64",
					"openSUSE Tumbleweed:python36-Django-3.2.7-2.3.ppc64le",
					"openSUSE Tumbleweed:python36-Django-3.2.7-2.3.s390x",
					"openSUSE Tumbleweed:python36-Django-3.2.7-2.3.x86_64",
					"openSUSE Tumbleweed:python38-Django-3.2.7-2.3.aarch64",
					"openSUSE Tumbleweed:python38-Django-3.2.7-2.3.ppc64le",
					"openSUSE Tumbleweed:python38-Django-3.2.7-2.3.s390x",
					"openSUSE Tumbleweed:python38-Django-3.2.7-2.3.x86_64",
					"openSUSE Tumbleweed:python39-Django-3.2.7-2.3.aarch64",
					"openSUSE Tumbleweed:python39-Django-3.2.7-2.3.ppc64le",
					"openSUSE Tumbleweed:python39-Django-3.2.7-2.3.s390x",
					"openSUSE Tumbleweed:python39-Django-3.2.7-2.3.x86_64"
				]
			},
			"references": [
				{
					"category": "external",
					"summary": "CVE-2019-12781",
					"url": "https://www.suse.com/security/cve/CVE-2019-12781"
				},
				{
					"category": "external",
					"summary": "SUSE Bug 1124991 for CVE-2019-12781",
					"url": "https://bugzilla.suse.com/1124991"
				},
				{
					"category": "external",
					"summary": "SUSE Bug 1139945 for CVE-2019-12781",
					"url": "https://bugzilla.suse.com/1139945"
				}
			],
			"remediations": [
				{
					"category": "vendor_fix",
					"details": "To install this SUSE Security Update use the SUSE recommended installation methods like YaST online_update or \"zypper patch\".\n",
					"product_ids": [
						"openSUSE Tumbleweed:python36-Django-3.2.7-2.3.aarch64",
						"openSUSE Tumbleweed:python36-Django-3.2.7-2.3.ppc64le",
						"openSUSE Tumbleweed:python36-Django-3.2.7-2.3.s390x",
						"openSUSE Tumbleweed:python36-Django-3.2.7-2.3.x86_64",
						"openSUSE Tumbleweed:python38-Django-3.2.7-2.3.aarch64",
						"openSUSE Tumbleweed:python38-Django-3.2.7-2.3.ppc64le",
						"openSUSE Tumbleweed:python38-Django-3.2.7-2.3.s390x",
						"openSUSE Tumbleweed:python38-Django-3.2.7-2.3.x86_64",
						"openSUSE Tumbleweed:python39-Django-3.2.7-2.3.aarch64",
						"openSUSE Tumbleweed:python39-Django-3.2.7-2.3.ppc64le",
						"openSUSE Tumbleweed:python39-Django-3.2.7-2.3.s390x",
						"openSUSE Tumbleweed:python39-Django-3.2.7-2.3.x86_64"
					]
				}
			],
			"scores": [
				{
					"cvss_v3": {
						"baseScore": 6.5,
						"baseSeverity": "MEDIUM",
						"vectorString": "CVSS:3.0/AV:N/AC:L/PR:N/UI:N/S:U/C:L/I:L/A:N",
						"version": "3.0"
					},
					"products": [
						"openSUSE Tumbleweed:python36-Django-3.2.7-2.3.aarch64",
						"openSUSE Tumbleweed:python36-Django-3.2.7-2.3.ppc64le",
						"openSUSE Tumbleweed:python36-Django-3.2.7-2.3.s390x",
						"openSUSE Tumbleweed:python36-Django-3.2.7-2.3.x86_64",
						"openSUSE Tumbleweed:python38-Django-3.2.7-2.3.aarch64",
						"openSUSE Tumbleweed:python38-Django-3.2.7-2.3.ppc64le",
						"openSUSE Tumbleweed:python38-Django-3.2.7-2.3.s390x",
						"openSUSE Tumbleweed:python38-Django-3.2.7-2.3.x86_64",
						"openSUSE Tumbleweed:python39-Django-3.2.7-2.3.aarch64",
						"openSUSE Tumbleweed:python39-Django-3.2.7-2.3.ppc64le",
						"openSUSE Tumbleweed:python39-Django-3.2.7-2.3.s390x",
						"openSUSE Tumbleweed:python39-Django-3.2.7-2.3.x86_64"
					]
				}
			],
			"threats": [
				{
					"category": "impact",
					"date": "2024-06-15T00:00:00Z",
					"details": "moderate"
				}
			],
			"title": "CVE-2019-12781"
		},
		{
			"cve": "CVE-2019-14232",
			"ids": [
				{
					"system_name": "SUSE CVE Page",
					"text": "https://www.suse.com/security/cve/CVE-2019-14232"
				}
			],
			"notes": [
				{
					"category": "general",
					"text": "An issue was discovered in Django 1.11.x before 1.11.23, 2.1.x before 2.1.11, and 2.2.x before 2.2.4. If django.utils.text.Truncator's chars() and words() methods were passed the html=True argument, they were extremely slow to evaluate certain inputs due to a catastrophic backtracking vulnerability in a regular expression. The chars() and words() methods are used to implement the truncatechars_html and truncatewords_html template filters, which were thus vulnerable.",
					"title": "CVE description"
				}
			],
			"product_status": {
				"recommended": [
					"openSUSE Tumbleweed:python36-Django-3.2.7-2.3.aarch64",
					"openSUSE Tumbleweed:python36-Django-3.2.7-2.3.ppc64le",
					"openSUSE Tumbleweed:python36-Django-3.2.7-2.3.s390x",
					"openSUSE Tumbleweed:python36-Django-3.2.7-2.3.x86_64",
					"openSUSE Tumbleweed:python38-Django-3.2.7-2.3.aarch64",
					"openSUSE Tumbleweed:python38-Django-3.2.7-2.3.ppc64le",
					"openSUSE Tumbleweed:python38-Django-3.2.7-2.3.s390x",
					"openSUSE Tumbleweed:python38-Django-3.2.7-2.3.x86_64",
					"openSUSE Tumbleweed:python39-Django-3.2.7-2.3.aarch64",
					"openSUSE Tumbleweed:python39-Django-3.2.7-2.3.ppc64le",
					"openSUSE Tumbleweed:python39-Django-3.2.7-2.3.s390x",
					"openSUSE Tumbleweed:python39-Django-3.2.7-2.3.x86_64"
				]
			},
			"references": [
				{
					"category": "external",
					"summary": "CVE-2019-14232",
					"url": "https://www.suse.com/security/cve/CVE-2019-14232"
				},
				{
					"category": "external",
					"summary": "SUSE Bug 1142880 for CVE-2019-14232",
					"url": "https://bugzilla.suse.com/1142880"
				},
				{
					"category": "external",
					"summary": "SUSE Bug 1215978 for CVE-2019-14232",
					"url": "https://bugzilla.suse.com/1215978"
				},
				{
					"category": "external",
					"summary": "SUSE Bug 1220358 for CVE-2019-14232",
					"url": "https://bugzilla.suse.com/1220358"
				}
			],
			"remediations": [
				{
					"category": "vendor_fix",
					"details": "To install this SUSE Security Update use the SUSE recommended installation methods like YaST online_update or \"zypper patch\".\n",
					"product_ids": [
						"openSUSE Tumbleweed:python36-Django-3.2.7-2.3.aarch64",
						"openSUSE Tumbleweed:python36-Django-3.2.7-2.3.ppc64le",
						"openSUSE Tumbleweed:python36-Django-3.2.7-2.3.s390x",
						"openSUSE Tumbleweed:python36-Django-3.2.7-2.3.x86_64",
						"openSUSE Tumbleweed:python38-Django-3.2.7-2.3.aarch64",
						"openSUSE Tumbleweed:python38-Django-3.2.7-2.3.ppc64le",
						"openSUSE Tumbleweed:python38-Django-3.2.7-2.3.s390x",
						"openSUSE Tumbleweed:python38-Django-3.2.7-2.3.x86_64",
						"openSUSE Tumbleweed:python39-Django-3.2.7-2.3.aarch64",
						"openSUSE Tumbleweed:python39-Django-3.2.7-2.3.ppc64le",
						"openSUSE Tumbleweed:python39-Django-3.2.7-2.3.s390x",
						"openSUSE Tumbleweed:python39-Django-3.2.7-2.3.x86_64"
					]
				}
			],
			"scores": [
				{
					"cvss_v3": {
						"baseScore": 7.5,
						"baseSeverity": "HIGH",
						"vectorString": "CVSS:3.0/AV:N/AC:L/PR:N/UI:N/S:U/C:N/I:N/A:H",
						"version": "3.0"
					},
					"products": [
						"openSUSE Tumbleweed:python36-Django-3.2.7-2.3.aarch64",
						"openSUSE Tumbleweed:python36-Django-3.2.7-2.3.ppc64le",
						"openSUSE Tumbleweed:python36-Django-3.2.7-2.3.s390x",
						"openSUSE Tumbleweed:python36-Django-3.2.7-2.3.x86_64",
						"openSUSE Tumbleweed:python38-Django-3.2.7-2.3.aarch64",
						"openSUSE Tumbleweed:python38-Django-3.2.7-2.3.ppc64le",
						"openSUSE Tumbleweed:python38-Django-3.2.7-2.3.s390x",
						"openSUSE Tumbleweed:python38-Django-3.2.7-2.3.x86_64",
						"openSUSE Tumbleweed:python39-Django-3.2.7-2.3.aarch64",
						"openSUSE Tumbleweed:python39-Django-3.2.7-2.3.ppc64le",
						"openSUSE Tumbleweed:python39-Django-3.2.7-2.3.s390x",
						"openSUSE Tumbleweed:python39-Django-3.2.7-2.3.x86_64"
					]
				}
			],
			"threats": [
				{
					"category": "impact",
					"date": "2024-06-15T00:00:00Z",
					"details": "important"
				}
			],
			"title": "CVE-2019-14232"
		},
		{
			"cve": "CVE-2019-19118",
			"ids": [
				{
					"system_name": "SUSE CVE Page",
					"text": "https://www.suse.com/security/cve/CVE-2019-19118"
				}
			],
			"notes": [
				{
					"category": "general",
					"text": "Django 2.1 before 2.1.15 and 2.2 before 2.2.8 allows unintended model editing. A Django model admin displaying inline related models, where the user has view-only permissions to a parent model but edit permissions to the inline model, would be presented with an editing UI, allowing POST requests, for updating the inline model. Directly editing the view-only parent model was not possible, but the parent model's save() method was called, triggering potential side effects, and causing pre and post-save signal handlers to be invoked. (To resolve this, the Django admin is adjusted to require edit permissions on the parent model in order for inline models to be editable.)",
					"title": "CVE description"
				}
			],
			"product_status": {
				"recommended": [
					"openSUSE Tumbleweed:python36-Django-3.2.7-2.3.aarch64",
					"openSUSE Tumbleweed:python36-Django-3.2.7-2.3.ppc64le",
					"openSUSE Tumbleweed:python36-Django-3.2.7-2.3.s390x",
					"openSUSE Tumbleweed:python36-Django-3.2.7-2.3.x86_64",
					"openSUSE Tumbleweed:python38-Django-3.2.7-2.3.aarch64",
					"openSUSE Tumbleweed:python38-Django-3.2.7-2.3.ppc64le",
					"openSUSE Tumbleweed:python38-Django-3.2.7-2.3.s390x",
					"openSUSE Tumbleweed:python38-Django-3.2.7-2.3.x86_64",
					"openSUSE Tumbleweed:python39-Django-3.2.7-2.3.aarch64",
					"openSUSE Tumbleweed:python39-Django-3.2.7-2.3.ppc64le",
					"openSUSE Tumbleweed:python39-Django-3.2.7-2.3.s390x",
					"openSUSE Tumbleweed:python39-Django-3.2.7-2.3.x86_64"
				]
			},
			"references": [
				{
					"category": "external",
					"summary": "CVE-2019-19118",
					"url": "https://www.suse.com/security/cve/CVE-2019-19118"
				},
				{
					"category": "external",
					"summary": "SUSE Bug 1157705 for CVE-2019-19118",
					"url": "https://bugzilla.suse.com/1157705"
				}
			],
			"remediations": [
				{
					"category": "vendor_fix",
					"details": "To install this SUSE Security Update use the SUSE recommended installation methods like YaST online_update or \"zypper patch\".\n",
					"product_ids": [
						"openSUSE Tumbleweed:python36-Django-3.2.7-2.3.aarch64",
						"openSUSE Tumbleweed:python36-Django-3.2.7-2.3.ppc64le",
						"openSUSE Tumbleweed:python36-Django-3.2.7-2.3.s390x",
						"openSUSE Tumbleweed:python36-Django-3.2.7-2.3.x86_64",
						"openSUSE Tumbleweed:python38-Django-3.2.7-2.3.aarch64",
						"openSUSE Tumbleweed:python38-Django-3.2.7-2.3.ppc64le",
						"openSUSE Tumbleweed:python38-Django-3.2.7-2.3.s390x",
						"openSUSE Tumbleweed:python38-Django-3.2.7-2.3.x86_64",
						"openSUSE Tumbleweed:python39-Django-3.2.7-2.3.aarch64",
						"openSUSE Tumbleweed:python39-Django-3.2.7-2.3.ppc64le",
						"openSUSE Tumbleweed:python39-Django-3.2.7-2.3.s390x",
						"openSUSE Tumbleweed:python39-Django-3.2.7-2.3.x86_64"
					]
				}
			],
			"scores": [
				{
					"cvss_v3": {
						"baseScore": 6.5,
						"baseSeverity": "MEDIUM",
						"vectorString": "CVSS:3.1/AV:N/AC:L/PR:L/UI:N/S:U/C:N/I:H/A:N",
						"version": "3.1"
					},
					"products": [
						"openSUSE Tumbleweed:python36-Django-3.2.7-2.3.aarch64",
						"openSUSE Tumbleweed:python36-Django-3.2.7-2.3.ppc64le",
						"openSUSE Tumbleweed:python36-Django-3.2.7-2.3.s390x",
						"openSUSE Tumbleweed:python36-Django-3.2.7-2.3.x86_64",
						"openSUSE Tumbleweed:python38-Django-3.2.7-2.3.aarch64",
						"openSUSE Tumbleweed:python38-Django-3.2.7-2.3.ppc64le",
						"openSUSE Tumbleweed:python38-Django-3.2.7-2.3.s390x",
						"openSUSE Tumbleweed:python38-Django-3.2.7-2.3.x86_64",
						"openSUSE Tumbleweed:python39-Django-3.2.7-2.3.aarch64",
						"openSUSE Tumbleweed:python39-Django-3.2.7-2.3.ppc64le",
						"openSUSE Tumbleweed:python39-Django-3.2.7-2.3.s390x",
						"openSUSE Tumbleweed:python39-Django-3.2.7-2.3.x86_64"
					]
				}
			],
			"threats": [
				{
					"category": "impact",
					"date": "2024-06-15T00:00:00Z",
					"details": "moderate"
				}
			],
			"title": "CVE-2019-19118"
		},
		{
			"cve": "CVE-2019-19844",
			"ids": [
				{
					"system_name": "SUSE CVE Page",
					"text": "https://www.suse.com/security/cve/CVE-2019-19844"
				}
			],
			"notes": [
				{
					"category": "general",
					"text": "Django before 1.11.27, 2.x before 2.2.9, and 3.x before 3.0.1 allows account takeover. A suitably crafted email address (that is equal to an existing user's email address after case transformation of Unicode characters) would allow an attacker to be sent a password reset token for the matched user account. (One mitigation in the new releases is to send password reset tokens only to the registered user email address.)",
					"title": "CVE description"
				}
			],
			"product_status": {
				"recommended": [
					"openSUSE Tumbleweed:python36-Django-3.2.7-2.3.aarch64",
					"openSUSE Tumbleweed:python36-Django-3.2.7-2.3.ppc64le",
					"openSUSE Tumbleweed:python36-Django-3.2.7-2.3.s390x",
					"openSUSE Tumbleweed:python36-Django-3.2.7-2.3.x86_64",
					"openSUSE Tumbleweed:python38-Django-3.2.7-2.3.aarch64",
					"openSUSE Tumbleweed:python38-Django-3.2.7-2.3.ppc64le",
					"openSUSE Tumbleweed:python38-Django-3.2.7-2.3.s390x",
					"openSUSE Tumbleweed:python38-Django-3.2.7-2.3.x86_64",
					"openSUSE Tumbleweed:python39-Django-3.2.7-2.3.aarch64",
					"openSUSE Tumbleweed:python39-Django-3.2.7-2.3.ppc64le",
					"openSUSE Tumbleweed:python39-Django-3.2.7-2.3.s390x",
					"openSUSE Tumbleweed:python39-Django-3.2.7-2.3.x86_64"
				]
			},
			"references": [
				{
					"category": "external",
					"summary": "CVE-2019-19844",
					"url": "https://www.suse.com/security/cve/CVE-2019-19844"
				},
				{
					"category": "external",
					"summary": "SUSE Bug 1159447 for CVE-2019-19844",
					"url": "https://bugzilla.suse.com/1159447"
				}
			],
			"remediations": [
				{
					"category": "vendor_fix",
					"details": "To install this SUSE Security Update use the SUSE recommended installation methods like YaST online_update or \"zypper patch\".\n",
					"product_ids": [
						"openSUSE Tumbleweed:python36-Django-3.2.7-2.3.aarch64",
						"openSUSE Tumbleweed:python36-Django-3.2.7-2.3.ppc64le",
						"openSUSE Tumbleweed:python36-Django-3.2.7-2.3.s390x",
						"openSUSE Tumbleweed:python36-Django-3.2.7-2.3.x86_64",
						"openSUSE Tumbleweed:python38-Django-3.2.7-2.3.aarch64",
						"openSUSE Tumbleweed:python38-Django-3.2.7-2.3.ppc64le",
						"openSUSE Tumbleweed:python38-Django-3.2.7-2.3.s390x",
						"openSUSE Tumbleweed:python38-Django-3.2.7-2.3.x86_64",
						"openSUSE Tumbleweed:python39-Django-3.2.7-2.3.aarch64",
						"openSUSE Tumbleweed:python39-Django-3.2.7-2.3.ppc64le",
						"openSUSE Tumbleweed:python39-Django-3.2.7-2.3.s390x",
						"openSUSE Tumbleweed:python39-Django-3.2.7-2.3.x86_64"
					]
				}
			],
			"scores": [
				{
					"cvss_v3": {
						"baseScore": 6.5,
						"baseSeverity": "MEDIUM",
						"vectorString": "CVSS:3.1/AV:N/AC:L/PR:N/UI:N/S:U/C:L/I:L/A:N",
						"version": "3.1"
					},
					"products": [
						"openSUSE Tumbleweed:python36-Django-3.2.7-2.3.aarch64",
						"openSUSE Tumbleweed:python36-Django-3.2.7-2.3.ppc64le",
						"openSUSE Tumbleweed:python36-Django-3.2.7-2.3.s390x",
						"openSUSE Tumbleweed:python36-Django-3.2.7-2.3.x86_64",
						"openSUSE Tumbleweed:python38-Django-3.2.7-2.3.aarch64",
						"openSUSE Tumbleweed:python38-Django-3.2.7-2.3.ppc64le",
						"openSUSE Tumbleweed:python38-Django-3.2.7-2.3.s390x",
						"openSUSE Tumbleweed:python38-Django-3.2.7-2.3.x86_64",
						"openSUSE Tumbleweed:python39-Django-3.2.7-2.3.aarch64",
						"openSUSE Tumbleweed:python39-Django-3.2.7-2.3.ppc64le",
						"openSUSE Tumbleweed:python39-Django-3.2.7-2.3.s390x",
						"openSUSE Tumbleweed:python39-Django-3.2.7-2.3.x86_64"
					]
				}
			],
			"threats": [
				{
					"category": "impact",
					"date": "2024-06-15T00:00:00Z",
					"details": "moderate"
				}
			],
			"title": "CVE-2019-19844"
		},
		{
			"cve": "CVE-2019-3498",
			"ids": [
				{
					"system_name": "SUSE CVE Page",
					"text": "https://www.suse.com/security/cve/CVE-2019-3498"
				}
			],
			"notes": [
				{
					"category": "general",
					"text": "In Django 1.11.x before 1.11.18, 2.0.x before 2.0.10, and 2.1.x before 2.1.5, an Improper Neutralization of Special Elements in Output Used by a Downstream Component issue exists in django.views.defaults.page_not_found(), leading to content spoofing (in a 404 error page) if a user fails to recognize that a crafted URL has malicious content.",
					"title": "CVE description"
				}
			],
			"product_status": {
				"recommended": [
					"openSUSE Tumbleweed:python36-Django-3.2.7-2.3.aarch64",
					"openSUSE Tumbleweed:python36-Django-3.2.7-2.3.ppc64le",
					"openSUSE Tumbleweed:python36-Django-3.2.7-2.3.s390x",
					"openSUSE Tumbleweed:python36-Django-3.2.7-2.3.x86_64",
					"openSUSE Tumbleweed:python38-Django-3.2.7-2.3.aarch64",
					"openSUSE Tumbleweed:python38-Django-3.2.7-2.3.ppc64le",
					"openSUSE Tumbleweed:python38-Django-3.2.7-2.3.s390x",
					"openSUSE Tumbleweed:python38-Django-3.2.7-2.3.x86_64",
					"openSUSE Tumbleweed:python39-Django-3.2.7-2.3.aarch64",
					"openSUSE Tumbleweed:python39-Django-3.2.7-2.3.ppc64le",
					"openSUSE Tumbleweed:python39-Django-3.2.7-2.3.s390x",
					"openSUSE Tumbleweed:python39-Django-3.2.7-2.3.x86_64"
				]
			},
			"references": [
				{
					"category": "external",
					"summary": "CVE-2019-3498",
					"url": "https://www.suse.com/security/cve/CVE-2019-3498"
				},
				{
					"category": "external",
					"summary": "SUSE Bug 1120932 for CVE-2019-3498",
					"url": "https://bugzilla.suse.com/1120932"
				},
				{
					"category": "external",
					"summary": "SUSE Bug 1139945 for CVE-2019-3498",
					"url": "https://bugzilla.suse.com/1139945"
				}
			],
			"remediations": [
				{
					"category": "vendor_fix",
					"details": "To install this SUSE Security Update use the SUSE recommended installation methods like YaST online_update or \"zypper patch\".\n",
					"product_ids": [
						"openSUSE Tumbleweed:python36-Django-3.2.7-2.3.aarch64",
						"openSUSE Tumbleweed:python36-Django-3.2.7-2.3.ppc64le",
						"openSUSE Tumbleweed:python36-Django-3.2.7-2.3.s390x",
						"openSUSE Tumbleweed:python36-Django-3.2.7-2.3.x86_64",
						"openSUSE Tumbleweed:python38-Django-3.2.7-2.3.aarch64",
						"openSUSE Tumbleweed:python38-Django-3.2.7-2.3.ppc64le",
						"openSUSE Tumbleweed:python38-Django-3.2.7-2.3.s390x",
						"openSUSE Tumbleweed:python38-Django-3.2.7-2.3.x86_64",
						"openSUSE Tumbleweed:python39-Django-3.2.7-2.3.aarch64",
						"openSUSE Tumbleweed:python39-Django-3.2.7-2.3.ppc64le",
						"openSUSE Tumbleweed:python39-Django-3.2.7-2.3.s390x",
						"openSUSE Tumbleweed:python39-Django-3.2.7-2.3.x86_64"
					]
				}
			],
			"scores": [
				{
					"cvss_v3": {
						"baseScore": 4.3,
						"baseSeverity": "MEDIUM",
						"vectorString": "CVSS:3.0/AV:N/AC:L/PR:N/UI:R/S:U/C:N/I:L/A:N",
						"version": "3.0"
					},
					"products": [
						"openSUSE Tumbleweed:python36-Django-3.2.7-2.3.aarch64",
						"openSUSE Tumbleweed:python36-Django-3.2.7-2.3.ppc64le",
						"openSUSE Tumbleweed:python36-Django-3.2.7-2.3.s390x",
						"openSUSE Tumbleweed:python36-Django-3.2.7-2.3.x86_64",
						"openSUSE Tumbleweed:python38-Django-3.2.7-2.3.aarch64",
						"openSUSE Tumbleweed:python38-Django-3.2.7-2.3.ppc64le",
						"openSUSE Tumbleweed:python38-Django-3.2.7-2.3.s390x",
						"openSUSE Tumbleweed:python38-Django-3.2.7-2.3.x86_64",
						"openSUSE Tumbleweed:python39-Django-3.2.7-2.3.aarch64",
						"openSUSE Tumbleweed:python39-Django-3.2.7-2.3.ppc64le",
						"openSUSE Tumbleweed:python39-Django-3.2.7-2.3.s390x",
						"openSUSE Tumbleweed:python39-Django-3.2.7-2.3.x86_64"
					]
				}
			],
			"threats": [
				{
					"category": "impact",
					"date": "2024-06-15T00:00:00Z",
					"details": "low"
				}
			],
			"title": "CVE-2019-3498"
		},
		{
			"cve": "CVE-2019-6975",
			"ids": [
				{
					"system_name": "SUSE CVE Page",
					"text": "https://www.suse.com/security/cve/CVE-2019-6975"
				}
			],
			"notes": [
				{
					"category": "general",
					"text": "Django 1.11.x before 1.11.19, 2.0.x before 2.0.11, and 2.1.x before 2.1.6 allows Uncontrolled Memory Consumption via a malicious attacker-supplied value to the django.utils.numberformat.format() function.",
					"title": "CVE description"
				}
			],
			"product_status": {
				"recommended": [
					"openSUSE Tumbleweed:python36-Django-3.2.7-2.3.aarch64",
					"openSUSE Tumbleweed:python36-Django-3.2.7-2.3.ppc64le",
					"openSUSE Tumbleweed:python36-Django-3.2.7-2.3.s390x",
					"openSUSE Tumbleweed:python36-Django-3.2.7-2.3.x86_64",
					"openSUSE Tumbleweed:python38-Django-3.2.7-2.3.aarch64",
					"openSUSE Tumbleweed:python38-Django-3.2.7-2.3.ppc64le",
					"openSUSE Tumbleweed:python38-Django-3.2.7-2.3.s390x",
					"openSUSE Tumbleweed:python38-Django-3.2.7-2.3.x86_64",
					"openSUSE Tumbleweed:python39-Django-3.2.7-2.3.aarch64",
					"openSUSE Tumbleweed:python39-Django-3.2.7-2.3.ppc64le",
					"openSUSE Tumbleweed:python39-Django-3.2.7-2.3.s390x",
					"openSUSE Tumbleweed:python39-Django-3.2.7-2.3.x86_64"
				]
			},
			"references": [
				{
					"category": "external",
					"summary": "CVE-2019-6975",
					"url": "https://www.suse.com/security/cve/CVE-2019-6975"
				},
				{
					"category": "external",
					"summary": "SUSE Bug 1124991 for CVE-2019-6975",
					"url": "https://bugzilla.suse.com/1124991"
				},
				{
					"category": "external",
					"summary": "SUSE Bug 1139945 for CVE-2019-6975",
					"url": "https://bugzilla.suse.com/1139945"
				}
			],
			"remediations": [
				{
					"category": "vendor_fix",
					"details": "To install this SUSE Security Update use the SUSE recommended installation methods like YaST online_update or \"zypper patch\".\n",
					"product_ids": [
						"openSUSE Tumbleweed:python36-Django-3.2.7-2.3.aarch64",
						"openSUSE Tumbleweed:python36-Django-3.2.7-2.3.ppc64le",
						"openSUSE Tumbleweed:python36-Django-3.2.7-2.3.s390x",
						"openSUSE Tumbleweed:python36-Django-3.2.7-2.3.x86_64",
						"openSUSE Tumbleweed:python38-Django-3.2.7-2.3.aarch64",
						"openSUSE Tumbleweed:python38-Django-3.2.7-2.3.ppc64le",
						"openSUSE Tumbleweed:python38-Django-3.2.7-2.3.s390x",
						"openSUSE Tumbleweed:python38-Django-3.2.7-2.3.x86_64",
						"openSUSE Tumbleweed:python39-Django-3.2.7-2.3.aarch64",
						"openSUSE Tumbleweed:python39-Django-3.2.7-2.3.ppc64le",
						"openSUSE Tumbleweed:python39-Django-3.2.7-2.3.s390x",
						"openSUSE Tumbleweed:python39-Django-3.2.7-2.3.x86_64"
					]
				}
			],
			"scores": [
				{
					"cvss_v3": {
						"baseScore": 5.9,
						"baseSeverity": "MEDIUM",
						"vectorString": "CVSS:3.0/AV:N/AC:H/PR:N/UI:N/S:U/C:N/I:N/A:H",
						"version": "3.0"
					},
					"products": [
						"openSUSE Tumbleweed:python36-Django-3.2.7-2.3.aarch64",
						"openSUSE Tumbleweed:python36-Django-3.2.7-2.3.ppc64le",
						"openSUSE Tumbleweed:python36-Django-3.2.7-2.3.s390x",
						"openSUSE Tumbleweed:python36-Django-3.2.7-2.3.x86_64",
						"openSUSE Tumbleweed:python38-Django-3.2.7-2.3.aarch64",
						"openSUSE Tumbleweed:python38-Django-3.2.7-2.3.ppc64le",
						"openSUSE Tumbleweed:python38-Django-3.2.7-2.3.s390x",
						"openSUSE Tumbleweed:python38-Django-3.2.7-2.3.x86_64",
						"openSUSE Tumbleweed:python39-Django-3.2.7-2.3.aarch64",
						"openSUSE Tumbleweed:python39-Django-3.2.7-2.3.ppc64le",
						"openSUSE Tumbleweed:python39-Django-3.2.7-2.3.s390x",
						"openSUSE Tumbleweed:python39-Django-3.2.7-2.3.x86_64"
					]
				}
			],
			"threats": [
				{
					"category": "impact",
					"date": "2024-06-15T00:00:00Z",
					"details": "moderate"
				}
			],
			"title": "CVE-2019-6975"
		},
		{
			"cve": "CVE-2020-13254",
			"ids": [
				{
					"system_name": "SUSE CVE Page",
					"text": "https://www.suse.com/security/cve/CVE-2020-13254"
				}
			],
			"notes": [
				{
					"category": "general",
					"text": "An issue was discovered in Django 2.2 before 2.2.13 and 3.0 before 3.0.7. In cases where a memcached backend does not perform key validation, passing malformed cache keys could result in a key collision, and potential data leakage.",
					"title": "CVE description"
				}
			],
			"product_status": {
				"recommended": [
					"openSUSE Tumbleweed:python36-Django-3.2.7-2.3.aarch64",
					"openSUSE Tumbleweed:python36-Django-3.2.7-2.3.ppc64le",
					"openSUSE Tumbleweed:python36-Django-3.2.7-2.3.s390x",
					"openSUSE Tumbleweed:python36-Django-3.2.7-2.3.x86_64",
					"openSUSE Tumbleweed:python38-Django-3.2.7-2.3.aarch64",
					"openSUSE Tumbleweed:python38-Django-3.2.7-2.3.ppc64le",
					"openSUSE Tumbleweed:python38-Django-3.2.7-2.3.s390x",
					"openSUSE Tumbleweed:python38-Django-3.2.7-2.3.x86_64",
					"openSUSE Tumbleweed:python39-Django-3.2.7-2.3.aarch64",
					"openSUSE Tumbleweed:python39-Django-3.2.7-2.3.ppc64le",
					"openSUSE Tumbleweed:python39-Django-3.2.7-2.3.s390x",
					"openSUSE Tumbleweed:python39-Django-3.2.7-2.3.x86_64"
				]
			},
			"references": [
				{
					"category": "external",
					"summary": "CVE-2020-13254",
					"url": "https://www.suse.com/security/cve/CVE-2020-13254"
				},
				{
					"category": "external",
					"summary": "SUSE Bug 1172166 for CVE-2020-13254",
					"url": "https://bugzilla.suse.com/1172166"
				},
				{
					"category": "external",
					"summary": "SUSE Bug 1172167 for CVE-2020-13254",
					"url": "https://bugzilla.suse.com/1172167"
				}
			],
			"remediations": [
				{
					"category": "vendor_fix",
					"details": "To install this SUSE Security Update use the SUSE recommended installation methods like YaST online_update or \"zypper patch\".\n",
					"product_ids": [
						"openSUSE Tumbleweed:python36-Django-3.2.7-2.3.aarch64",
						"openSUSE Tumbleweed:python36-Django-3.2.7-2.3.ppc64le",
						"openSUSE Tumbleweed:python36-Django-3.2.7-2.3.s390x",
						"openSUSE Tumbleweed:python36-Django-3.2.7-2.3.x86_64",
						"openSUSE Tumbleweed:python38-Django-3.2.7-2.3.aarch64",
						"openSUSE Tumbleweed:python38-Django-3.2.7-2.3.ppc64le",
						"openSUSE Tumbleweed:python38-Django-3.2.7-2.3.s390x",
						"openSUSE Tumbleweed:python38-Django-3.2.7-2.3.x86_64",
						"openSUSE Tumbleweed:python39-Django-3.2.7-2.3.aarch64",
						"openSUSE Tumbleweed:python39-Django-3.2.7-2.3.ppc64le",
						"openSUSE Tumbleweed:python39-Django-3.2.7-2.3.s390x",
						"openSUSE Tumbleweed:python39-Django-3.2.7-2.3.x86_64"
					]
				}
			],
			"scores": [
				{
					"cvss_v3": {
						"baseScore": 5.9,
						"baseSeverity": "MEDIUM",
						"vectorString": "CVSS:3.1/AV:N/AC:H/PR:N/UI:N/S:U/C:H/I:N/A:N",
						"version": "3.1"
					},
					"products": [
						"openSUSE Tumbleweed:python36-Django-3.2.7-2.3.aarch64",
						"openSUSE Tumbleweed:python36-Django-3.2.7-2.3.ppc64le",
						"openSUSE Tumbleweed:python36-Django-3.2.7-2.3.s390x",
						"openSUSE Tumbleweed:python36-Django-3.2.7-2.3.x86_64",
						"openSUSE Tumbleweed:python38-Django-3.2.7-2.3.aarch64",
						"openSUSE Tumbleweed:python38-Django-3.2.7-2.3.ppc64le",
						"openSUSE Tumbleweed:python38-Django-3.2.7-2.3.s390x",
						"openSUSE Tumbleweed:python38-Django-3.2.7-2.3.x86_64",
						"openSUSE Tumbleweed:python39-Django-3.2.7-2.3.aarch64",
						"openSUSE Tumbleweed:python39-Django-3.2.7-2.3.ppc64le",
						"openSUSE Tumbleweed:python39-Django-3.2.7-2.3.s390x",
						"openSUSE Tumbleweed:python39-Django-3.2.7-2.3.x86_64"
					]
				}
			],
			"threats": [
				{
					"category": "impact",
					"date": "2024-06-15T00:00:00Z",
					"details": "moderate"
				}
			],
			"title": "CVE-2020-13254"
		},
		{
			"cve": "CVE-2020-13596",
			"ids": [
				{
					"system_name": "SUSE CVE Page",
					"text": "https://www.suse.com/security/cve/CVE-2020-13596"
				}
			],
			"notes": [
				{
					"category": "general",
					"text": "An issue was discovered in Django 2.2 before 2.2.13 and 3.0 before 3.0.7. Query parameters generated by the Django admin ForeignKeyRawIdWidget were not properly URL encoded, leading to a possibility of an XSS attack.",
					"title": "CVE description"
				}
			],
			"product_status": {
				"recommended": [
					"openSUSE Tumbleweed:python36-Django-3.2.7-2.3.aarch64",
					"openSUSE Tumbleweed:python36-Django-3.2.7-2.3.ppc64le",
					"openSUSE Tumbleweed:python36-Django-3.2.7-2.3.s390x",
					"openSUSE Tumbleweed:python36-Django-3.2.7-2.3.x86_64",
					"openSUSE Tumbleweed:python38-Django-3.2.7-2.3.aarch64",
					"openSUSE Tumbleweed:python38-Django-3.2.7-2.3.ppc64le",
					"openSUSE Tumbleweed:python38-Django-3.2.7-2.3.s390x",
					"openSUSE Tumbleweed:python38-Django-3.2.7-2.3.x86_64",
					"openSUSE Tumbleweed:python39-Django-3.2.7-2.3.aarch64",
					"openSUSE Tumbleweed:python39-Django-3.2.7-2.3.ppc64le",
					"openSUSE Tumbleweed:python39-Django-3.2.7-2.3.s390x",
					"openSUSE Tumbleweed:python39-Django-3.2.7-2.3.x86_64"
				]
			},
			"references": [
				{
					"category": "external",
					"summary": "CVE-2020-13596",
					"url": "https://www.suse.com/security/cve/CVE-2020-13596"
				},
				{
					"category": "external",
					"summary": "SUSE Bug 1172166 for CVE-2020-13596",
					"url": "https://bugzilla.suse.com/1172166"
				},
				{
					"category": "external",
					"summary": "SUSE Bug 1172167 for CVE-2020-13596",
					"url": "https://bugzilla.suse.com/1172167"
				}
			],
			"remediations": [
				{
					"category": "vendor_fix",
					"details": "To install this SUSE Security Update use the SUSE recommended installation methods like YaST online_update or \"zypper patch\".\n",
					"product_ids": [
						"openSUSE Tumbleweed:python36-Django-3.2.7-2.3.aarch64",
						"openSUSE Tumbleweed:python36-Django-3.2.7-2.3.ppc64le",
						"openSUSE Tumbleweed:python36-Django-3.2.7-2.3.s390x",
						"openSUSE Tumbleweed:python36-Django-3.2.7-2.3.x86_64",
						"openSUSE Tumbleweed:python38-Django-3.2.7-2.3.aarch64",
						"openSUSE Tumbleweed:python38-Django-3.2.7-2.3.ppc64le",
						"openSUSE Tumbleweed:python38-Django-3.2.7-2.3.s390x",
						"openSUSE Tumbleweed:python38-Django-3.2.7-2.3.x86_64",
						"openSUSE Tumbleweed:python39-Django-3.2.7-2.3.aarch64",
						"openSUSE Tumbleweed:python39-Django-3.2.7-2.3.ppc64le",
						"openSUSE Tumbleweed:python39-Django-3.2.7-2.3.s390x",
						"openSUSE Tumbleweed:python39-Django-3.2.7-2.3.x86_64"
					]
				}
			],
			"scores": [
				{
					"cvss_v3": {
						"baseScore": 6.4,
						"baseSeverity": "MEDIUM",
						"vectorString": "CVSS:3.1/AV:N/AC:L/PR:L/UI:N/S:C/C:L/I:L/A:N",
						"version": "3.1"
					},
					"products": [
						"openSUSE Tumbleweed:python36-Django-3.2.7-2.3.aarch64",
						"openSUSE Tumbleweed:python36-Django-3.2.7-2.3.ppc64le",
						"openSUSE Tumbleweed:python36-Django-3.2.7-2.3.s390x",
						"openSUSE Tumbleweed:python36-Django-3.2.7-2.3.x86_64",
						"openSUSE Tumbleweed:python38-Django-3.2.7-2.3.aarch64",
						"openSUSE Tumbleweed:python38-Django-3.2.7-2.3.ppc64le",
						"openSUSE Tumbleweed:python38-Django-3.2.7-2.3.s390x",
						"openSUSE Tumbleweed:python38-Django-3.2.7-2.3.x86_64",
						"openSUSE Tumbleweed:python39-Django-3.2.7-2.3.aarch64",
						"openSUSE Tumbleweed:python39-Django-3.2.7-2.3.ppc64le",
						"openSUSE Tumbleweed:python39-Django-3.2.7-2.3.s390x",
						"openSUSE Tumbleweed:python39-Django-3.2.7-2.3.x86_64"
					]
				}
			],
			"threats": [
				{
					"category": "impact",
					"date": "2024-06-15T00:00:00Z",
					"details": "moderate"
				}
			],
			"title": "CVE-2020-13596"
		},
		{
			"cve": "CVE-2020-24583",
			"ids": [
				{
					"system_name": "SUSE CVE Page",
					"text": "https://www.suse.com/security/cve/CVE-2020-24583"
				}
			],
			"notes": [
				{
					"category": "general",
					"text": "An issue was discovered in Django 2.2 before 2.2.16, 3.0 before 3.0.10, and 3.1 before 3.1.1 (when Python 3.7+ is used). FILE_UPLOAD_DIRECTORY_PERMISSIONS mode was not applied to intermediate-level directories created in the process of uploading files. It was also not applied to intermediate-level collected static directories when using the collectstatic management command.",
					"title": "CVE description"
				}
			],
			"product_status": {
				"recommended": [
					"openSUSE Tumbleweed:python36-Django-3.2.7-2.3.aarch64",
					"openSUSE Tumbleweed:python36-Django-3.2.7-2.3.ppc64le",
					"openSUSE Tumbleweed:python36-Django-3.2.7-2.3.s390x",
					"openSUSE Tumbleweed:python36-Django-3.2.7-2.3.x86_64",
					"openSUSE Tumbleweed:python38-Django-3.2.7-2.3.aarch64",
					"openSUSE Tumbleweed:python38-Django-3.2.7-2.3.ppc64le",
					"openSUSE Tumbleweed:python38-Django-3.2.7-2.3.s390x",
					"openSUSE Tumbleweed:python38-Django-3.2.7-2.3.x86_64",
					"openSUSE Tumbleweed:python39-Django-3.2.7-2.3.aarch64",
					"openSUSE Tumbleweed:python39-Django-3.2.7-2.3.ppc64le",
					"openSUSE Tumbleweed:python39-Django-3.2.7-2.3.s390x",
					"openSUSE Tumbleweed:python39-Django-3.2.7-2.3.x86_64"
				]
			},
			"references": [
				{
					"category": "external",
					"summary": "CVE-2020-24583",
					"url": "https://www.suse.com/security/cve/CVE-2020-24583"
				},
				{
					"category": "external",
					"summary": "SUSE Bug 1175784 for CVE-2020-24583",
					"url": "https://bugzilla.suse.com/1175784"
				}
			],
			"remediations": [
				{
					"category": "vendor_fix",
					"details": "To install this SUSE Security Update use the SUSE recommended installation methods like YaST online_update or \"zypper patch\".\n",
					"product_ids": [
						"openSUSE Tumbleweed:python36-Django-3.2.7-2.3.aarch64",
						"openSUSE Tumbleweed:python36-Django-3.2.7-2.3.ppc64le",
						"openSUSE Tumbleweed:python36-Django-3.2.7-2.3.s390x",
						"openSUSE Tumbleweed:python36-Django-3.2.7-2.3.x86_64",
						"openSUSE Tumbleweed:python38-Django-3.2.7-2.3.aarch64",
						"openSUSE Tumbleweed:python38-Django-3.2.7-2.3.ppc64le",
						"openSUSE Tumbleweed:python38-Django-3.2.7-2.3.s390x",
						"openSUSE Tumbleweed:python38-Django-3.2.7-2.3.x86_64",
						"openSUSE Tumbleweed:python39-Django-3.2.7-2.3.aarch64",
						"openSUSE Tumbleweed:python39-Django-3.2.7-2.3.ppc64le",
						"openSUSE Tumbleweed:python39-Django-3.2.7-2.3.s390x",
						"openSUSE Tumbleweed:python39-Django-3.2.7-2.3.x86_64"
					]
				}
			],
			"scores": [
				{
					"cvss_v3": {
						"baseScore": 7.5,
						"baseSeverity": "HIGH",
						"vectorString": "CVSS:3.1/AV:N/AC:L/PR:N/UI:N/S:U/C:H/I:N/A:N",
						"version": "3.1"
					},
					"products": [
						"openSUSE Tumbleweed:python36-Django-3.2.7-2.3.aarch64",
						"openSUSE Tumbleweed:python36-Django-3.2.7-2.3.ppc64le",
						"openSUSE Tumbleweed:python36-Django-3.2.7-2.3.s390x",
						"openSUSE Tumbleweed:python36-Django-3.2.7-2.3.x86_64",
						"openSUSE Tumbleweed:python38-Django-3.2.7-2.3.aarch64",
						"openSUSE Tumbleweed:python38-Django-3.2.7-2.3.ppc64le",
						"openSUSE Tumbleweed:python38-Django-3.2.7-2.3.s390x",
						"openSUSE Tumbleweed:python38-Django-3.2.7-2.3.x86_64",
						"openSUSE Tumbleweed:python39-Django-3.2.7-2.3.aarch64",
						"openSUSE Tumbleweed:python39-Django-3.2.7-2.3.ppc64le",
						"openSUSE Tumbleweed:python39-Django-3.2.7-2.3.s390x",
						"openSUSE Tumbleweed:python39-Django-3.2.7-2.3.x86_64"
					]
				}
			],
			"threats": [
				{
					"category": "impact",
					"date": "2024-06-15T00:00:00Z",
					"details": "important"
				}
			],
			"title": "CVE-2020-24583"
		},
		{
			"cve": "CVE-2020-24584",
			"ids": [
				{
					"system_name": "SUSE CVE Page",
					"text": "https://www.suse.com/security/cve/CVE-2020-24584"
				}
			],
			"notes": [
				{
					"category": "general",
					"text": "An issue was discovered in Django 2.2 before 2.2.16, 3.0 before 3.0.10, and 3.1 before 3.1.1 (when Python 3.7+ is used). The intermediate-level directories of the filesystem cache had the system's standard umask rather than 0o077.",
					"title": "CVE description"
				}
			],
			"product_status": {
				"recommended": [
					"openSUSE Tumbleweed:python36-Django-3.2.7-2.3.aarch64",
					"openSUSE Tumbleweed:python36-Django-3.2.7-2.3.ppc64le",
					"openSUSE Tumbleweed:python36-Django-3.2.7-2.3.s390x",
					"openSUSE Tumbleweed:python36-Django-3.2.7-2.3.x86_64",
					"openSUSE Tumbleweed:python38-Django-3.2.7-2.3.aarch64",
					"openSUSE Tumbleweed:python38-Django-3.2.7-2.3.ppc64le",
					"openSUSE Tumbleweed:python38-Django-3.2.7-2.3.s390x",
					"openSUSE Tumbleweed:python38-Django-3.2.7-2.3.x86_64",
					"openSUSE Tumbleweed:python39-Django-3.2.7-2.3.aarch64",
					"openSUSE Tumbleweed:python39-Django-3.2.7-2.3.ppc64le",
					"openSUSE Tumbleweed:python39-Django-3.2.7-2.3.s390x",
					"openSUSE Tumbleweed:python39-Django-3.2.7-2.3.x86_64"
				]
			},
			"references": [
				{
					"category": "external",
					"summary": "CVE-2020-24584",
					"url": "https://www.suse.com/security/cve/CVE-2020-24584"
				},
				{
					"category": "external",
					"summary": "SUSE Bug 1175784 for CVE-2020-24584",
					"url": "https://bugzilla.suse.com/1175784"
				}
			],
			"remediations": [
				{
					"category": "vendor_fix",
					"details": "To install this SUSE Security Update use the SUSE recommended installation methods like YaST online_update or \"zypper patch\".\n",
					"product_ids": [
						"openSUSE Tumbleweed:python36-Django-3.2.7-2.3.aarch64",
						"openSUSE Tumbleweed:python36-Django-3.2.7-2.3.ppc64le",
						"openSUSE Tumbleweed:python36-Django-3.2.7-2.3.s390x",
						"openSUSE Tumbleweed:python36-Django-3.2.7-2.3.x86_64",
						"openSUSE Tumbleweed:python38-Django-3.2.7-2.3.aarch64",
						"openSUSE Tumbleweed:python38-Django-3.2.7-2.3.ppc64le",
						"openSUSE Tumbleweed:python38-Django-3.2.7-2.3.s390x",
						"openSUSE Tumbleweed:python38-Django-3.2.7-2.3.x86_64",
						"openSUSE Tumbleweed:python39-Django-3.2.7-2.3.aarch64",
						"openSUSE Tumbleweed:python39-Django-3.2.7-2.3.ppc64le",
						"openSUSE Tumbleweed:python39-Django-3.2.7-2.3.s390x",
						"openSUSE Tumbleweed:python39-Django-3.2.7-2.3.x86_64"
					]
				}
			],
			"scores": [
				{
					"cvss_v3": {
						"baseScore": 7.5,
						"baseSeverity": "HIGH",
						"vectorString": "CVSS:3.1/AV:N/AC:L/PR:N/UI:N/S:U/C:H/I:N/A:N",
						"version": "3.1"
					},
					"products": [
						"openSUSE Tumbleweed:python36-Django-3.2.7-2.3.aarch64",
						"openSUSE Tumbleweed:python36-Django-3.2.7-2.3.ppc64le",
						"openSUSE Tumbleweed:python36-Django-3.2.7-2.3.s390x",
						"openSUSE Tumbleweed:python36-Django-3.2.7-2.3.x86_64",
						"openSUSE Tumbleweed:python38-Django-3.2.7-2.3.aarch64",
						"openSUSE Tumbleweed:python38-Django-3.2.7-2.3.ppc64le",
						"openSUSE Tumbleweed:python38-Django-3.2.7-2.3.s390x",
						"openSUSE Tumbleweed:python38-Django-3.2.7-2.3.x86_64",
						"openSUSE Tumbleweed:python39-Django-3.2.7-2.3.aarch64",
						"openSUSE Tumbleweed:python39-Django-3.2.7-2.3.ppc64le",
						"openSUSE Tumbleweed:python39-Django-3.2.7-2.3.s390x",
						"openSUSE Tumbleweed:python39-Django-3.2.7-2.3.x86_64"
					]
				}
			],
			"threats": [
				{
					"category": "impact",
					"date": "2024-06-15T00:00:00Z",
					"details": "important"
				}
			],
			"title": "CVE-2020-24584"
		},
		{
			"cve": "CVE-2020-7471",
			"ids": [
				{
					"system_name": "SUSE CVE Page",
					"text": "https://www.suse.com/security/cve/CVE-2020-7471"
				}
			],
			"notes": [
				{
					"category": "general",
					"text": "Django 1.11 before 1.11.28, 2.2 before 2.2.10, and 3.0 before 3.0.3 allows SQL Injection if untrusted data is used as a StringAgg delimiter (e.g., in Django applications that offer downloads of data as a series of rows with a user-specified column delimiter). By passing a suitably crafted delimiter to a contrib.postgres.aggregates.StringAgg instance, it was possible to break escaping and inject malicious SQL.",
					"title": "CVE description"
				}
			],
			"product_status": {
				"recommended": [
					"openSUSE Tumbleweed:python36-Django-3.2.7-2.3.aarch64",
					"openSUSE Tumbleweed:python36-Django-3.2.7-2.3.ppc64le",
					"openSUSE Tumbleweed:python36-Django-3.2.7-2.3.s390x",
					"openSUSE Tumbleweed:python36-Django-3.2.7-2.3.x86_64",
					"openSUSE Tumbleweed:python38-Django-3.2.7-2.3.aarch64",
					"openSUSE Tumbleweed:python38-Django-3.2.7-2.3.ppc64le",
					"openSUSE Tumbleweed:python38-Django-3.2.7-2.3.s390x",
					"openSUSE Tumbleweed:python38-Django-3.2.7-2.3.x86_64",
					"openSUSE Tumbleweed:python39-Django-3.2.7-2.3.aarch64",
					"openSUSE Tumbleweed:python39-Django-3.2.7-2.3.ppc64le",
					"openSUSE Tumbleweed:python39-Django-3.2.7-2.3.s390x",
					"openSUSE Tumbleweed:python39-Django-3.2.7-2.3.x86_64"
				]
			},
			"references": [
				{
					"category": "external",
					"summary": "CVE-2020-7471",
					"url": "https://www.suse.com/security/cve/CVE-2020-7471"
				},
				{
					"category": "external",
					"summary": "SUSE Bug 1161919 for CVE-2020-7471",
					"url": "https://bugzilla.suse.com/1161919"
				},
				{
					"category": "external",
					"summary": "SUSE Bug 1161920 for CVE-2020-7471",
					"url": "https://bugzilla.suse.com/1161920"
				}
			],
			"remediations": [
				{
					"category": "vendor_fix",
					"details": "To install this SUSE Security Update use the SUSE recommended installation methods like YaST online_update or \"zypper patch\".\n",
					"product_ids": [
						"openSUSE Tumbleweed:python36-Django-3.2.7-2.3.aarch64",
						"openSUSE Tumbleweed:python36-Django-3.2.7-2.3.ppc64le",
						"openSUSE Tumbleweed:python36-Django-3.2.7-2.3.s390x",
						"openSUSE Tumbleweed:python36-Django-3.2.7-2.3.x86_64",
						"openSUSE Tumbleweed:python38-Django-3.2.7-2.3.aarch64",
						"openSUSE Tumbleweed:python38-Django-3.2.7-2.3.ppc64le",
						"openSUSE Tumbleweed:python38-Django-3.2.7-2.3.s390x",
						"openSUSE Tumbleweed:python38-Django-3.2.7-2.3.x86_64",
						"openSUSE Tumbleweed:python39-Django-3.2.7-2.3.aarch64",
						"openSUSE Tumbleweed:python39-Django-3.2.7-2.3.ppc64le",
						"openSUSE Tumbleweed:python39-Django-3.2.7-2.3.s390x",
						"openSUSE Tumbleweed:python39-Django-3.2.7-2.3.x86_64"
					]
				}
			],
			"scores": [
				{
					"cvss_v3": {
						"baseScore": 7.6,
						"baseSeverity": "HIGH",
						"vectorString": "CVSS:3.1/AV:N/AC:L/PR:L/UI:N/S:U/C:L/I:H/A:L",
						"version": "3.1"
					},
					"products": [
						"openSUSE Tumbleweed:python36-Django-3.2.7-2.3.aarch64",
						"openSUSE Tumbleweed:python36-Django-3.2.7-2.3.ppc64le",
						"openSUSE Tumbleweed:python36-Django-3.2.7-2.3.s390x",
						"openSUSE Tumbleweed:python36-Django-3.2.7-2.3.x86_64",
						"openSUSE Tumbleweed:python38-Django-3.2.7-2.3.aarch64",
						"openSUSE Tumbleweed:python38-Django-3.2.7-2.3.ppc64le",
						"openSUSE Tumbleweed:python38-Django-3.2.7-2.3.s390x",
						"openSUSE Tumbleweed:python38-Django-3.2.7-2.3.x86_64",
						"openSUSE Tumbleweed:python39-Django-3.2.7-2.3.aarch64",
						"openSUSE Tumbleweed:python39-Django-3.2.7-2.3.ppc64le",
						"openSUSE Tumbleweed:python39-Django-3.2.7-2.3.s390x",
						"openSUSE Tumbleweed:python39-Django-3.2.7-2.3.x86_64"
					]
				}
			],
			"threats": [
				{
					"category": "impact",
					"date": "2024-06-15T00:00:00Z",
					"details": "important"
				}
			],
			"title": "CVE-2020-7471"
		},
		{
			"cve": "CVE-2020-9402",
			"ids": [
				{
					"system_name": "SUSE CVE Page",
					"text": "https://www.suse.com/security/cve/CVE-2020-9402"
				}
			],
			"notes": [
				{
					"category": "general",
					"text": "Django 1.11 before 1.11.29, 2.2 before 2.2.11, and 3.0 before 3.0.4 allows SQL Injection if untrusted data is used as a tolerance parameter in GIS functions and aggregates on Oracle. By passing a suitably crafted tolerance to GIS functions and aggregates on Oracle, it was possible to break escaping and inject malicious SQL.",
					"title": "CVE description"
				}
			],
			"product_status": {
				"recommended": [
					"openSUSE Tumbleweed:python36-Django-3.2.7-2.3.aarch64",
					"openSUSE Tumbleweed:python36-Django-3.2.7-2.3.ppc64le",
					"openSUSE Tumbleweed:python36-Django-3.2.7-2.3.s390x",
					"openSUSE Tumbleweed:python36-Django-3.2.7-2.3.x86_64",
					"openSUSE Tumbleweed:python38-Django-3.2.7-2.3.aarch64",
					"openSUSE Tumbleweed:python38-Django-3.2.7-2.3.ppc64le",
					"openSUSE Tumbleweed:python38-Django-3.2.7-2.3.s390x",
					"openSUSE Tumbleweed:python38-Django-3.2.7-2.3.x86_64",
					"openSUSE Tumbleweed:python39-Django-3.2.7-2.3.aarch64",
					"openSUSE Tumbleweed:python39-Django-3.2.7-2.3.ppc64le",
					"openSUSE Tumbleweed:python39-Django-3.2.7-2.3.s390x",
					"openSUSE Tumbleweed:python39-Django-3.2.7-2.3.x86_64"
				]
			},
			"references": [
				{
					"category": "external",
					"summary": "CVE-2020-9402",
					"url": "https://www.suse.com/security/cve/CVE-2020-9402"
				},
				{
					"category": "external",
					"summary": "SUSE Bug 1165022 for CVE-2020-9402",
					"url": "https://bugzilla.suse.com/1165022"
				}
			],
			"remediations": [
				{
					"category": "vendor_fix",
					"details": "To install this SUSE Security Update use the SUSE recommended installation methods like YaST online_update or \"zypper patch\".\n",
					"product_ids": [
						"openSUSE Tumbleweed:python36-Django-3.2.7-2.3.aarch64",
						"openSUSE Tumbleweed:python36-Django-3.2.7-2.3.ppc64le",
						"openSUSE Tumbleweed:python36-Django-3.2.7-2.3.s390x",
						"openSUSE Tumbleweed:python36-Django-3.2.7-2.3.x86_64",
						"openSUSE Tumbleweed:python38-Django-3.2.7-2.3.aarch64",
						"openSUSE Tumbleweed:python38-Django-3.2.7-2.3.ppc64le",
						"openSUSE Tumbleweed:python38-Django-3.2.7-2.3.s390x",
						"openSUSE Tumbleweed:python38-Django-3.2.7-2.3.x86_64",
						"openSUSE Tumbleweed:python39-Django-3.2.7-2.3.aarch64",
						"openSUSE Tumbleweed:python39-Django-3.2.7-2.3.ppc64le",
						"openSUSE Tumbleweed:python39-Django-3.2.7-2.3.s390x",
						"openSUSE Tumbleweed:python39-Django-3.2.7-2.3.x86_64"
					]
				}
			],
			"scores": [
				{
					"cvss_v3": {
						"baseScore": 7.6,
						"baseSeverity": "HIGH",
						"vectorString": "CVSS:3.1/AV:N/AC:L/PR:L/UI:N/S:U/C:H/I:L/A:L",
						"version": "3.1"
					},
					"products": [
						"openSUSE Tumbleweed:python36-Django-3.2.7-2.3.aarch64",
						"openSUSE Tumbleweed:python36-Django-3.2.7-2.3.ppc64le",
						"openSUSE Tumbleweed:python36-Django-3.2.7-2.3.s390x",
						"openSUSE Tumbleweed:python36-Django-3.2.7-2.3.x86_64",
						"openSUSE Tumbleweed:python38-Django-3.2.7-2.3.aarch64",
						"openSUSE Tumbleweed:python38-Django-3.2.7-2.3.ppc64le",
						"openSUSE Tumbleweed:python38-Django-3.2.7-2.3.s390x",
						"openSUSE Tumbleweed:python38-Django-3.2.7-2.3.x86_64",
						"openSUSE Tumbleweed:python39-Django-3.2.7-2.3.aarch64",
						"openSUSE Tumbleweed:python39-Django-3.2.7-2.3.ppc64le",
						"openSUSE Tumbleweed:python39-Django-3.2.7-2.3.s390x",
						"openSUSE Tumbleweed:python39-Django-3.2.7-2.3.x86_64"
					]
				}
			],
			"threats": [
				{
					"category": "impact",
					"date": "2024-06-15T00:00:00Z",
					"details": "important"
				}
			],
			"title": "CVE-2020-9402"
		},
		{
			"cve": "CVE-2021-31542",
			"ids": [
				{
					"system_name": "SUSE CVE Page",
					"text": "https://www.suse.com/security/cve/CVE-2021-31542"
				}
			],
			"notes": [
				{
					"category": "general",
					"text": "In Django 2.2 before 2.2.21, 3.1 before 3.1.9, and 3.2 before 3.2.1, MultiPartParser, UploadedFile, and FieldFile allowed directory traversal via uploaded files with suitably crafted file names.",
					"title": "CVE description"
				}
			],
			"product_status": {
				"recommended": [
					"openSUSE Tumbleweed:python36-Django-3.2.7-2.3.aarch64",
					"openSUSE Tumbleweed:python36-Django-3.2.7-2.3.ppc64le",
					"openSUSE Tumbleweed:python36-Django-3.2.7-2.3.s390x",
					"openSUSE Tumbleweed:python36-Django-3.2.7-2.3.x86_64",
					"openSUSE Tumbleweed:python38-Django-3.2.7-2.3.aarch64",
					"openSUSE Tumbleweed:python38-Django-3.2.7-2.3.ppc64le",
					"openSUSE Tumbleweed:python38-Django-3.2.7-2.3.s390x",
					"openSUSE Tumbleweed:python38-Django-3.2.7-2.3.x86_64",
					"openSUSE Tumbleweed:python39-Django-3.2.7-2.3.aarch64",
					"openSUSE Tumbleweed:python39-Django-3.2.7-2.3.ppc64le",
					"openSUSE Tumbleweed:python39-Django-3.2.7-2.3.s390x",
					"openSUSE Tumbleweed:python39-Django-3.2.7-2.3.x86_64"
				]
			},
			"references": [
				{
					"category": "external",
					"summary": "CVE-2021-31542",
					"url": "https://www.suse.com/security/cve/CVE-2021-31542"
				},
				{
					"category": "external",
					"summary": "SUSE Bug 1185623 for CVE-2021-31542",
					"url": "https://bugzilla.suse.com/1185623"
				}
			],
			"remediations": [
				{
					"category": "vendor_fix",
					"details": "To install this SUSE Security Update use the SUSE recommended installation methods like YaST online_update or \"zypper patch\".\n",
					"product_ids": [
						"openSUSE Tumbleweed:python36-Django-3.2.7-2.3.aarch64",
						"openSUSE Tumbleweed:python36-Django-3.2.7-2.3.ppc64le",
						"openSUSE Tumbleweed:python36-Django-3.2.7-2.3.s390x",
						"openSUSE Tumbleweed:python36-Django-3.2.7-2.3.x86_64",
						"openSUSE Tumbleweed:python38-Django-3.2.7-2.3.aarch64",
						"openSUSE Tumbleweed:python38-Django-3.2.7-2.3.ppc64le",
						"openSUSE Tumbleweed:python38-Django-3.2.7-2.3.s390x",
						"openSUSE Tumbleweed:python38-Django-3.2.7-2.3.x86_64",
						"openSUSE Tumbleweed:python39-Django-3.2.7-2.3.aarch64",
						"openSUSE Tumbleweed:python39-Django-3.2.7-2.3.ppc64le",
						"openSUSE Tumbleweed:python39-Django-3.2.7-2.3.s390x",
						"openSUSE Tumbleweed:python39-Django-3.2.7-2.3.x86_64"
					]
				}
			],
			"scores": [
				{
					"cvss_v3": {
						"baseScore": 6.5,
						"baseSeverity": "MEDIUM",
						"vectorString": "CVSS:3.1/AV:N/AC:L/PR:L/UI:N/S:U/C:H/I:N/A:N",
						"version": "3.1"
					},
					"products": [
						"openSUSE Tumbleweed:python36-Django-3.2.7-2.3.aarch64",
						"openSUSE Tumbleweed:python36-Django-3.2.7-2.3.ppc64le",
						"openSUSE Tumbleweed:python36-Django-3.2.7-2.3.s390x",
						"openSUSE Tumbleweed:python36-Django-3.2.7-2.3.x86_64",
						"openSUSE Tumbleweed:python38-Django-3.2.7-2.3.aarch64",
						"openSUSE Tumbleweed:python38-Django-3.2.7-2.3.ppc64le",
						"openSUSE Tumbleweed:python38-Django-3.2.7-2.3.s390x",
						"openSUSE Tumbleweed:python38-Django-3.2.7-2.3.x86_64",
						"openSUSE Tumbleweed:python39-Django-3.2.7-2.3.aarch64",
						"openSUSE Tumbleweed:python39-Django-3.2.7-2.3.ppc64le",
						"openSUSE Tumbleweed:python39-Django-3.2.7-2.3.s390x",
						"openSUSE Tumbleweed:python39-Django-3.2.7-2.3.x86_64"
					]
				}
			],
			"threats": [
				{
					"category": "impact",
					"date": "2024-06-15T00:00:00Z",
					"details": "moderate"
				}
			],
			"title": "CVE-2021-31542"
		},
		{
			"cve": "CVE-2021-32052",
			"ids": [
				{
					"system_name": "SUSE CVE Page",
					"text": "https://www.suse.com/security/cve/CVE-2021-32052"
				}
			],
			"notes": [
				{
					"category": "general",
					"text": "In Django 2.2 before 2.2.22, 3.1 before 3.1.10, and 3.2 before 3.2.2 (with Python 3.9.5+), URLValidator does not prohibit newlines and tabs (unless the URLField form field is used). If an application uses values with newlines in an HTTP response, header injection can occur. Django itself is unaffected because HttpResponse prohibits newlines in HTTP headers.",
					"title": "CVE description"
				}
			],
			"product_status": {
				"recommended": [
					"openSUSE Tumbleweed:python36-Django-3.2.7-2.3.aarch64",
					"openSUSE Tumbleweed:python36-Django-3.2.7-2.3.ppc64le",
					"openSUSE Tumbleweed:python36-Django-3.2.7-2.3.s390x",
					"openSUSE Tumbleweed:python36-Django-3.2.7-2.3.x86_64",
					"openSUSE Tumbleweed:python38-Django-3.2.7-2.3.aarch64",
					"openSUSE Tumbleweed:python38-Django-3.2.7-2.3.ppc64le",
					"openSUSE Tumbleweed:python38-Django-3.2.7-2.3.s390x",
					"openSUSE Tumbleweed:python38-Django-3.2.7-2.3.x86_64",
					"openSUSE Tumbleweed:python39-Django-3.2.7-2.3.aarch64",
					"openSUSE Tumbleweed:python39-Django-3.2.7-2.3.ppc64le",
					"openSUSE Tumbleweed:python39-Django-3.2.7-2.3.s390x",
					"openSUSE Tumbleweed:python39-Django-3.2.7-2.3.x86_64"
				]
			},
			"references": [
				{
					"category": "external",
					"summary": "CVE-2021-32052",
					"url": "https://www.suse.com/security/cve/CVE-2021-32052"
				},
				{
					"category": "external",
					"summary": "SUSE Bug 1185713 for CVE-2021-32052",
					"url": "https://bugzilla.suse.com/1185713"
				}
			],
			"remediations": [
				{
					"category": "vendor_fix",
					"details": "To install this SUSE Security Update use the SUSE recommended installation methods like YaST online_update or \"zypper patch\".\n",
					"product_ids": [
						"openSUSE Tumbleweed:python36-Django-3.2.7-2.3.aarch64",
						"openSUSE Tumbleweed:python36-Django-3.2.7-2.3.ppc64le",
						"openSUSE Tumbleweed:python36-Django-3.2.7-2.3.s390x",
						"openSUSE Tumbleweed:python36-Django-3.2.7-2.3.x86_64",
						"openSUSE Tumbleweed:python38-Django-3.2.7-2.3.aarch64",
						"openSUSE Tumbleweed:python38-Django-3.2.7-2.3.ppc64le",
						"openSUSE Tumbleweed:python38-Django-3.2.7-2.3.s390x",
						"openSUSE Tumbleweed:python38-Django-3.2.7-2.3.x86_64",
						"openSUSE Tumbleweed:python39-Django-3.2.7-2.3.aarch64",
						"openSUSE Tumbleweed:python39-Django-3.2.7-2.3.ppc64le",
						"openSUSE Tumbleweed:python39-Django-3.2.7-2.3.s390x",
						"openSUSE Tumbleweed:python39-Django-3.2.7-2.3.x86_64"
					]
				}
			],
			"scores": [
				{
					"cvss_v3": {
						"baseScore": 5.4,
						"baseSeverity": "MEDIUM",
						"vectorString": "CVSS:3.1/AV:N/AC:L/PR:N/UI:R/S:U/C:L/I:L/A:N",
						"version": "3.1"
					},
					"products": [
						"openSUSE Tumbleweed:python36-Django-3.2.7-2.3.aarch64",
						"openSUSE Tumbleweed:python36-Django-3.2.7-2.3.ppc64le",
						"openSUSE Tumbleweed:python36-Django-3.2.7-2.3.s390x",
						"openSUSE Tumbleweed:python36-Django-3.2.7-2.3.x86_64",
						"openSUSE Tumbleweed:python38-Django-3.2.7-2.3.aarch64",
						"openSUSE Tumbleweed:python38-Django-3.2.7-2.3.ppc64le",
						"openSUSE Tumbleweed:python38-Django-3.2.7-2.3.s390x",
						"openSUSE Tumbleweed:python38-Django-3.2.7-2.3.x86_64",
						"openSUSE Tumbleweed:python39-Django-3.2.7-2.3.aarch64",
						"openSUSE Tumbleweed:python39-Django-3.2.7-2.3.ppc64le",
						"openSUSE Tumbleweed:python39-Django-3.2.7-2.3.s390x",
						"openSUSE Tumbleweed:python39-Django-3.2.7-2.3.x86_64"
					]
				}
			],
			"threats": [
				{
					"category": "impact",
					"date": "2024-06-15T00:00:00Z",
					"details": "moderate"
				}
			],
			"title": "CVE-2021-32052"
		},
		{
			"cve": "CVE-2021-33203",
			"ids": [
				{
					"system_name": "SUSE CVE Page",
					"text": "https://www.suse.com/security/cve/CVE-2021-33203"
				}
			],
			"notes": [
				{
					"category": "general",
					"text": "Django before 2.2.24, 3.x before 3.1.12, and 3.2.x before 3.2.4 has a potential directory traversal via django.contrib.admindocs. Staff members could use the TemplateDetailView view to check the existence of arbitrary files. Additionally, if (and only if) the default admindocs templates have been customized by application developers to also show file contents, then not only the existence but also the file contents would have been exposed. In other words, there is directory traversal outside of the template root directories.",
					"title": "CVE description"
				}
			],
			"product_status": {
				"recommended": [
					"openSUSE Tumbleweed:python36-Django-3.2.7-2.3.aarch64",
					"openSUSE Tumbleweed:python36-Django-3.2.7-2.3.ppc64le",
					"openSUSE Tumbleweed:python36-Django-3.2.7-2.3.s390x",
					"openSUSE Tumbleweed:python36-Django-3.2.7-2.3.x86_64",
					"openSUSE Tumbleweed:python38-Django-3.2.7-2.3.aarch64",
					"openSUSE Tumbleweed:python38-Django-3.2.7-2.3.ppc64le",
					"openSUSE Tumbleweed:python38-Django-3.2.7-2.3.s390x",
					"openSUSE Tumbleweed:python38-Django-3.2.7-2.3.x86_64",
					"openSUSE Tumbleweed:python39-Django-3.2.7-2.3.aarch64",
					"openSUSE Tumbleweed:python39-Django-3.2.7-2.3.ppc64le",
					"openSUSE Tumbleweed:python39-Django-3.2.7-2.3.s390x",
					"openSUSE Tumbleweed:python39-Django-3.2.7-2.3.x86_64"
				]
			},
			"references": [
				{
					"category": "external",
					"summary": "CVE-2021-33203",
					"url": "https://www.suse.com/security/cve/CVE-2021-33203"
				},
				{
					"category": "external",
					"summary": "SUSE Bug 1186608 for CVE-2021-33203",
					"url": "https://bugzilla.suse.com/1186608"
				}
			],
			"remediations": [
				{
					"category": "vendor_fix",
					"details": "To install this SUSE Security Update use the SUSE recommended installation methods like YaST online_update or \"zypper patch\".\n",
					"product_ids": [
						"openSUSE Tumbleweed:python36-Django-3.2.7-2.3.aarch64",
						"openSUSE Tumbleweed:python36-Django-3.2.7-2.3.ppc64le",
						"openSUSE Tumbleweed:python36-Django-3.2.7-2.3.s390x",
						"openSUSE Tumbleweed:python36-Django-3.2.7-2.3.x86_64",
						"openSUSE Tumbleweed:python38-Django-3.2.7-2.3.aarch64",
						"openSUSE Tumbleweed:python38-Django-3.2.7-2.3.ppc64le",
						"openSUSE Tumbleweed:python38-Django-3.2.7-2.3.s390x",
						"openSUSE Tumbleweed:python38-Django-3.2.7-2.3.x86_64",
						"openSUSE Tumbleweed:python39-Django-3.2.7-2.3.aarch64",
						"openSUSE Tumbleweed:python39-Django-3.2.7-2.3.ppc64le",
						"openSUSE Tumbleweed:python39-Django-3.2.7-2.3.s390x",
						"openSUSE Tumbleweed:python39-Django-3.2.7-2.3.x86_64"
					]
				}
			],
			"scores": [
				{
					"cvss_v3": {
						"baseScore": 4.9,
						"baseSeverity": "MEDIUM",
						"vectorString": "CVSS:3.1/AV:N/AC:L/PR:H/UI:N/S:U/C:H/I:N/A:N",
						"version": "3.1"
					},
					"products": [
						"openSUSE Tumbleweed:python36-Django-3.2.7-2.3.aarch64",
						"openSUSE Tumbleweed:python36-Django-3.2.7-2.3.ppc64le",
						"openSUSE Tumbleweed:python36-Django-3.2.7-2.3.s390x",
						"openSUSE Tumbleweed:python36-Django-3.2.7-2.3.x86_64",
						"openSUSE Tumbleweed:python38-Django-3.2.7-2.3.aarch64",
						"openSUSE Tumbleweed:python38-Django-3.2.7-2.3.ppc64le",
						"openSUSE Tumbleweed:python38-Django-3.2.7-2.3.s390x",
						"openSUSE Tumbleweed:python38-Django-3.2.7-2.3.x86_64",
						"openSUSE Tumbleweed:python39-Django-3.2.7-2.3.aarch64",
						"openSUSE Tumbleweed:python39-Django-3.2.7-2.3.ppc64le",
						"openSUSE Tumbleweed:python39-Django-3.2.7-2.3.s390x",
						"openSUSE Tumbleweed:python39-Django-3.2.7-2.3.x86_64"
					]
				}
			],
			"threats": [
				{
					"category": "impact",
					"date": "2024-06-15T00:00:00Z",
					"details": "moderate"
				}
			],
			"title": "CVE-2021-33203"
		},
		{
			"cve": "CVE-2021-33571",
			"ids": [
				{
					"system_name": "SUSE CVE Page",
					"text": "https://www.suse.com/security/cve/CVE-2021-33571"
				}
			],
			"notes": [
				{
					"category": "general",
					"text": "In Django 2.2 before 2.2.24, 3.x before 3.1.12, and 3.2 before 3.2.4, URLValidator, validate_ipv4_address, and validate_ipv46_address do not prohibit leading zero characters in octal literals. This may allow a bypass of access control that is based on IP addresses. (validate_ipv4_address and validate_ipv46_address are unaffected with Python 3.9.5+..) .",
					"title": "CVE description"
				}
			],
			"product_status": {
				"recommended": [
					"openSUSE Tumbleweed:python36-Django-3.2.7-2.3.aarch64",
					"openSUSE Tumbleweed:python36-Django-3.2.7-2.3.ppc64le",
					"openSUSE Tumbleweed:python36-Django-3.2.7-2.3.s390x",
					"openSUSE Tumbleweed:python36-Django-3.2.7-2.3.x86_64",
					"openSUSE Tumbleweed:python38-Django-3.2.7-2.3.aarch64",
					"openSUSE Tumbleweed:python38-Django-3.2.7-2.3.ppc64le",
					"openSUSE Tumbleweed:python38-Django-3.2.7-2.3.s390x",
					"openSUSE Tumbleweed:python38-Django-3.2.7-2.3.x86_64",
					"openSUSE Tumbleweed:python39-Django-3.2.7-2.3.aarch64",
					"openSUSE Tumbleweed:python39-Django-3.2.7-2.3.ppc64le",
					"openSUSE Tumbleweed:python39-Django-3.2.7-2.3.s390x",
					"openSUSE Tumbleweed:python39-Django-3.2.7-2.3.x86_64"
				]
			},
			"references": [
				{
					"category": "external",
					"summary": "CVE-2021-33571",
					"url": "https://www.suse.com/security/cve/CVE-2021-33571"
				},
				{
					"category": "external",
					"summary": "SUSE Bug 1186611 for CVE-2021-33571",
					"url": "https://bugzilla.suse.com/1186611"
				}
			],
			"remediations": [
				{
					"category": "vendor_fix",
					"details": "To install this SUSE Security Update use the SUSE recommended installation methods like YaST online_update or \"zypper patch\".\n",
					"product_ids": [
						"openSUSE Tumbleweed:python36-Django-3.2.7-2.3.aarch64",
						"openSUSE Tumbleweed:python36-Django-3.2.7-2.3.ppc64le",
						"openSUSE Tumbleweed:python36-Django-3.2.7-2.3.s390x",
						"openSUSE Tumbleweed:python36-Django-3.2.7-2.3.x86_64",
						"openSUSE Tumbleweed:python38-Django-3.2.7-2.3.aarch64",
						"openSUSE Tumbleweed:python38-Django-3.2.7-2.3.ppc64le",
						"openSUSE Tumbleweed:python38-Django-3.2.7-2.3.s390x",
						"openSUSE Tumbleweed:python38-Django-3.2.7-2.3.x86_64",
						"openSUSE Tumbleweed:python39-Django-3.2.7-2.3.aarch64",
						"openSUSE Tumbleweed:python39-Django-3.2.7-2.3.ppc64le",
						"openSUSE Tumbleweed:python39-Django-3.2.7-2.3.s390x",
						"openSUSE Tumbleweed:python39-Django-3.2.7-2.3.x86_64"
					]
				}
			],
			"scores": [
				{
					"cvss_v3": {
						"baseScore": 7.5,
						"baseSeverity": "HIGH",
						"vectorString": "CVSS:3.1/AV:N/AC:L/PR:N/UI:N/S:U/C:N/I:H/A:N",
						"version": "3.1"
					},
					"products": [
						"openSUSE Tumbleweed:python36-Django-3.2.7-2.3.aarch64",
						"openSUSE Tumbleweed:python36-Django-3.2.7-2.3.ppc64le",
						"openSUSE Tumbleweed:python36-Django-3.2.7-2.3.s390x",
						"openSUSE Tumbleweed:python36-Django-3.2.7-2.3.x86_64",
						"openSUSE Tumbleweed:python38-Django-3.2.7-2.3.aarch64",
						"openSUSE Tumbleweed:python38-Django-3.2.7-2.3.ppc64le",
						"openSUSE Tumbleweed:python38-Django-3.2.7-2.3.s390x",
						"openSUSE Tumbleweed:python38-Django-3.2.7-2.3.x86_64",
						"openSUSE Tumbleweed:python39-Django-3.2.7-2.3.aarch64",
						"openSUSE Tumbleweed:python39-Django-3.2.7-2.3.ppc64le",
						"openSUSE Tumbleweed:python39-Django-3.2.7-2.3.s390x",
						"openSUSE Tumbleweed:python39-Django-3.2.7-2.3.x86_64"
					]
				}
			],
			"threats": [
				{
					"category": "impact",
					"date": "2024-06-15T00:00:00Z",
					"details": "important"
				}
			],
			"title": "CVE-2021-33571"
		},
		{
			"cve": "CVE-2021-35042",
			"ids": [
				{
					"system_name": "SUSE CVE Page",
					"text": "https://www.suse.com/security/cve/CVE-2021-35042"
				}
			],
			"notes": [
				{
					"category": "general",
					"text": "Django 3.1.x before 3.1.13 and 3.2.x before 3.2.5 allows QuerySet.order_by SQL injection if order_by is untrusted input from a client of a web application.",
					"title": "CVE description"
				}
			],
			"product_status": {
				"recommended": [
					"openSUSE Tumbleweed:python36-Django-3.2.7-2.3.aarch64",
					"openSUSE Tumbleweed:python36-Django-3.2.7-2.3.ppc64le",
					"openSUSE Tumbleweed:python36-Django-3.2.7-2.3.s390x",
					"openSUSE Tumbleweed:python36-Django-3.2.7-2.3.x86_64",
					"openSUSE Tumbleweed:python38-Django-3.2.7-2.3.aarch64",
					"openSUSE Tumbleweed:python38-Django-3.2.7-2.3.ppc64le",
					"openSUSE Tumbleweed:python38-Django-3.2.7-2.3.s390x",
					"openSUSE Tumbleweed:python38-Django-3.2.7-2.3.x86_64",
					"openSUSE Tumbleweed:python39-Django-3.2.7-2.3.aarch64",
					"openSUSE Tumbleweed:python39-Django-3.2.7-2.3.ppc64le",
					"openSUSE Tumbleweed:python39-Django-3.2.7-2.3.s390x",
					"openSUSE Tumbleweed:python39-Django-3.2.7-2.3.x86_64"
				]
			},
			"references": [
				{
					"category": "external",
					"summary": "CVE-2021-35042",
					"url": "https://www.suse.com/security/cve/CVE-2021-35042"
				},
				{
					"category": "external",
					"summary": "SUSE Bug 1187785 for CVE-2021-35042",
					"url": "https://bugzilla.suse.com/1187785"
				}
			],
			"remediations": [
				{
					"category": "vendor_fix",
					"details": "To install this SUSE Security Update use the SUSE recommended installation methods like YaST online_update or \"zypper patch\".\n",
					"product_ids": [
						"openSUSE Tumbleweed:python36-Django-3.2.7-2.3.aarch64",
						"openSUSE Tumbleweed:python36-Django-3.2.7-2.3.ppc64le",
						"openSUSE Tumbleweed:python36-Django-3.2.7-2.3.s390x",
						"openSUSE Tumbleweed:python36-Django-3.2.7-2.3.x86_64",
						"openSUSE Tumbleweed:python38-Django-3.2.7-2.3.aarch64",
						"openSUSE Tumbleweed:python38-Django-3.2.7-2.3.ppc64le",
						"openSUSE Tumbleweed:python38-Django-3.2.7-2.3.s390x",
						"openSUSE Tumbleweed:python38-Django-3.2.7-2.3.x86_64",
						"openSUSE Tumbleweed:python39-Django-3.2.7-2.3.aarch64",
						"openSUSE Tumbleweed:python39-Django-3.2.7-2.3.ppc64le",
						"openSUSE Tumbleweed:python39-Django-3.2.7-2.3.s390x",
						"openSUSE Tumbleweed:python39-Django-3.2.7-2.3.x86_64"
					]
				}
			],
			"scores": [
				{
					"cvss_v3": {
						"baseScore": 9.8,
						"baseSeverity": "CRITICAL",
						"vectorString": "CVSS:3.1/AV:N/AC:L/PR:N/UI:N/S:U/C:H/I:H/A:H",
						"version": "3.1"
					},
					"products": [
						"openSUSE Tumbleweed:python36-Django-3.2.7-2.3.aarch64",
						"openSUSE Tumbleweed:python36-Django-3.2.7-2.3.ppc64le",
						"openSUSE Tumbleweed:python36-Django-3.2.7-2.3.s390x",
						"openSUSE Tumbleweed:python36-Django-3.2.7-2.3.x86_64",
						"openSUSE Tumbleweed:python38-Django-3.2.7-2.3.aarch64",
						"openSUSE Tumbleweed:python38-Django-3.2.7-2.3.ppc64le",
						"openSUSE Tumbleweed:python38-Django-3.2.7-2.3.s390x",
						"openSUSE Tumbleweed:python38-Django-3.2.7-2.3.x86_64",
						"openSUSE Tumbleweed:python39-Django-3.2.7-2.3.aarch64",
						"openSUSE Tumbleweed:python39-Django-3.2.7-2.3.ppc64le",
						"openSUSE Tumbleweed:python39-Django-3.2.7-2.3.s390x",
						"openSUSE Tumbleweed:python39-Django-3.2.7-2.3.x86_64"
					]
				}
			],
			"threats": [
				{
					"category": "impact",
					"date": "2024-06-15T00:00:00Z",
					"details": "critical"
				}
			],
			"title": "CVE-2021-35042"
		}
	]
}
